<?xml version="1.0" encoding="UTF-8"?>
<sdf version="1.6">
    <model name="fanuc_lrmate200id">
        <link name="link0">
            <pose frame="">0 0 0 0 -0 0</pose>
            <inertial>
                <pose frame="">0 0 0 0 -0 0</pose>
                <mass>4</mass>
                <inertia>
                    <ixx>0.0216667</ixx>
                    <ixy>0</ixy>
                    <ixz>0</ixz>
                    <iyy>0.0216667</iyy>
                    <iyz>0</iyz>
                    <izz>0.0240667</izz>
                </inertia>
            </inertial>
            <collision name="link0_fixed_joint_lump__fanuc_base_link_collision">
                <pose frame="">0 0 0 0 -0 0</pose>
                <geometry>
                    <mesh>
                        <scale>1 1 1</scale>
                        <uri>model://fanuc_lrmate200id_support/meshes/lrmate200id/visual/base_link.stl</uri>
                    </mesh>
                </geometry>
                <surface>
                    <contact>
                        <ode />
                    </contact>
                    <friction>
                        <ode />
                    </friction>
                </surface>
            </collision>
            <visual name="link0_fixed_joint_lump__fanuc_base_link_visual">
                <pose frame="">0 0 0 0 -0 0</pose>
                <geometry>
                    <mesh>
                        <scale>1 1 1</scale>
                        <uri>model://fanuc_lrmate200id_support/meshes/lrmate200id/visual/base_link.stl</uri>
                    </mesh>
                </geometry>
                <material>
                    <script>
                        <name>Gazebo/Grey</name>
                        <uri>file://media/materials/scripts/gazebo.material</uri>
                    </script>
                </material>
            </visual>
            <gravity>0</gravity>
            <velocity_decay />
            <self_collide>0</self_collide>
        </link>
        <joint name="world_joint" type="revolute">
            <child>link0</child>
            <parent>world</parent>
            <axis>
                <limit>
                    <lower>0</lower>
                    <upper>0</upper>
                </limit>
                <dynamics>
                    <damping>0</damping>
                    <friction>0</friction>
                    <spring_reference>0</spring_reference>
                    <spring_stiffness>0</spring_stiffness>
                </dynamics>
                <use_parent_model_frame>1</use_parent_model_frame>
                <xyz>0 0 1</xyz>
            </axis>
        </joint>
        <link name="fanuc_link_1">
            <pose frame="">0 0 0.33 0 -0 0</pose>
            <inertial>
                <pose frame="">0 0 0 0 -0 0</pose>
                <mass>4</mass>
                <inertia>
                    <ixx>0.0322667</ixx>
                    <ixy>0</ixy>
                    <ixz>0</ixz>
                    <iyy>0.0226667</iyy>
                    <iyz>0</iyz>
                    <izz>0.0226667</izz>
                </inertia>
            </inertial>
            <collision name="fanuc_link_1_collision">
                <pose frame="">0 0 0 0 -0 0</pose>
                <geometry>
                    <mesh>
                        <scale>1 1 1</scale>
                        <uri>model://fanuc_lrmate200id_support/meshes/lrmate200id/visual/link_1.stl</uri>
                    </mesh>
                </geometry>
                <surface>
                    <contact>
                        <ode />
                    </contact>
                    <friction>
                        <ode />
                    </friction>
                </surface>
            </collision>
            <visual name="fanuc_link_1_visual">
                <pose frame="">0 0 0 0 -0 0</pose>
                <geometry>
                    <mesh>
                        <scale>1 1 1</scale>
                        <uri>model://fanuc_lrmate200id_support/meshes/lrmate200id/visual/link_1.stl</uri>
                    </mesh>
                </geometry>
                <material>
                    <script>
                        <name>Gazebo/Yellow</name>
                        <uri>file://media/materials/scripts/gazebo.material</uri>
                    </script>
                </material>
            </visual>
            <gravity>0</gravity>
            <velocity_decay />
            <self_collide>0</self_collide>
        </link>
        <joint name="fanuc_joint_1" type="revolute">
            <child>fanuc_link_1</child>
            <parent>link0</parent>
            <axis>
                <xyz>0 0 1</xyz>
                <limit>
                    <lower>-2.965</lower>
                    <upper>2.965</upper>
                    <effort>0</effort>
                    <velocity>7.85</velocity>
                </limit>
                <dynamics>
                    <spring_reference>0</spring_reference>
                    <spring_stiffness>0</spring_stiffness>
                </dynamics>
                <use_parent_model_frame>1</use_parent_model_frame>
            </axis>
        </joint>
        <link name="fanuc_link_2">
            <pose frame="">0.05 0 0.33 0 -0 0</pose>
            <inertial>
                <pose frame="">0 0 0 0 -0 0</pose>
                <mass>5</mass>
                <inertia>
                    <ixx>0.0973333</ixx>
                    <ixy>0</ixy>
                    <ixz>0</ixz>
                    <iyy>0.0888333</iyy>
                    <iyz>0</iyz>
                    <izz>0.0248333</izz>
                </inertia>
            </inertial>
            <collision name="fanuc_link_2_collision">
                <pose frame="">0 0 0 0 -0 0</pose>
                <geometry>
                    <mesh>
                        <scale>1 1 1</scale>
                        <uri>model://fanuc_lrmate200id_support/meshes/lrmate200id/visual/link_2.stl</uri>
                    </mesh>
                </geometry>
                <surface>
                    <contact>
                        <ode />
                    </contact>
                    <friction>
                        <ode />
                    </friction>
                </surface>
            </collision>
            <visual name="fanuc_link_2_visual">
                <pose frame="">0 0 0 0 -0 0</pose>
                <geometry>
                    <mesh>
                        <scale>1 1 1</scale>
                        <uri>model://fanuc_lrmate200id_support/meshes/lrmate200id/visual/link_2.stl</uri>
                    </mesh>
                </geometry>
                <material>
                    <script>
                        <name>Gazebo/Yellow</name>
                        <uri>file://media/materials/scripts/gazebo.material</uri>
                    </script>
                </material>
            </visual>
            <gravity>0</gravity>
            <velocity_decay />
            <self_collide>0</self_collide>
        </link>
        <joint name="fanuc_joint_2" type="revolute">
            <child>fanuc_link_2</child>
            <parent>fanuc_link_1</parent>
            <axis>
                <xyz>0 1 0</xyz>
                <limit>
                    <lower>-1.74533</lower>
                    <upper>2.53073</upper>
                    <effort>0</effort>
                    <velocity>6.63</velocity>
                </limit>
                <dynamics>
                    <spring_reference>0</spring_reference>
                    <spring_stiffness>0</spring_stiffness>
                </dynamics>
                <use_parent_model_frame>1</use_parent_model_frame>
            </axis>
        </joint>
        <link name="fanuc_link_3">
            <pose frame="">0.05 0 0.66 0 -0 0</pose>
            <inertial>
                <pose frame="">0 0 0 0 -0 0</pose>
                <mass>4</mass>
                <inertia>
                    <ixx>0.0104333</ixx>
                    <ixy>0</ixy>
                    <ixz>0</ixz>
                    <iyy>0.0121667</iyy>
                    <iyz>0</iyz>
                    <izz>0.0113333</izz>
                </inertia>
            </inertial>
            <collision name="fanuc_link_3_collision">
                <pose frame="">0 0 0 0 -0 0</pose>
                <geometry>
                    <mesh>
                        <scale>1 1 1</scale>
                        <uri>model://fanuc_lrmate200id_support/meshes/lrmate200id/visual/link_3.stl</uri>
                    </mesh>
                </geometry>
                <surface>
                    <contact>
                        <ode />
                    </contact>
                    <friction>
                        <ode />
                    </friction>
                </surface>
            </collision>
            <visual name="fanuc_link_3_visual">
                <pose frame="">0 0 0 0 -0 0</pose>
                <geometry>
                    <mesh>
                        <scale>1 1 1</scale>
                        <uri>model://fanuc_lrmate200id_support/meshes/lrmate200id/visual/link_3.stl</uri>
                    </mesh>
                </geometry>
                <material>
                    <script>
                        <name>Gazebo/Yellow</name>
                        <uri>file://media/materials/scripts/gazebo.material</uri>
                    </script>
                </material>
            </visual>
            <gravity>0</gravity>
            <velocity_decay />
            <self_collide>0</self_collide>
        </link>
        <joint name="fanuc_joint_3" type="revolute">
            <child>fanuc_link_3</child>
            <parent>fanuc_link_2</parent>
            <axis>
                <xyz>0 -1 0</xyz>
                <limit>
                    <lower>-2.45097</lower>
                    <upper>4.88692</upper>
                    <effort>0</effort>
                    <velocity>9.08</velocity>
                </limit>
                <dynamics>
                    <spring_reference>0</spring_reference>
                    <spring_stiffness>0</spring_stiffness>
                </dynamics>
                <use_parent_model_frame>1</use_parent_model_frame>
            </axis>
        </joint>
        <link name="fanuc_link_4">
            <pose frame="">0.05 0 0.695 0 -0 0</pose>
            <inertial>
                <pose frame="">0 0 0 0 -0 0</pose>
                <mass>5</mass>
                <inertia>
                    <ixx>0.00833333</ixx>
                    <ixy>0</ixy>
                    <ixz>0</ixz>
                    <iyy>0.0368333</iyy>
                    <iyz>0</iyz>
                    <izz>0.0368333</izz>
                </inertia>
            </inertial>
            <collision name="fanuc_link_4_collision">
                <pose frame="">0 0 0 0 -0 0</pose>
                <geometry>
                    <mesh>
                        <scale>1 1 1</scale>
                        <uri>model://fanuc_lrmate200id_support/meshes/lrmate200id/visual/link_4.stl</uri>
                    </mesh>
                </geometry>
                <surface>
                    <contact>
                        <ode />
                    </contact>
                    <friction>
                        <ode />
                    </friction>
                </surface>
            </collision>
            <visual name="fanuc_link_4_visual">
                <pose frame="">0 0 0 0 -0 0</pose>
                <geometry>
                    <mesh>
                        <scale>1 1 1</scale>
                        <uri>model://fanuc_lrmate200id_support/meshes/lrmate200id/visual/link_4.stl</uri>
                    </mesh>
                </geometry>
                <material>
                    <script>
                        <name>Gazebo/Yellow</name>
                        <uri>file://media/materials/scripts/gazebo.material</uri>
                    </script>
                </material>
            </visual>
            <gravity>0</gravity>
            <velocity_decay />
            <self_collide>0</self_collide>
        </link>
        <joint name="fanuc_joint_4" type="revolute">
            <child>fanuc_link_4</child>
            <parent>fanuc_link_3</parent>
            <axis>
                <xyz>-1 0 0</xyz>
                <limit>
                    <lower>-3.315</lower>
                    <upper>3.315</upper>
                    <effort>0</effort>
                    <velocity>9.6</velocity>
                </limit>
                <dynamics>
                    <spring_reference>0</spring_reference>
                    <spring_stiffness>0</spring_stiffness>
                </dynamics>
                <use_parent_model_frame>1</use_parent_model_frame>
            </axis>
        </joint>
        <link name="fanuc_link_5">
            <pose frame="">0.385 0 0.695 0 -0 0</pose>
            <inertial>
                <pose frame="">0 0 0 0 -0 0</pose>
                <mass>1.5</mass>
                <inertia>
                    <ixx>0.0018125</ixx>
                    <ixy>0</ixy>
                    <ixz>0</ixz>
                    <iyy>0.0023125</iyy>
                    <iyz>0</iyz>
                    <izz>0.002525</izz>
                </inertia>
            </inertial>
            <collision name="fanuc_link_5_collision">
                <pose frame="">0 0 0 0 -0 0</pose>
                <geometry>
                    <mesh>
                        <scale>1 1 1</scale>
                        <uri>model://fanuc_lrmate200id_support/meshes/lrmate200id/visual/link_5.stl</uri>
                    </mesh>
                </geometry>
                <surface>
                    <contact>
                        <ode />
                    </contact>
                    <friction>
                        <ode />
                    </friction>
                </surface>
            </collision>
            <visual name="fanuc_link_5_visual">
                <pose frame="">0 0 0 0 -0 0</pose>
                <geometry>
                    <mesh>
                        <scale>1 1 1</scale>
                        <uri>model://fanuc_lrmate200id_support/meshes/lrmate200id/visual/link_5.stl</uri>
                    </mesh>
                </geometry>
                <material>
                    <script>
                        <name>Gazebo/Yellow</name>
                        <uri>file://media/materials/scripts/gazebo.material</uri>
                    </script>
                </material>
            </visual>
            <gravity>0</gravity>
            <velocity_decay />
            <self_collide>0</self_collide>
        </link>
        <joint name="fanuc_joint_5" type="revolute">
            <child>fanuc_link_5</child>
            <parent>fanuc_link_4</parent>
            <axis>
                <xyz>0 -1 0</xyz>
                <limit>
                    <lower>-2.18</lower>
                    <upper>2.18</upper>
                    <effort>0</effort>
                    <velocity>9.51</velocity>
                </limit>
                <dynamics>
                    <spring_reference>0</spring_reference>
                    <spring_stiffness>0</spring_stiffness>
                </dynamics>
                <use_parent_model_frame>1</use_parent_model_frame>
            </axis>
        </joint>
        <link name="fanuc_link_6">
            <pose frame="">0.465 0 0.695 0 -0 0</pose>
            <inertial>
                <pose frame="">0.003553 0 -0.001714 0 -0 0</pose>
                <mass>1.5239</mass>
                <inertia>
                    <ixx>0.000832898</ixx>
                    <ixy>0</ixy>
                    <ixz>1.29197e-05</ixz>
                    <iyy>0.00228843</iyy>
                    <iyz>0</iyz>
                    <izz>0.0024042</izz>
                </inertia>
            </inertial>
            <collision name="fanuc_link_6_collision">
                <pose frame="">0 0 0 0 -0 0</pose>
                <geometry>
                    <mesh>
                        <scale>1 1 1</scale>
                        <uri>model://fanuc_lrmate200id_support/meshes/lrmate200id/visual/link_6.stl</uri>
                    </mesh>
                </geometry>
                <surface>
                    <contact>
                        <ode />
                    </contact>
                    <friction>
                        <ode />
                    </friction>
                </surface>
            </collision>
            <collision name="fanuc_link_6_fixed_joint_lump__fanuc_robotiq_85_adapter_link_collision_1">
                <pose frame="">0 0 0 0 -0 1.5707</pose>
                <geometry>
                    <mesh>
                        <scale>1 1 1</scale>
                        <uri>model://robotiq_c2_model_visualization/meshes/robotiq_c2/collision/robotiq_85_gripper_adapter_plate.dae</uri>
                    </mesh>
                </geometry>
            </collision>
            <collision name="fanuc_link_6_fixed_joint_lump__fanuc_robotiq_85_base_link_collision_2">
                <pose frame="">0.0085 0 -0.0041 1.5707 0 1.5707</pose>
                <geometry>
                    <mesh>
                        <scale>1 1 1</scale>
                        <uri>model://robotiq_c2_model_visualization/meshes/robotiq_c2/collision/robotiq_85_gripper_base.dae</uri>
                    </mesh>
                </geometry>
            </collision>
            <visual name="fanuc_link_6_visual">
                <pose frame="">0 0 0 0 -0 0</pose>
                <geometry>
                    <mesh>
                        <scale>1 1 1</scale>
                        <uri>model://fanuc_lrmate200id_support/meshes/lrmate200id/visual/link_6.stl</uri>
                    </mesh>
                </geometry>
                <material>
                    <script>
                        <name>Gazebo/Yellow</name>
                        <uri>file://media/materials/scripts/gazebo.material</uri>
                    </script>
                </material>
            </visual>
            <visual name="fanuc_link_6_fixed_joint_lump__fanuc_robotiq_85_adapter_link_visual_1">
                <pose frame="">0 0 0 1.5707 0 1.5707</pose>
                <geometry>
                    <mesh>
                        <scale>1 1 1</scale>
                        <uri>model://robotiq_c2_model_visualization/meshes/robotiq_c2/visual/robotiq_85_gripper_adapter_plate.dae</uri>
                    </mesh>
                </geometry>
            </visual>
            <visual name="fanuc_link_6_fixed_joint_lump__fanuc_robotiq_85_base_link_visual_2">
                <pose frame="">0.0085 0 -0.0041 3.1415 -0 1.5707</pose>
                <geometry>
                    <mesh>
                        <scale>1 1 1</scale>
                        <uri>model://robotiq_c2_model_visualization/meshes/robotiq_c2/visual/robotiq_85_gripper_base.dae</uri>
                    </mesh>
                </geometry>
            </visual>
            <gravity>0</gravity>
            <velocity_decay />
            <self_collide>0</self_collide>
        </link>
        <joint name="fanuc_joint_6" type="revolute">
            <child>fanuc_link_6</child>
            <parent>fanuc_link_5</parent>
            <axis>
                <xyz>-1 0 0</xyz>
                <limit>
                    <lower>-6.285</lower>
                    <upper>6.285</upper>
                    <effort>0</effort>
                    <velocity>17.45</velocity>
                </limit>
                <dynamics>
                    <spring_reference>0</spring_reference>
                    <spring_stiffness>0</spring_stiffness>
                </dynamics>
                <use_parent_model_frame>1</use_parent_model_frame>
            </axis>
        </joint>
        <link name="fanuc_robotiq_85_left_inner_knuckle_link">
            <pose frame="">0.52193 0.0127 0.6909 1.5707 1.5707 -0</pose>
            <inertial>
                <pose frame="">0 0 0 0 -0 0</pose>
                <mass>0.029951</mass>
                <inertia>
                    <ixx>3.9e-05</ixx>
                    <ixy>0</ixy>
                    <ixz>0</ixz>
                    <iyy>5e-06</iyy>
                    <iyz>0</iyz>
                    <izz>3.5e-05</izz>
                </inertia>
            </inertial>
            <collision name="fanuc_robotiq_85_left_inner_knuckle_link_collision">
                <pose frame="">0 -0.04843 0.0127 3.14159 1.57079 -1.57079</pose>
                <geometry>
                    <mesh>
                        <scale>1 1 1</scale>
                        <uri>model://robotiq_c2_model_visualization/meshes/robotiq_c2/collision/robotiq_85_gripper_joint_2_L.dae</uri>
                    </mesh>
                </geometry>
            </collision>
            <visual name="fanuc_robotiq_85_left_inner_knuckle_link_visual">
                <pose frame="">0 -0.04843 0.0127 3.14159 1.57079 3.14159</pose>
                <geometry>
                    <mesh>
                        <scale>1 1 1</scale>
                        <uri>model://robotiq_c2_model_visualization/meshes/robotiq_c2/visual/robotiq_85_gripper_joint_2_L.dae</uri>
                    </mesh>
                </geometry>
            </visual>
        </link>
        <joint name="fanuc_robotiq_85_left_inner_knuckle_joint" type="revolute">
            <child>fanuc_robotiq_85_left_inner_knuckle_link</child>
            <parent>fanuc_link_6</parent>
            <axis>
                <xyz>9.6e-05 -0 -1</xyz>
                <limit>
                    <lower>0</lower>
                    <upper>1.5707</upper>
                    <effort>1000</effort>
                    <velocity>2</velocity>
                </limit>
                <dynamics>
                    <spring_reference>0</spring_reference>
                    <spring_stiffness>0</spring_stiffness>
                </dynamics>
                <use_parent_model_frame>1</use_parent_model_frame>
            </axis>
        </joint>
        <link name="fanuc_robotiq_85_left_finger_tip_link">
            <pose frame="">0.563886 0.051504 0.690904 1.5707 1.5707 -0</pose>
            <inertial>
                <pose frame="">0 0 0 0 -0 0</pose>
                <mass>0.019555</mass>
                <inertia>
                    <ixx>2e-06</ixx>
                    <ixy>0</ixy>
                    <ixz>0</ixz>
                    <iyy>5e-06</iyy>
                    <iyz>0</iyz>
                    <izz>6e-06</izz>
                </inertia>
            </inertial>
            <collision name="fanuc_robotiq_85_left_finger_tip_link_collision">
                <pose frame="">0 -0.090381 0.051505 3.14159 1.57079 -1.57079</pose>
                <geometry>
                    <mesh>
                        <scale>1 1 1</scale>
                        <uri>model://robotiq_c2_model_visualization/meshes/robotiq_c2/collision/robotiq_85_gripper_joint_3_L.dae</uri>
                    </mesh>
                </geometry>
                <surface>
                    <contact>
                        <ode>
                            <kp>1000000.0</kp>
                            <kd>1.</kd>
                            <max_vel>0</max_vel>
                            <min_depth>0.001</min_depth>
                        </ode>
                    </contact>
                    <bounce />
                    <friction>
                        <ode>
                            <mu>1.</mu>
                            <mu2>1.</mu2>
                        </ode>
                    </friction>
                </surface>
            </collision>
            <visual name="fanuc_robotiq_85_left_finger_tip_link_visual">
                <pose frame="">0 -0.090381 0.051505 3.14159 1.57079 3.14159</pose>
                <geometry>
                    <mesh>
                        <scale>1 1 1</scale>
                        <uri>model://robotiq_c2_model_visualization/meshes/robotiq_c2/visual/robotiq_85_gripper_joint_3_L.dae</uri>
                    </mesh>
                </geometry>
            </visual>
            <sensor name="left_finger_contact" type="contact">
                <contact>
                    <collision>fanuc_robotiq_85_left_finger_tip_link_collision</collision>
                </contact>
            </sensor>
        </link>
        <joint name="fanuc_robotiq_85_left_finger_tip_joint" type="revolute">
            <child>fanuc_robotiq_85_left_finger_tip_link</child>
            <parent>fanuc_robotiq_85_left_inner_knuckle_link</parent>
            <axis>
                <xyz>9.6e-05 -0 -1</xyz>
                <limit>
                    <lower>0</lower>
                    <upper>1.5707</upper>
                    <effort>1000</effort>
                    <velocity>2</velocity>
                </limit>
                <physics>
                    <ode>
                        <implicit_spring_damper>1</implicit_spring_damper>
                    </ode>
                </physics>
                <use_parent_model_frame>1</use_parent_model_frame>
            </axis>
        </joint>
        <link name="fanuc_robotiq_85_left_knuckle_link">
            <pose frame="">0.51541 0.0306 0.6909 -1.5707 1.5707 0</pose>
            <inertial>
                <pose frame="">0 0.003029 0.018687 0 -0 0</pose>
                <mass>0.0458</mass>
                <inertia>
                    <ixx>2.31138e-05</ixx>
                    <ixy>1e-06</ixy>
                    <ixz>-1.85307e-10</ixz>
                    <iyy>3.28293e-05</iyy>
                    <iyz>-1.75544e-06</iyz>
                    <izz>3.02845e-05</izz>
                </inertia>
            </inertial>
            <collision name="fanuc_robotiq_85_left_knuckle_link_collision">
                <pose frame="">0 0.04191 -0.0306 -3.14159 -1.57079 -1.57079</pose>
                <geometry>
                    <mesh>
                        <scale>1 1 1</scale>
                        <uri>model://robotiq_c2_model_visualization/meshes/robotiq_c2/collision/robotiq_85_gripper_joint_0_L.dae</uri>
                    </mesh>
                </geometry>
            </collision>
            <collision name="fanuc_robotiq_85_left_knuckle_link_fixed_joint_lump__fanuc_robotiq_85_left_finger_link_collision_1">
                <pose frame="">0 0.041904 -0.030603 3.14159 -1.57079 -1.5706</pose>
                <geometry>
                    <mesh>
                        <scale>1 1 1</scale>
                        <uri>model://robotiq_c2_model_visualization/meshes/robotiq_c2/collision/robotiq_85_gripper_joint_1_L.dae</uri>
                    </mesh>
                </geometry>
            </collision>
            <visual name="fanuc_robotiq_85_left_knuckle_link_visual">
                <pose frame="">0 0.04191 -0.0306 3.14159 -1.57079 -3e-06</pose>
                <geometry>
                    <mesh>
                        <scale>1 1 1</scale>
                        <uri>model://robotiq_c2_model_visualization/meshes/robotiq_c2/visual/robotiq_85_gripper_joint_0_L.dae</uri>
                    </mesh>
                </geometry>
            </visual>
            <visual name="fanuc_robotiq_85_left_knuckle_link_fixed_joint_lump__fanuc_robotiq_85_left_finger_link_visual_1">
                <pose frame="">0 0.041904 -0.030603 -3.14159 -1.57079 9.7e-05</pose>
                <geometry>
                    <mesh>
                        <scale>1 1 1</scale>
                        <uri>model://robotiq_c2_model_visualization/meshes/robotiq_c2/visual/robotiq_85_gripper_joint_1_L.dae</uri>
                    </mesh>
                </geometry>
            </visual>
        </link>
        <joint name="fanuc_robotiq_85_left_knuckle_joint" type="revolute">
            <child>fanuc_robotiq_85_left_knuckle_link</child>
            <parent>fanuc_link_6</parent>
            <axis>
                <xyz>9.6e-05 0 -1</xyz>
                <limit>
                    <lower>0</lower>
                    <upper>0.8575</upper>
                    <effort>1000</effort>
                    <velocity>2</velocity>
                </limit>
                <dynamics>
                    <spring_reference>0</spring_reference>
                    <spring_stiffness>0</spring_stiffness>
                </dynamics>
                <use_parent_model_frame>1</use_parent_model_frame>
            </axis>
        </joint>
        <link name="fanuc_robotiq_85_right_inner_knuckle_link">
            <pose frame="">0.52193 -0.0127 0.6909 -1.5707 -1.5707 -0</pose>
            <inertial>
                <pose frame="">0 0 0 0 -0 0</pose>
                <mass>0.029951</mass>
                <inertia>
                    <ixx>3.9e-05</ixx>
                    <ixy>0</ixy>
                    <ixz>0</ixz>
                    <iyy>5e-06</iyy>
                    <iyz>0</iyz>
                    <izz>3.5e-05</izz>
                </inertia>
            </inertial>
            <collision name="fanuc_robotiq_85_right_inner_knuckle_link_collision">
                <pose frame="">0 -0.04843 0.0127 3.14159 -1.57079 1.57079</pose>
                <geometry>
                    <mesh>
                        <scale>1 1 1</scale>
                        <uri>model://robotiq_c2_model_visualization/meshes/robotiq_c2/collision/robotiq_85_gripper_joint_2_R.dae</uri>
                    </mesh>
                </geometry>
            </collision>
            <visual name="fanuc_robotiq_85_right_inner_knuckle_link_visual">
                <pose frame="">0 -0.04843 0.0127 3.14159 -1.57079 3.14159</pose>
                <geometry>
                    <mesh>
                        <scale>1 1 1</scale>
                        <uri>model://robotiq_c2_model_visualization/meshes/robotiq_c2/visual/robotiq_85_gripper_joint_2_R.dae</uri>
                    </mesh>
                </geometry>
            </visual>
        </link>
        <joint name="fanuc_robotiq_85_right_inner_knuckle_joint" type="revolute">
            <child>fanuc_robotiq_85_right_inner_knuckle_link</child>
            <parent>fanuc_link_6</parent>
            <axis>
                <xyz>9.6e-05 -0 1</xyz>
                <limit>
                    <lower>0</lower>
                    <upper>1.5707</upper>
                    <effort>1000</effort>
                    <velocity>2</velocity>
                </limit>
                <dynamics>
                    <spring_reference>0</spring_reference>
                    <spring_stiffness>0</spring_stiffness>
                </dynamics>
                <use_parent_model_frame>1</use_parent_model_frame>
            </axis>
        </joint>
        <link name="fanuc_robotiq_85_right_finger_tip_link">
            <pose frame="">0.563894 -0.051496 0.690896 -1.5707 -1.5707 -0</pose>
            <inertial>
                <pose frame="">0 0 0 0 -0 0</pose>
                <mass>0.019555</mass>
                <inertia>
                    <ixx>2e-06</ixx>
                    <ixy>0</ixy>
                    <ixz>0</ixz>
                    <iyy>5e-06</iyy>
                    <iyz>0</iyz>
                    <izz>6e-06</izz>
                </inertia>
            </inertial>
            <collision name="fanuc_robotiq_85_right_finger_tip_link_collision">
                <pose frame="">0 -0.090381 0.051505 3.14159 -1.57079 1.57079</pose>
                <geometry>
                    <mesh>
                        <scale>1 1 1</scale>
                        <uri>model://robotiq_c2_model_visualization/meshes/robotiq_c2/collision/robotiq_85_gripper_joint_3_R.dae</uri>
                    </mesh>
                </geometry>
                <surface>
                    <contact>
                        <ode>
                            <kp>1000000.0</kp>
                            <kd>1.</kd>
                            <max_vel>0</max_vel>
                            <min_depth>0.001</min_depth>
                        </ode>
                    </contact>
                    <bounce />
                    <friction>
                        <ode>
                            <mu>1.</mu>
                            <mu2>1.</mu2>
                        </ode>
                    </friction>
                </surface>
            </collision>
            <visual name="fanuc_robotiq_85_right_finger_tip_link_visual">
                <pose frame="">0 -0.090381 0.051505 3.14159 -1.57079 3.14159</pose>
                <geometry>
                    <mesh>
                        <scale>1 1 1</scale>
                        <uri>model://robotiq_c2_model_visualization/meshes/robotiq_c2/visual/robotiq_85_gripper_joint_3_R.dae</uri>
                    </mesh>
                </geometry>
            </visual>
            <sensor name="right_finger_contact" type="contact">
                <contact>
                    <collision>fanuc_robotiq_85_right_finger_tip_link_collision</collision>
                </contact>
            </sensor>
        </link>
        <joint name="fanuc_robotiq_85_right_finger_tip_joint" type="revolute">
            <child>fanuc_robotiq_85_right_finger_tip_link</child>
            <parent>fanuc_robotiq_85_right_inner_knuckle_link</parent>
            <axis>
                <xyz>9.6e-05 -0 1</xyz>
                <limit>
                    <lower>0</lower>
                    <upper>1.5707</upper>
                    <effort>1000</effort>
                    <velocity>2</velocity>
                </limit>
                <physics>
                    <ode>
                        <implicit_spring_damper>1</implicit_spring_damper>
                    </ode>
                </physics>
                <use_parent_model_frame>1</use_parent_model_frame>
            </axis>
        </joint>
        <link name="fanuc_robotiq_85_right_knuckle_link">
            <pose frame="">0.51541 -0.0306 0.6909 1.5707 -1.5707 0</pose>
            <inertial>
                <pose frame="">0 0.003029 0.018687 0 -0 0</pose>
                <mass>0.0458</mass>
                <inertia>
                    <ixx>2.31138e-05</ixx>
                    <ixy>1e-06</ixy>
                    <ixz>-1.85307e-10</ixz>
                    <iyy>3.28293e-05</iyy>
                    <iyz>-1.75544e-06</iyz>
                    <izz>3.02845e-05</izz>
                </inertia>
            </inertial>
            <collision name="fanuc_robotiq_85_right_knuckle_link_collision">
                <pose frame="">0 0.04191 -0.0306 -3.14159 1.57079 1.57079</pose>
                <geometry>
                    <mesh>
                        <scale>1 1 1</scale>
                        <uri>model://robotiq_c2_model_visualization/meshes/robotiq_c2/collision/robotiq_85_gripper_joint_0_R.dae</uri>
                    </mesh>
                </geometry>
            </collision>
            <collision name="fanuc_robotiq_85_right_knuckle_link_fixed_joint_lump__fanuc_robotiq_85_right_finger_link_collision_1">
                <pose frame="">0 0.041904 -0.030603 3.14159 1.57079 1.5706</pose>
                <geometry>
                    <mesh>
                        <scale>1 1 1</scale>
                        <uri>model://robotiq_c2_model_visualization/meshes/robotiq_c2/collision/robotiq_85_gripper_joint_1_R.dae</uri>
                    </mesh>
                </geometry>
            </collision>
            <visual name="fanuc_robotiq_85_right_knuckle_link_visual">
                <pose frame="">0 0.04191 -0.0306 3.14159 1.57079 3e-06</pose>
                <geometry>
                    <mesh>
                        <scale>1 1 1</scale>
                        <uri>model://robotiq_c2_model_visualization/meshes/robotiq_c2/visual/robotiq_85_gripper_joint_0_R.dae</uri>
                    </mesh>
                </geometry>
            </visual>
            <visual name="fanuc_robotiq_85_right_knuckle_link_fixed_joint_lump__fanuc_robotiq_85_right_finger_link_visual_1">
                <pose frame="">0 0.041904 -0.030603 -3.14159 1.57079 -9.7e-05</pose>
                <geometry>
                    <mesh>
                        <scale>1 1 1</scale>
                        <uri>model://robotiq_c2_model_visualization/meshes/robotiq_c2/visual/robotiq_85_gripper_joint_1_R.dae</uri>
                    </mesh>
                </geometry>
            </visual>
        </link>
        <joint name="fanuc_robotiq_85_right_knuckle_joint" type="revolute">
            <child>fanuc_robotiq_85_right_knuckle_link</child>
            <parent>fanuc_link_6</parent>
            <axis>
                <xyz>9.6e-05 0 1</xyz>
                <limit>
                    <lower>0</lower>
                    <upper>1.5707</upper>
                    <effort>1000</effort>
                    <velocity>2</velocity>
                </limit>
                <dynamics>
                    <spring_reference>0</spring_reference>
                    <spring_stiffness>0</spring_stiffness>
                </dynamics>
                <use_parent_model_frame>1</use_parent_model_frame>
            </axis>
        </joint>
    </model>
</sdf>
