<?xml version="1.0" ?>
<!-- =================================================================================== -->
<!-- |    This document was autogenerated by xacro from motoman_only.xacro             | -->
<!-- |    EDITING THIS FILE BY HAND IS NOT RECOMMENDED                                 | -->
<!-- =================================================================================== -->
<robot name="motoman_sia20d" xmlns:xacro="http://ros.org/wiki/xacro">
  <!-- link list -->
  <link name="motoman_base_link">
    <inertial>
      <mass value="150"/>
      <inertia ixx="1" ixy="0.0" ixz="0.0" iyy="1" iyz="0.0" izz="1"/>
    </inertial>
    <visual>
      <geometry>
        <mesh filename="package://motoman_sia20d_support/meshes/sia20d/visual/MOTOMAN_BASE.stl"/>
      </geometry>
      <material name="blue">
        <color rgba="0 0 1 1"/>
      </material>
    </visual>
    <collision>
      <geometry>
        <mesh filename="package://motoman_sia20d_support/meshes/sia20d/collision/MOTOMAN_BASE.stl"/>
      </geometry>
      <material name="yellow">
        <color rgba="0 1 1 1"/>
      </material>
    </collision>
  </link>
  <link name="motoman_link_s">
    <inertial>
      <mass value="34.5"/>
      <inertia ixx="0.502079701" ixy="0.0" ixz="0.0" iyy="0.502079701" iyz="0.0" izz="0.12956896"/>
    </inertial>
    <visual>
      <origin rpy="0 0 3.1416" xyz="0 0 0"/>
      <geometry>
        <mesh filename="package://motoman_sia20d_support/meshes/sia20d/visual/MOTOMAN_AXIS_S.stl"/>
      </geometry>
      <material name="silver">
        <color rgba="0.8 0.8 0.8 1"/>
      </material>
    </visual>
    <collision>
      <origin rpy="0 0 3.1416" xyz="0 0 0"/>
      <geometry>
        <mesh filename="package://motoman_sia20d_support/meshes/sia20d/collision/MOTOMAN_AXIS_S.stl"/>
      </geometry>
      <material name="yellow"/>
    </collision>
  </link>
  <link name="motoman_link_l">
    <inertial>
      <mass value="30.6"/>
      <inertia ixx="0.310135823" ixy="0.0" ixz="0.0" iyy="0.310135823" iyz="0.0" izz="0.12889481"/>
    </inertial>
    <visual>
      <origin rpy="1.57 3.1416 3.1416" xyz="0 0 0"/>
      <geometry>
        <mesh filename="package://motoman_sia20d_support/meshes/sia20d/visual/MOTOMAN_AXIS_L.stl"/>
      </geometry>
      <material name="blue"/>
    </visual>
    <collision>
      <origin rpy="1.57 3.1416 3.1416" xyz="0 0 0"/>
      <geometry>
        <mesh filename="package://motoman_sia20d_support/meshes/sia20d/collision/MOTOMAN_AXIS_L.stl"/>
      </geometry>
      <material name="yellow"/>
    </collision>
  </link>
  <link name="motoman_link_e">
    <inertial>
      <mass value="18.54"/>
      <inertia ixx="0.147277445" ixy="0.0" ixz="0.0" iyy="0.147277445" iyz="0.0" izz="0.05217123"/>
    </inertial>
    <visual>
      <origin rpy="0 0 0" xyz="0 0 0"/>
      <geometry>
        <mesh filename="package://motoman_sia20d_support/meshes/sia20d/visual/MOTOMAN_AXIS_E.stl"/>
      </geometry>
      <material name="silver"/>
    </visual>
    <collision>
      <origin rpy="0 0 0" xyz="0 0 0"/>
      <geometry>
        <mesh filename="package://motoman_sia20d_support/meshes/sia20d/collision/MOTOMAN_AXIS_E.stl"/>
      </geometry>
      <material name="yellow"/>
    </collision>
  </link>
  <link name="motoman_link_u">
    <inertial>
      <mass value="12.9"/>
      <inertia ixx="0.086548013" ixy="0.0" ixz="0.0" iyy="0.086548013" iyz="0.0" izz="0.02733095"/>
    </inertial>
    <visual>
      <origin rpy="1.57 -3.1415 3.1416" xyz="0 0 0"/>
      <geometry>
        <mesh filename="package://motoman_sia20d_support/meshes/sia20d/visual/MOTOMAN_AXIS_U.stl"/>
      </geometry>
      <material name="blue"/>
    </visual>
    <collision>
      <origin rpy="1.57 -3.1415 3.1416" xyz="0 0 0"/>
      <geometry>
        <mesh filename="package://motoman_sia20d_support/meshes/sia20d/collision/MOTOMAN_AXIS_U.stl"/>
      </geometry>
      <material name="yellow"/>
    </collision>
  </link>
  <link name="motoman_link_r">
    <inertial>
      <mass value="7.3"/>
      <inertia ixx="0.034967411" ixy="0.0" ixz="0.0" iyy="0.034967411" iyz="0.0" izz="0.01048203"/>
    </inertial>
    <visual>
      <origin rpy="0 0 0" xyz="0 0 0"/>
      <geometry>
        <mesh filename="package://motoman_sia20d_support/meshes/sia20d/visual/MOTOMAN_AXIS_R.stl"/>
      </geometry>
      <material name="silver"/>
    </visual>
    <collision>
      <origin rpy="0 0 0" xyz="0 0 0"/>
      <geometry>
        <mesh filename="package://motoman_sia20d_support/meshes/sia20d/collision/MOTOMAN_AXIS_R.stl"/>
      </geometry>
      <material name="yellow"/>
    </collision>
  </link>
  <link name="motoman_link_b">
    <inertial>
      <mass value="6.6"/>
      <inertia ixx="0.028669762" ixy="0.0" ixz="0.0" iyy="0.028669762" iyz="0.0" izz="0.0088123"/>
    </inertial>
    <visual>
      <origin rpy="-1.57 0 0" xyz="0 0 0"/>
      <geometry>
        <mesh filename="package://motoman_sia20d_support/meshes/sia20d/visual/MOTOMAN_AXIS_B.stl"/>
      </geometry>
      <material name="blue"/>
    </visual>
    <collision>
      <origin rpy="-1.57 0 0" xyz="0 0 0"/>
      <geometry>
        <mesh filename="package://motoman_sia20d_support/meshes/sia20d/collision/MOTOMAN_AXIS_B.stl"/>
      </geometry>
      <material name="yellow"/>
    </collision>
  </link>
  <link name="motoman_link_t">
    <inertial>
      <mass value="9.36"/>
      <inertia ixx="0.026345268" ixy="0.0" ixz="0.0" iyy="0.026345268" iyz="0.0" izz="0.03381399"/>
      <pose>0 0 0 0 -0 0</pose>
    </inertial>
    <visual>
      <geometry>
        <mesh filename="package://motoman_sia20d_support/meshes/sia20d/visual/MOTOMAN_AXIS_T.stl"/>
      </geometry>
      <material name="silver"/>
    </visual>
    <collision>
      <geometry>
        <mesh filename="package://motoman_sia20d_support/meshes/sia20d/collision/MOTOMAN_AXIS_T.stl"/>
      </geometry>
      <material name="yellow"/>
    </collision>
  </link>
  <!--  <link name="${prefix}tool0" /> -->
  <!-- end of link list -->
  <!-- joint list -->
  <joint name="motoman_joint_s" type="revolute">
    <parent link="motoman_base_link"/>
    <child link="motoman_link_s"/>
    <origin rpy="0 0 0" xyz="0 0 0.41"/>
    <axis xyz="0 0 1"/>
    <limit effort="100" lower="-3.1416" upper="3.1416" velocity="2.26"/>
  </joint>
  <joint name="motoman_joint_l" type="revolute">
    <parent link="motoman_link_s"/>
    <child link="motoman_link_l"/>
    <origin rpy="0 0 0" xyz="0 0 0"/>
    <axis xyz="0 1 0"/>
    <limit effort="100" lower="-1.91" upper="1.91" velocity="2.26"/>
  </joint>
  <joint name="motoman_joint_e" type="revolute">
    <parent link="motoman_link_l"/>
    <child link="motoman_link_e"/>
    <origin rpy="0 0 0" xyz="0 0 0.49"/>
    <axis xyz="0 0 1"/>
    <limit effort="100" lower="-2.96" upper="2.96" velocity="2.96"/>
  </joint>
  <joint name="motoman_joint_u" type="revolute">
    <parent link="motoman_link_e"/>
    <child link="motoman_link_u"/>
    <origin rpy="0 0 0" xyz="0 0 0"/>
    <axis xyz="0 -1 0"/>
    <limit effort="100" lower="-2.26" upper="2.26" velocity="2.96"/>
  </joint>
  <joint name="motoman_joint_r" type="revolute">
    <parent link="motoman_link_u"/>
    <child link="motoman_link_r"/>
    <origin rpy="0 0 0" xyz="0 0 0.420"/>
    <axis xyz="0 0 -1"/>
    <limit effort="100" lower="-3.1416" upper="3.1416" velocity="3.48"/>
  </joint>
  <joint name="motoman_joint_b" type="revolute">
    <parent link="motoman_link_r"/>
    <child link="motoman_link_b"/>
    <origin rpy="0 0 0" xyz="0 0 0"/>
    <axis xyz="0 -1 0"/>
    <limit effort="100" lower="-1.91" upper="1.91" velocity="3.48"/>
  </joint>
  <joint name="motoman_joint_t" type="revolute">
    <parent link="motoman_link_b"/>
    <child link="motoman_link_t"/>
    <origin rpy="0 0 0" xyz="0 0 0.18"/>
    <axis xyz="0 0 -1"/>
    <limit effort="100" lower="-3.1416" upper="3.1416" velocity="6.97"/>
  </joint>
  <!-- end of joint list 
        <joint name="${prefix}base_link-base" type="fixed">
            <origin xyz="0 0 0" rpy="0 0 0" />
            <parent link="${prefix}base_link" />
            <child link="${prefix}base" />
        </joint>-->
  <gazebo reference="motoman_base_link">
    <material>Gazebo/White</material>
  </gazebo>
  <gazebo reference="motoman_link_s">
    <material>Gazebo/Blue</material>
  </gazebo>
  <gazebo reference="motoman_link_l">
    <material>Gazebo/White</material>
  </gazebo>
  <gazebo reference="motoman_link_e">
    <material>Gazebo/Blue</material>
  </gazebo>
  <gazebo reference="motoman_link_u">
    <material>Gazebo/White</material>
  </gazebo>
  <gazebo reference="motoman_link_r">
    <material>Gazebo/Blue</material>
  </gazebo>
  <gazebo reference="motoman_link_b">
    <material>Gazebo/White</material>
  </gazebo>
  <gazebo reference="motoman_link_t">
    <material>Gazebo/Blue</material>
  </gazebo>
  <link name="motoman_robotiq_85_adapter_link">
    <inertial>
      <mass value="0.636951"/>
      <origin xyz="0.0 0.0 0.0"/>
      <inertia ixx="0.000380" ixy="0.000000" ixz="0.000000" iyx="0.000000" iyy="0.001110" iyz="0.000000" izx="0.000000" izy="0.000000" izz="0.001171"/>
    </inertial>
    <visual>
      <geometry>
        <mesh filename="package://robotiq_c2_model_visualization/meshes/robotiq_c2/visual/robotiq_85_gripper_adapter_plate.dae"/>
      </geometry>
      <origin rpy="1.5707 0 1.5707" xyz="0 0 0"/>
    </visual>
    <collision>
      <geometry>
        <mesh filename="package://robotiq_c2_model_visualization/meshes/robotiq_c2/collision/robotiq_85_gripper_adapter_plate.dae"/>
      </geometry>
      <origin rpy="0 0 1.5707" xyz="0 0 0"/>
    </collision>
  </link>
  <!--  /\  -->
  <joint name="motoman_robotiq_85_base_joint" type="fixed">
    <parent link="motoman_robotiq_85_adapter_link"/>
    <child link="motoman_robotiq_85_base_link"/>
    <axis xyz="1 0 0"/>
    <origin rpy="0 0 0" xyz=".0085 0 -.0041"/>
  </joint>
  <!--  \/  -->
  <link name="motoman_robotiq_85_base_link">
    <inertial>
      <mass value="0.636951"/>
      <origin xyz="0.0 0.0 0.0"/>
      <inertia ixx="0.000380" ixy="0.000000" ixz="0.000000" iyx="0.000000" iyy="0.001110" iyz="0.000000" izx="0.000000" izy="0.000000" izz="0.001171"/>
    </inertial>
    <visual>
      <geometry>
        <mesh filename="package://robotiq_c2_model_visualization/meshes/robotiq_c2/visual/robotiq_85_gripper_base.dae"/>
      </geometry>
      <origin rpy="3.1415 0 1.5707" xyz="0 0 0"/>
    </visual>
    <collision>
      <geometry>
        <mesh filename="package://robotiq_c2_model_visualization/meshes/robotiq_c2/collision/robotiq_85_gripper_base.dae"/>
      </geometry>
      <origin rpy="1.5707 0 1.5707" xyz="0 0 0"/>
    </collision>
  </link>
  <!--  /\  -->
  <!--  /\  -->
  <joint name="motoman_robotiq_85_left_knuckle_joint" type="revolute">
    <parent link="motoman_robotiq_85_base_link"/>
    <child link="motoman_robotiq_85_left_knuckle_link"/>
    <axis xyz="1 0 0"/>
    <origin rpy="-1.5707 1.5707 0" xyz=".04191 .0306 0"/>
    <limit effort="1000" lower="0" upper=".8575" velocity="2.0"/>
  </joint>
  <joint name="motoman_robotiq_85_right_knuckle_joint" type="revolute">
    <parent link="motoman_robotiq_85_base_link"/>
    <child link="motoman_robotiq_85_right_knuckle_link"/>
    <axis xyz="1 0 0"/>
    <origin rpy="1.5707 -1.5707 0" xyz=".04191 -.0306 0"/>
    <limit effort="1000" lower="0" upper="1.5707" velocity="2.0"/>
    <mimic joint="motoman_robotiq_85_left_knuckle_joint" multiplier="1"/>
  </joint>
  <!--  \/  -->
  <!--  \/  -->
  <link name="motoman_robotiq_85_left_knuckle_link">
    <inertial>
      <mass value="0.018491"/>
      <origin xyz="0.0 0.0 0.0"/>
      <inertia ixx="0.000009" ixy="-0.000001" ixz="0.000000" iyx="-0.000001" iyy="0.000001" iyz="0.000000" izx="0.000000" izy="0.000000" izz="0.000010"/>
    </inertial>
    <visual>
      <geometry>
        <mesh filename="package://robotiq_c2_model_visualization/meshes/robotiq_c2/visual/robotiq_85_gripper_joint_0_L.dae"/>
      </geometry>
      <origin rpy="3.14159 -1.5707 0" xyz="0 .04191 -.0306"/>
    </visual>
    <collision>
      <geometry>
        <mesh filename="package://robotiq_c2_model_visualization/meshes/robotiq_c2/collision/robotiq_85_gripper_joint_0_L.dae"/>
      </geometry>
      <origin rpy="1.5707 -1.5707 0" xyz="0 .04191 -.0306"/>
    </collision>
  </link>
  <link name="motoman_robotiq_85_right_knuckle_link">
    <inertial>
      <mass value="0.018491"/>
      <origin xyz="0.0 0.0 0.0"/>
      <inertia ixx="0.000009" ixy="-0.000001" ixz="0.000000" iyx="-0.000001" iyy="0.000001" iyz="0.000000" izx="0.000000" izy="0.000000" izz="0.000010"/>
    </inertial>
    <visual>
      <geometry>
        <mesh filename="package://robotiq_c2_model_visualization/meshes/robotiq_c2/visual/robotiq_85_gripper_joint_0_R.dae"/>
      </geometry>
      <origin rpy="3.14159 1.5707 0" xyz="0 .04191 -.0306"/>
    </visual>
    <collision>
      <geometry>
        <mesh filename="package://robotiq_c2_model_visualization/meshes/robotiq_c2/collision/robotiq_85_gripper_joint_0_R.dae"/>
      </geometry>
      <origin rpy="1.5707 1.5707 0" xyz="0 .04191 -.0306"/>
    </collision>
  </link>
  <!--  /\  -->
  <!--  /\  -->
  <joint name="motoman_robotiq_85_left_finger_joint" type="fixed">
    <parent link="motoman_robotiq_85_left_knuckle_link"/>
    <child link="motoman_robotiq_85_left_finger_link"/>
    <axis xyz="1 0 0"/>
    <origin rpy="3.1415 0 0" xyz="0 .00508 .03134"/>
    <limit effort="1000" lower="0" upper="1.5707" velocity="2.0"/>
  </joint>
  <joint name="motoman_robotiq_85_right_finger_joint" type="fixed">
    <parent link="motoman_robotiq_85_right_knuckle_link"/>
    <child link="motoman_robotiq_85_right_finger_link"/>
    <axis xyz="1 0 0"/>
    <origin rpy="3.1415 0 0" xyz="0 .00508 .03134"/>
    <limit effort="1000" lower="0" upper="1.5707" velocity="2.0"/>
  </joint>
  <!--  \/  -->
  <!--  \/  -->
  <link name="motoman_robotiq_85_left_finger_link">
    <inertial>
      <mass value="0.027309"/>
      <origin xyz="0.0 0.0 0.0"/>
      <inertia ixx="0.000003" ixy="-0.000002" ixz="0.000000" iyx="-0.000002" iyy="0.000021" iyz="0.000000" izx="0.000000" izy="0.000000" izz="0.000020"/>
    </inertial>
    <visual>
      <geometry>
        <mesh filename="package://robotiq_c2_model_visualization/meshes/robotiq_c2/visual/robotiq_85_gripper_joint_1_L.dae"/>
      </geometry>
      <origin rpy="0 1.5707 0" xyz="0 -.03683 .06194"/>
    </visual>
    <collision>
      <geometry>
        <mesh filename="package://robotiq_c2_model_visualization/meshes/robotiq_c2/collision/robotiq_85_gripper_joint_1_L.dae"/>
      </geometry>
      <origin rpy="-1.5707 1.5707 0" xyz="0 -.03683 .06194"/>
    </collision>
  </link>
  <link name="motoman_robotiq_85_right_finger_link">
    <inertial>
      <mass value="0.027309"/>
      <origin xyz="0.0 0.0 0.0"/>
      <inertia ixx="0.000003" ixy="-0.000002" ixz="0.000000" iyx="-0.000002" iyy="0.000021" iyz="0.000000" izx="0.000000" izy="0.000000" izz="0.000020"/>
    </inertial>
    <visual>
      <geometry>
        <mesh filename="package://robotiq_c2_model_visualization/meshes/robotiq_c2/visual/robotiq_85_gripper_joint_1_R.dae"/>
      </geometry>
      <origin rpy="0 -1.5707 0" xyz="0 -.03683 .06194"/>
    </visual>
    <collision>
      <geometry>
        <mesh filename="package://robotiq_c2_model_visualization/meshes/robotiq_c2/collision/robotiq_85_gripper_joint_1_R.dae"/>
      </geometry>
      <origin rpy="-1.5707 -1.5707 0" xyz="0 -.03683 .06194"/>
    </collision>
  </link>
  <!--  /\  -->
  <!--  /\  -->
  <joint name="motoman_robotiq_85_left_inner_knuckle_joint" type="revolute">
    <parent link="motoman_robotiq_85_base_link"/>
    <child link="motoman_robotiq_85_left_inner_knuckle_link"/>
    <axis xyz="1 0 0"/>
    <origin rpy="1.5707 1.5707 0" xyz=".04843 .0127 0"/>
    <limit effort="1000" lower="0" upper="1.5707" velocity="2.0"/>
    <mimic joint="motoman_robotiq_85_left_knuckle_joint" offset="0"/>
  </joint>
  <joint name="motoman_robotiq_85_right_inner_knuckle_joint" type="revolute">
    <parent link="motoman_robotiq_85_base_link"/>
    <child link="motoman_robotiq_85_right_inner_knuckle_link"/>
    <axis xyz="1 0 0"/>
    <origin rpy="-1.5707 -1.5707 0" xyz=".04843 -.0127 0"/>
    <limit effort="1000" lower="0" upper="1.5707" velocity="2.0"/>
    <mimic joint="motoman_robotiq_85_left_knuckle_joint" offset="0"/>
  </joint>
  <!--  \/  -->
  <!--  \/  -->
  <link name="motoman_robotiq_85_left_inner_knuckle_link">
    <inertial>
      <mass value="0.029951"/>
      <origin xyz="0.0 0.0 0.0"/>
      <inertia ixx="0.000039" ixy="0.000000" ixz="0.000000" iyx="0.000000" iyy="0.000005" iyz="0.000000" izx="0.000000" izy="0.000000" izz="0.000035"/>
    </inertial>
    <visual>
      <geometry>
        <mesh filename="package://robotiq_c2_model_visualization/meshes/robotiq_c2/visual/robotiq_85_gripper_joint_2_L.dae"/>
      </geometry>
      <origin rpy="0 1.5707 0" xyz="0 -.04843 .0127"/>
    </visual>
    <collision>
      <geometry>
        <mesh filename="package://robotiq_c2_model_visualization/meshes/robotiq_c2/collision/robotiq_85_gripper_joint_2_L.dae"/>
      </geometry>
      <origin rpy="-1.5707 1.5707 0" xyz="0 -.04843 .0127"/>
    </collision>
  </link>
  <link name="motoman_robotiq_85_right_inner_knuckle_link">
    <inertial>
      <mass value="0.029951"/>
      <origin xyz="0.0 0.0 0.0"/>
      <inertia ixx="0.000039" ixy="0.000000" ixz="0.000000" iyx="0.000000" iyy="0.000005" iyz="0.000000" izx="0.000000" izy="0.000000" izz="0.000035"/>
    </inertial>
    <visual>
      <geometry>
        <mesh filename="package://robotiq_c2_model_visualization/meshes/robotiq_c2/visual/robotiq_85_gripper_joint_2_R.dae"/>
      </geometry>
      <origin rpy="0 -1.5707 0" xyz="0 -.04843 .0127"/>
    </visual>
    <collision>
      <geometry>
        <mesh filename="package://robotiq_c2_model_visualization/meshes/robotiq_c2/collision/robotiq_85_gripper_joint_2_R.dae"/>
      </geometry>
      <origin rpy="-1.5707 -1.5707 0" xyz="0 -.04843 .0127"/>
    </collision>
  </link>
  <!--  /\  -->
  <!--  /\  -->
  <joint name="motoman_robotiq_85_left_finger_tip_joint" type="revolute">
    <parent link="motoman_robotiq_85_left_inner_knuckle_link"/>
    <child link="motoman_robotiq_85_left_finger_tip_link"/>
    <axis xyz="1 0 0"/>
    <origin rpy="0 0 0" xyz="0 .04196 -.0388"/>
    <limit effort="1000" lower="0" upper="1.5707" velocity="2.0"/>
    <mimic joint="motoman_robotiq_85_left_knuckle_joint" multiplier="-1"/>
  </joint>
  <joint name="motoman_robotiq_85_right_finger_tip_joint" type="revolute">
    <parent link="motoman_robotiq_85_right_inner_knuckle_link"/>
    <child link="motoman_robotiq_85_right_finger_tip_link"/>
    <axis xyz="1 0 0"/>
    <origin rpy="0 0 0" xyz="0 .04196 -.0388"/>
    <limit effort="1000" lower="0" upper="1.5707" velocity="2.0"/>
    <mimic joint="motoman_robotiq_85_left_knuckle_joint" multiplier="-1"/>
  </joint>
  <!--  \/  -->
  <!--  \/  -->
  <link name="motoman_robotiq_85_left_finger_tip_link">
    <inertial>
      <mass value="0.019555"/>
      <origin xyz="0.0 0.0 0.0"/>
      <inertia ixx="0.000002" ixy="0.000000" ixz="0.000000" iyx="0.000000" iyy="0.000005" iyz="0.000000" izx="0.000000" izy="0.000000" izz="0.000006"/>
    </inertial>
    <visual>
      <geometry>
        <mesh filename="package://robotiq_c2_model_visualization/meshes/robotiq_c2/visual/robotiq_85_gripper_joint_3_L.dae"/>
      </geometry>
      <origin rpy="0 1.5707 0" xyz="0 -.090381 .051505"/>
    </visual>
    <collision>
      <geometry>
        <mesh filename="package://robotiq_c2_model_visualization/meshes/robotiq_c2/collision/robotiq_85_gripper_joint_3_L.dae"/>
      </geometry>
      <origin rpy="-1.5707 1.5707 0" xyz="0 -.090381 .051505"/>
    </collision>
  </link>
  <link name="motoman_robotiq_85_right_finger_tip_link">
    <inertial>
      <mass value="0.019555"/>
      <origin xyz="0.0 0.0 0.0"/>
      <inertia ixx="0.000002" ixy="0.000000" ixz="0.000000" iyx="0.000000" iyy="0.000005" iyz="0.000000" izx="0.000000" izy="0.000000" izz="0.000006"/>
    </inertial>
    <visual>
      <geometry>
        <mesh filename="package://robotiq_c2_model_visualization/meshes/robotiq_c2/visual/robotiq_85_gripper_joint_3_R.dae"/>
      </geometry>
      <origin rpy="0 -1.5707 0" xyz="0 -.090381 .051505"/>
    </visual>
    <collision>
      <geometry>
        <mesh filename="package://robotiq_c2_model_visualization/meshes/robotiq_c2/collision/robotiq_85_gripper_joint_3_R.dae"/>
      </geometry>
      <origin rpy="-1.5707 -1.5707 0" xyz="0 -.090381 .051505"/>
    </collision>
  </link>
  <link name="world"/>
  <!-- Dummy Link -->
  <link name="link0"/>
  <joint name="world_joint" type="fixed">
    <parent link="world"/>
    <child link="link0"/>
    <origin rpy="0 0 0" xyz="0 0 0"/>
    <axis xyz="0 0 1"/>
  </joint>
  <!-- Second Robot -->
  <joint name="motoman_joint_0" type="fixed">
    <parent link="link0"/>
    <child link="motoman_base_link"/>
    <origin rpy="0 0 0" xyz="0 0 0"/>
  </joint>
  <joint name="motoman_link_t-tool0" type="fixed">
    <!--  <origin xyz="0 0 0.0" rpy="0 0 -3.1416"/> -->
    <origin rpy="0  -1.57  0" xyz="0 0 0.0"/>
    <parent link="motoman_link_t"/>
    <child link="motoman_robotiq_85_adapter_link"/>
  </joint>
</robot>
