<?xml version="1.0" ?>
<!-- =================================================================================== -->
<!-- |    This document was autogenerated by xacro from fanuc_only.xacro               | -->
<!-- |    EDITING THIS FILE BY HAND IS NOT RECOMMENDED                                 | -->
<!-- =================================================================================== -->
<robot name="fanuc_lrmate200id" xmlns:xacro="http://ros.org/wiki/xacro">
    <link name="world"/>
    <joint name="fanuc_base_link-base" type="fixed">
        <origin rpy="0 0 0" xyz="0 0 0"/>
        <parent link="world"/>
        <child link="fanuc_base_link"/>
    </joint>
    <!-- links: main serial chain -->
    <link name="fanuc_base_link">
        <visual>
            <origin rpy="0 0 0" xyz="0 0 0"/>
            <geometry>
                <mesh filename="model://fanuc_lrmate200id_support/meshes/lrmate200id/visual/base_link.stl"/>
            </geometry>
            <material name="">
                <color rgba="0.278431372549 0.278431372549 0.278431372549 1.0"/>
            </material>
        </visual>
        <collision>
            <origin rpy="0 0 0" xyz="0 0 0"/>
            <geometry>
                <mesh filename="model://fanuc_lrmate200id_support/meshes/lrmate200id/collision/base_link.stl"/>
            </geometry>
        </collision>
        <inertial>
            <mass value="0.1"/>
            <inertia ixx="0.03" ixy="0.0" ixz="0.0" iyy="0.03" iyz="0.0" izz="0.03"/>
        </inertial>
    </link>
    <link name="fanuc_link_1">
        <visual>
            <origin rpy="0 0 0" xyz="0 0 0"/>
            <geometry>
                <mesh filename="model://fanuc_lrmate200id_support/meshes/lrmate200id/visual/link_1.stl"/>
            </geometry>
            <material name="">
                <color rgba="0.96 0.76 0.13 1.0"/>
            </material>
        </visual>
        <collision>
            <origin rpy="0 0 0" xyz="0 0 0"/>
            <geometry>
                <mesh filename="model://fanuc_lrmate200id_support/meshes/lrmate200id/collision/link_1.stl"/>
            </geometry>
        </collision>
        <inertial>
            <origin rpy="0 0 0" xyz="0 0 0"/>
            <mass value="1"/>
            <inertia ixx="0.0226667" ixy="0.0" ixz="0.0" iyy="0.0226667" iyz="0.0" izz="0.0226667"/>
        </inertial>
    </link>
    <link name="fanuc_link_2">
        <visual>
            <origin rpy="0 0 0" xyz="0 0 0"/>
            <geometry>
                <mesh filename="model://fanuc_lrmate200id_support/meshes/lrmate200id/visual/link_2.stl"/>
            </geometry>
            <material name="">
                <color rgba="0.96 0.76 0.13 1.0"/>
            </material>
        </visual>
        <collision>
            <origin rpy="0 0 0" xyz="0 0 0"/>
            <geometry>
                <mesh filename="model://fanuc_lrmate200id_support/meshes/lrmate200id/collision/link_2.stl"/>
            </geometry>
        </collision>
        <inertial>
            <origin rpy="0 0 0" xyz="0 0 0"/>
            <mass value="1"/>
            <inertia ixx="0.0226667" ixy="0.0" ixz="0.0" iyy="0.0226667" iyz="0.0" izz="0.0226667"/>
        </inertial>
    </link>
    <link name="fanuc_link_3">
        <visual>
            <origin rpy="0 0 0" xyz="0 0 0"/>
            <geometry>
                <mesh filename="model://fanuc_lrmate200id_support/meshes/lrmate200id/visual/link_3.stl"/>
            </geometry>
            <material name="">
                <color rgba="0.96 0.76 0.13 1.0"/>
            </material>
        </visual>
        <collision>
            <origin rpy="0 0 0" xyz="0 0 0"/>
            <geometry>
                <mesh filename="model://fanuc_lrmate200id_support/meshes/lrmate200id/collision/link_3.stl"/>
            </geometry>
        </collision>
        <inertial>
            <origin rpy="0 0 0" xyz="0 0 0"/>
            <mass value="1"/>
            <inertia ixx="0.0226667" ixy="0.0" ixz="0.0" iyy="0.0226667" iyz="0.0" izz="0.0226667"/>
        </inertial>
    </link>
    <link name="fanuc_link_4">
        <visual>
            <origin rpy="0 0 0" xyz="0 0 0"/>
            <geometry>
                <mesh filename="model://fanuc_lrmate200id_support/meshes/lrmate200id/visual/link_4.stl"/>
            </geometry>
            <material name="">
                <color rgba="0.96 0.76 0.13 1.0"/>
            </material>
        </visual>
        <collision>
            <origin rpy="0 0 0" xyz="0 0 0"/>
            <geometry>
                <mesh filename="model://fanuc_lrmate200id_support/meshes/lrmate200id/collision/link_4.stl"/>
            </geometry>
        </collision>
        <inertial>
            <origin rpy="0 0 0" xyz="0 0 0"/>
            <mass value="1"/>
            <inertia ixx="0.0226667" ixy="0.0" ixz="0.0" iyy="0.0226667" iyz="0.0" izz="0.0226667"/>
        </inertial>
    </link>
    <link name="fanuc_link_5">
        <visual>
            <origin rpy="0 0 0" xyz="0 0 0"/>
            <geometry>
                <mesh filename="model://fanuc_lrmate200id_support/meshes/lrmate200id/visual/link_5.stl"/>
            </geometry>
            <material name="">
                <color rgba="0.96 0.76 0.13 1.0"/>
            </material>
        </visual>
        <collision>
            <origin rpy="0 0 0" xyz="0 0 0"/>
            <geometry>
                <mesh filename="model://fanuc_lrmate200id_support/meshes/lrmate200id/collision/link_5.stl"/>
            </geometry>
        </collision>
        <inertial>
            <origin rpy="0 0 0" xyz="0 0 0"/>
            <mass value="1"/>
            <inertia ixx="0.0226667" ixy="0.0" ixz="0.0" iyy="0.0226667" iyz="0.0" izz="0.0226667"/>
        </inertial>
    </link>
    <link name="fanuc_link_6">
        <visual>
            <origin rpy="0 0 0" xyz="0 0 0"/>
            <geometry>
                <mesh filename="model://fanuc_lrmate200id_support/meshes/lrmate200id/visual/link_6.stl"/>
            </geometry>
            <material name="">
                <color rgba="0.15 0.15 0.15 1.0"/>
            </material>
        </visual>
        <collision>
            <origin rpy="0 0 0" xyz="0 0 0"/>
            <geometry>
                <mesh filename="model://fanuc_lrmate200id_support/meshes/lrmate200id/collision/link_6.stl"/>
            </geometry>
        </collision>
        <inertial>
            <origin rpy="0 0 0" xyz="0 0 0"/>
            <mass value="1"/>
            <inertia ixx="0.0226667" ixy="0.0" ixz="0.0" iyy="0.0226667" iyz="0.0" izz="0.0226667"/>
        </inertial>
    </link>
    <gazebo reference="fanuc_base_link">
        <static>1</static>
        <gravity>0</gravity>
        <material>Gazebo/White</material>
    </gazebo>
    <gazebo reference="fanuc_link_1">
        <static>p</static>
        <gravity>0</gravity>
        <kinematic>1</kinematic>
        <material>Gazebo/Yellow</material>
    </gazebo>
    <gazebo reference="fanuc_link_2">
        <static>0</static>
        <gravity>0</gravity>
        <kinematic>1</kinematic>
        <material>Gazebo/Yellow</material>
    </gazebo>
    <gazebo reference="fanuc_link_3">
        <static>0</static>
        <gravity>0</gravity>
        <kinematic>1</kinematic>
        <material>Gazebo/Yellow</material>
    </gazebo>
    <gazebo reference="fanuc_link_4">
        <static>0</static>
        <gravity>0</gravity>
        <kinematic>1</kinematic>
        <material>Gazebo/Yellow</material>
    </gazebo>
    <gazebo reference="fanuc_link_5">
        <static>0</static>
        <gravity>0</gravity>
        <kinematic>1</kinematic>
        <material>Gazebo/Yellow</material>
    </gazebo>
    <gazebo reference="fanuc_link_6">
        <static>0</static>
        <gravity>1</gravity>
        <kinematic>0</kinematic>
        <material>Gazebo/Yellow</material>
    </gazebo>
    <!--   JOINTS -->
    <joint name="fanuc_joint_1" type="revolute">
        <origin rpy="0 0 0" xyz="0 0 0.330"/>
        <parent link="fanuc_base_link"/>
        <child link="fanuc_link_1"/>
        <axis xyz="0 0 1"/>
        <limit effort="0" lower="-2.965" upper="2.965" velocity="7.85"/>
    </joint>
    <joint name="fanuc_joint_2" type="revolute">
        <origin rpy="0 0 0" xyz="0.050 0 0"/>
        <parent link="fanuc_link_1"/>
        <child link="fanuc_link_2"/>
        <axis xyz="0 1 0"/>
        <limit effort="0" lower="-1.745329" upper="2.530727" velocity="6.63"/>
    </joint>
    <joint name="fanuc_joint_3" type="revolute">
        <origin rpy="0 0 0" xyz="0 0 0.330"/>
        <parent link="fanuc_link_2"/>
        <child link="fanuc_link_3"/>
        <axis xyz="0 -1 0"/>
        <limit effort="0" lower="-2.450966" upper="4.886922" velocity="9.08"/>
    </joint>
    <joint name="fanuc_joint_4" type="revolute">
        <origin rpy="0 0 0" xyz="0 0 0.035"/>
        <parent link="fanuc_link_3"/>
        <child link="fanuc_link_4"/>
        <axis xyz="-1 0 0"/>
        <limit effort="0" lower="-3.315" upper="3.315" velocity="9.6"/>
    </joint>
    <joint name="fanuc_joint_5" type="revolute">
        <origin rpy="0 0 0" xyz="0.335 0 0"/>
        <parent link="fanuc_link_4"/>
        <child link="fanuc_link_5"/>
        <axis xyz="0 -1 0"/>
        <limit effort="0" lower="-2.18" upper="2.18" velocity="9.51"/>
    </joint>
    <joint name="fanuc_joint_6" type="revolute">
        <origin rpy="0 0 0" xyz="0.080 0 0"/>
        <parent link="fanuc_link_5"/>
        <child link="fanuc_link_6"/>
        <axis xyz="-1 0 0"/>
        <limit effort="0" lower="-6.285" upper="6.285" velocity="17.45"/>
        <physics>
            <provide_feedback>true</provide_feedback>
        </physics>
    </joint>
    <link name="fanuc_finger_1">
        <visual>
            <origin rpy="0 0 0" xyz="0 0 0"/>
            <geometry>
                <mesh filename="model://fanuc_lrmate200id_support/meshes/lrmate200id/visual/fanuc_finger_1.STL"/>
            </geometry>
            <material name="">
                <color rgba="0.15 0.15 0.15 1.0"/>
            </material>
        </visual>
        <collision>
            <origin rpy="0 0 0" xyz="0 0 0"/>
            <geometry>
                <mesh filename="model://fanuc_lrmate200id_support/meshes/lrmate200id/collision/fanuc_finger_1.STL"/>
            </geometry>
        </collision>
        <inertial>
            <origin rpy="0 0 0" xyz="0 0 0"/>
            <mass value="1"/>
            <inertia ixx="1e-3" ixy="0.0" ixz="0.0" iyy="1e-3" iyz="0.0" izz="1e-3"/>
        </inertial>
    </link>
    <link name="fanuc_finger_2">
        <visual>
            <origin rpy="0 0 0" xyz="0 0 0"/>
            <geometry>
                <mesh filename="model://fanuc_lrmate200id_support/meshes/lrmate200id/visual/fanuc_finger_2.STL"/>
            </geometry>
            <material name="">
                <color rgba="0.15 0.15 0.15 1.0"/>
            </material>
        </visual>
        <collision>
            <origin rpy="0 0 0" xyz="0 0 0"/>
            <geometry>
                <mesh filename="model://fanuc_lrmate200id_support/meshes/lrmate200id/collision/fanuc_finger_2.STL"/>
            </geometry>
        </collision>
        <inertial>
            <origin rpy="0 0 0" xyz="0 0 0"/>
            <mass value="1"/>
            <inertia ixx="1e-3" ixy="0.0" ixz="0.0" iyy="1e-3" iyz="0.0" izz="1e-3"/>
        </inertial>
    </link>
    <joint name="fanuc_prism1" type="prismatic">
        <origin rpy="-3.14159  0       1.5708" xyz="0.0 0.02    0.01099"/>
        <parent link="fanuc_link_6"/>
        <child link="fanuc_finger_1"/>
        <axis xyz="-1 0 0 "/>
        <limit effort="1000" lower="-0.008" upper="0.01" velocity="1000"/>
    </joint>
    <joint name="fanuc_prism2" type="prismatic">
        <origin rpy="-3.14159  0      -1.5708" xyz="0.0 0 -0.01099"/>
        <parent link="fanuc_link_6"/>
        <child link="fanuc_finger_2"/>
        <axis xyz="-1 0 0"/>
        <limit effort="1000" lower="-0.008" upper="0.0" velocity="1000"/>
    </joint>
    <gazebo reference="fanuc_finger_1">
        <material>Gazebo/White</material>
        <turnGravityOff>true</turnGravityOff>
    </gazebo>
    <gazebo reference="fanuc_finger_2">
        <material>Gazebo/Yellow</material>
        <turnGravityOff>true</turnGravityOff>
    </gazebo>
    <gazebo>
        <plugin name="ft_sensor" filename="gazebo_ros_ft_sensor.dll">
            <updateRate>50.0</updateRate>
            <topicName>ft_sensor_topic</topicName>
            <jointName>fanuc_joint_6</jointName>
        </plugin>
    </gazebo>
    <gazebo reference="fanuc_joint_6">
        <provideFeedback>true</provideFeedback>
    </gazebo>
    <gazebo>
        <plugin filename="C:\opt\ros\noetic\gztaskboard\pluginswin\gripper_plugin.dll" name="ParallelGripperPlugin">
            <robotNamespace>/lrmate</robotNamespace>
            <grip_force_close>5</grip_force_close>
            <joint1>lrmate::fanuc_prism1</joint1>
            <joint2>lrmate::fanuc_prism2</joint2>
            <grip_kp>10000</grip_kp>
            <control_topic>/fanuc_lrmate200id/control</control_topic>
            <debug>1</debug>
            <fulldebug>0</fulldebug>
            <collisions>1</collisions>
            <synchronous> 0  </synchronous>
        </plugin>
    </gazebo>
    <gazebo>
        <plugin name="gazebo_ros_joint_state_publisher" 
            filename="C:\opt\ros\noetic\gztaskboard\pluginswin\gazebo_ros_joint_state_publisher.dll">
            <service_topic>/lrmate/gazebo_ros_joint_state_publisher_service</service_topic>
            <robotNamespace>lrmate</robotNamespace>
            <debug> 0 </debug>
            <jointName>fanuc_joint_1, fanuc_joint_2, fanuc_joint_3, fanuc_joint_4, fanuc_joint_5, fanuc_joint_6   </jointName>
        </plugin>
    </gazebo>
    <gazebo>
        <plugin name="gazebo_ros_guarded_move"
        filename="C:\opt\ros\noetic\gztaskboard\pluginswin\gazebo_ros_guarded_move.dll">
            <service_topic>/lrmate/gazebo_ros_guarded_move</service_topic>
            <robotNamespace>lrmate</robotNamespace>
            <debug> 1 </debug>
            <updateRate>  10  </updateRate>
            <jointName>fanuc_joint_1, fanuc_joint_2, fanuc_joint_3, fanuc_joint_4, fanuc_joint_5, fanuc_joint_6   </jointName>
            <forceTorqueJoint>fanuc_joint_6</forceTorqueJoint>
        </plugin>
    </gazebo>
</robot>