<?xml version="1.0" encoding="UTF-8"?>
<!-- =================================================================================== -->
<!-- |    This document was autogenerated by xacro from motoman_only.xacro             | -->
<!-- |    EDITING THIS FILE BY HAND IS NOT RECOMMENDED                                 | -->
<!-- =================================================================================== -->
<robot xmlns:xacro="http://ros.org/wiki/xacro" name="motoman_sia20d">
   <!-- link list -->
   <link name="motoman_base_link">
      <inertial>
         <mass value="150" />
         <inertia ixx="1" ixy="0.0" ixz="0.0" iyy="1" iyz="0.0" izz="1" />
      </inertial>
      <visual>
         <geometry>
            <mesh filename="model://motoman_sia20d_support/meshes/sia20d/visual/MOTOMAN_BASE.stl" />
         </geometry>
         <material name="blue">
            <color rgba="0 0 1 1" />
         </material>
      </visual>
      <collision>
         <geometry>
            <mesh filename="model://motoman_sia20d_support/meshes/sia20d/collision/MOTOMAN_BASE.stl" />
         </geometry>
         <material name="yellow">
            <color rgba="0 1 1 1" />
         </material>
      </collision>
   </link>
   <link name="motoman_link_s">
      <inertial>
         <mass value="34.5" />
         <inertia ixx="0.502079701" ixy="0.0" ixz="0.0" iyy="0.502079701" iyz="0.0" izz="0.12956896" />
      </inertial>
      <visual>
         <origin rpy="0 0 3.1416" xyz="0 0 0" />
         <geometry>
            <mesh filename="model://motoman_sia20d_support/meshes/sia20d/visual/MOTOMAN_AXIS_S.stl" />
         </geometry>
         <material name="silver">
            <color rgba="0.8 0.8 0.8 1" />
         </material>
      </visual>
      <collision>
         <origin rpy="0 0 3.1416" xyz="0 0 0" />
         <geometry>
            <mesh filename="model://motoman_sia20d_support/meshes/sia20d/collision/MOTOMAN_AXIS_S.stl" />
         </geometry>
         <material name="yellow" />
      </collision>
   </link>
   <link name="motoman_link_l">
      <inertial>
         <mass value="30.6" />
         <inertia ixx="0.310135823" ixy="0.0" ixz="0.0" iyy="0.310135823" iyz="0.0" izz="0.12889481" />
      </inertial>
      <visual>
         <origin rpy="1.57 3.1416 3.1416" xyz="0 0 0" />
         <geometry>
            <mesh filename="model://motoman_sia20d_support/meshes/sia20d/visual/MOTOMAN_AXIS_L.stl" />
         </geometry>
         <material name="blue" />
      </visual>
      <collision>
         <origin rpy="1.57 3.1416 3.1416" xyz="0 0 0" />
         <geometry>
            <mesh filename="model://motoman_sia20d_support/meshes/sia20d/collision/MOTOMAN_AXIS_L.stl" />
         </geometry>
         <material name="yellow" />
      </collision>
   </link>
   <link name="motoman_link_e">
      <inertial>
         <mass value="18.54" />
         <inertia ixx="0.147277445" ixy="0.0" ixz="0.0" iyy="0.147277445" iyz="0.0" izz="0.05217123" />
      </inertial>
      <visual>
         <origin rpy="0 0 0" xyz="0 0 0" />
         <geometry>
            <mesh filename="model://motoman_sia20d_support/meshes/sia20d/visual/MOTOMAN_AXIS_E.stl" />
         </geometry>
         <material name="silver" />
      </visual>
      <collision>
         <origin rpy="0 0 0" xyz="0 0 0" />
         <geometry>
            <mesh filename="model://motoman_sia20d_support/meshes/sia20d/collision/MOTOMAN_AXIS_E.stl" />
         </geometry>
         <material name="yellow" />
      </collision>
   </link>
   <link name="motoman_link_u">
      <inertial>
         <mass value="12.9" />
         <inertia ixx="0.086548013" ixy="0.0" ixz="0.0" iyy="0.086548013" iyz="0.0" izz="0.02733095" />
      </inertial>
      <visual>
         <origin rpy="1.57 -3.1415 3.1416" xyz="0 0 0" />
         <geometry>
            <mesh filename="model://motoman_sia20d_support/meshes/sia20d/visual/MOTOMAN_AXIS_U.stl" />
         </geometry>
         <material name="blue" />
      </visual>
      <collision>
         <origin rpy="1.57 -3.1415 3.1416" xyz="0 0 0" />
         <geometry>
            <mesh filename="model://motoman_sia20d_support/meshes/sia20d/collision/MOTOMAN_AXIS_U.stl" />
         </geometry>
         <material name="yellow" />
      </collision>
   </link>
   <link name="motoman_link_r">
      <inertial>
         <mass value="7.3" />
         <inertia ixx="0.034967411" ixy="0.0" ixz="0.0" iyy="0.034967411" iyz="0.0" izz="0.01048203" />
      </inertial>
      <visual>
         <origin rpy="0 0 0" xyz="0 0 0" />
         <geometry>
            <mesh filename="model://motoman_sia20d_support/meshes/sia20d/visual/MOTOMAN_AXIS_R.stl" />
         </geometry>
         <material name="silver" />
      </visual>
      <collision>
         <origin rpy="0 0 0" xyz="0 0 0" />
         <geometry>
            <mesh filename="model://motoman_sia20d_support/meshes/sia20d/collision/MOTOMAN_AXIS_R.stl" />
         </geometry>
         <material name="yellow" />
      </collision>
   </link>
   <link name="motoman_link_b">
      <inertial>
         <mass value="6.6" />
         <inertia ixx="0.028669762" ixy="0.0" ixz="0.0" iyy="0.028669762" iyz="0.0" izz="0.0088123" />
      </inertial>
      <visual>
         <origin rpy="-1.57 0 0" xyz="0 0 0" />
         <geometry>
            <mesh filename="model://motoman_sia20d_support/meshes/sia20d/visual/MOTOMAN_AXIS_B.stl" />
         </geometry>
         <material name="blue" />
      </visual>
      <collision>
         <origin rpy="-1.57 0 0" xyz="0 0 0" />
         <geometry>
            <mesh filename="model://motoman_sia20d_support/meshes/sia20d/collision/MOTOMAN_AXIS_B.stl" />
         </geometry>
         <material name="yellow" />
      </collision>
   </link>
   <link name="motoman_link_t">
      <inertial>
         <mass value="9.36" />
         <inertia ixx="0.026345268" ixy="0.0" ixz="0.0" iyy="0.026345268" iyz="0.0" izz="0.03381399" />
         <pose>0 0 0 0 -0 0</pose>
      </inertial>
      <visual>
         <geometry>
            <mesh filename="model://motoman_sia20d_support/meshes/sia20d/visual/MOTOMAN_AXIS_T.stl" />
         </geometry>
         <material name="silver" />
      </visual>
      <collision>
         <geometry>
            <mesh filename="model://motoman_sia20d_support/meshes/sia20d/collision/MOTOMAN_AXIS_T.stl" />
         </geometry>
         <material name="yellow" />
      </collision>
   </link>
   <gazebo reference="motoman_base_link">
      <static>1</static>
      <gravity>0</gravity>
      <material>Gazebo/White</material>
   </gazebo>
   <gazebo reference="motoman_link_s">
      <static>p</static>
      <gravity>0</gravity>
      <kinematic>1</kinematic>
      <material>Gazebo/Blue</material>
   </gazebo>
   <gazebo reference="motoman_link_l">
      <static>0</static>
      <gravity>0</gravity>
      <kinematic>1</kinematic>
      <material>Gazebo/White</material>
   </gazebo>
   <gazebo reference="motoman_link_e">
      <static>0</static>
      <gravity>0</gravity>
      <kinematic>1</kinematic>
      <material>Gazebo/Blue</material>
   </gazebo>
   <gazebo reference="motoman_link_u">
      <static>0</static>
      <gravity>0</gravity>
      <kinematic>1</kinematic>
      <material>Gazebo/White</material>
   </gazebo>
   <gazebo reference="motoman_link_r">
      <static>0</static>
      <gravity>0</gravity>
      <kinematic>1</kinematic>
      <material>Gazebo/Blue</material>
   </gazebo>
   <gazebo reference="motoman_link_b">
      <static>0</static>
      <gravity>0</gravity>
      <kinematic>1</kinematic>
      <material>Gazebo/White</material>
   </gazebo>
   <gazebo reference="motoman_link_t">
      <static>0</static>
      <gravity>0</gravity>
      <kinematic>1</kinematic>
      <material>Gazebo/Blue</material>
   </gazebo>

   <!-- end of link list -->
   <!-- joint list -->
   <joint name="motoman_joint_s" type="revolute">
      <parent link="motoman_base_link" />
      <child link="motoman_link_s" />
      <origin rpy="0 0 0" xyz="0 0 0.41" />
      <axis xyz="0 0 1" />
      <limit effort="100" lower="-3.1416" upper="3.1416" velocity="2.26" />
   </joint>
   <joint name="motoman_joint_l" type="revolute">
      <parent link="motoman_link_s" />
      <child link="motoman_link_l" />
      <origin rpy="0 0 0" xyz="0 0 0" />
      <axis xyz="0 1 0" />
      <limit effort="100" lower="-1.91" upper="1.91" velocity="2.26" />
   </joint>
   <joint name="motoman_joint_e" type="revolute">
      <parent link="motoman_link_l" />
      <child link="motoman_link_e" />
      <origin rpy="0 0 0" xyz="0 0 0.49" />
      <axis xyz="0 0 1" />
      <limit effort="100" lower="-2.96" upper="2.96" velocity="2.96" />
   </joint>
   <joint name="motoman_joint_u" type="revolute">
      <parent link="motoman_link_e" />
      <child link="motoman_link_u" />
      <origin rpy="0 0 0" xyz="0 0 0" />
      <axis xyz="0 -1 0" />
      <limit effort="100" lower="-2.26" upper="2.26" velocity="2.96" />
   </joint>
   <joint name="motoman_joint_r" type="revolute">
      <parent link="motoman_link_u" />
      <child link="motoman_link_r" />
      <origin rpy="0 0 0" xyz="0 0 0.420" />
      <axis xyz="0 0 -1" />
      <limit effort="100" lower="-3.1416" upper="3.1416" velocity="3.48" />
   </joint>
   <joint name="motoman_joint_b" type="revolute">
      <parent link="motoman_link_r" />
      <child link="motoman_link_b" />
      <origin rpy="0 0 0" xyz="0 0 0" />
      <axis xyz="0 -1 0" />
      <limit effort="100" lower="-1.91" upper="1.91" velocity="3.48" />
   </joint>
   <joint name="motoman_joint_t" type="revolute">
      <parent link="motoman_link_b" />
      <child link="motoman_link_t" />
      <origin rpy="0 0 0" xyz="0 0 0.18" />
      <axis xyz="0 0 -1" />
      <limit effort="100" lower="-3.1416" upper="3.1416" velocity="6.97" />
   </joint>
   <!-- end of joint list -->
  
   <link name="world" />
   <!-- Dummy Link -->
   <link name="link0" />
   <joint name="world_joint" type="fixed">
      <parent link="world" />
      <child link="link0" />
      <origin rpy="0 0 0" xyz="0 0 0" />
      <axis xyz="0 0 1" />
   </joint>
   <!-- Second Robot -->
   <joint name="motoman_joint_0" type="fixed">
      <parent link="link0" />
      <child link="motoman_base_link" />
      <origin rpy="0 0 0" xyz="0 0 0" />
   </joint>


  <!-- gripper -->
  <link name="motoman_finger_1">
    <inertial>
      <mass value=".1"/>
      <origin rpy="0 0 0" xyz="0 0 0"/>
      <inertia ixx="0.1" ixy="0" ixz="0" iyy="0.1" iyz="0" izz="0.1"/>
    </inertial>
    <collision name="motoman_right_finger_collision">
      <origin rpy="0 0 0" xyz="0 0 0"/>
      <geometry>
        <mesh filename="model://motoman_sia20d_support/meshes/sia20d/visual/motoman_finger_1.STL" scale="1 1 1"/>
      </geometry>
    </collision>
    <visual name="motoman_right_finger_visual">
      <origin rpy="0 0 0" xyz="0 0 0"/>
      <geometry>
        <mesh filename="model://motoman_sia20d_support/meshes/sia20d/collision/motoman_finger_1.STL" scale="1 1 1"/>
      </geometry>
    </visual>
  </link>
  <link name="motoman_finger_2">
    <inertial>
      <mass value=".1"/>
      <origin rpy="0 0 0" xyz="0 0 0"/>
      <inertia ixx="0.001" ixy="0" ixz="0" iyy="0.001" iyz="0" izz="0.001"/>
    </inertial>
    <collision name="motoman_left_finger_collision">
      <origin rpy="0 0 0" xyz="0 0 0"/>
      <geometry>
        <mesh filename="model://motoman_sia20d_support/meshes/sia20d/collision/motoman_finger_2.STL" scale="1 1 1"/>
      </geometry>
    </collision>
    <visual name="motoman_left_finger_visual">
      <origin rpy="0 0 0" xyz="0 0 0"/>
      <geometry>
        <mesh filename="model://motoman_sia20d_support/meshes/sia20d/visual/motoman_finger_2.STL" scale="1 1 1"/>
      </geometry>
    </visual>
  </link>
  <joint name="motoman_prism1" type="prismatic">
    <parent link="motoman_link_t"/>
    <child link="motoman_finger_1"/>
    <origin rpy="1.5708 0     0" xyz="0     0     0.00821"/>
    <axis xyz="-1  0  0"/>
    <limit effort="100.0" lower="-0.02" upper="0.0" velocity="10.0"/>
  </joint>
  <joint name="motoman_prism2" type="prismatic">
    <parent link="motoman_link_t"/>
    <child link="motoman_finger_2"/>
    <origin rpy="1.5708   0      -3.14159" xyz="0     0     0.00821"/>
    <axis xyz="-1  0  0"/>
    <limit effort="1000.0" lower="-0.02" upper="0.0" velocity="10.0"/>
  </joint>
  <gazebo reference="motoman_finger_1">
    <material>Gazebo/White</material>
    <turnGravityOff>true</turnGravityOff>
  </gazebo>
  <gazebo reference="motoman_finger_2">
    <material>Gazebo/White</material>
    <turnGravityOff>true</turnGravityOff>
  </gazebo>


</robot>