<sdf version='1.6'>
  <model name='motoman_sia20d'>
    <link name='base_link'>
      <pose frame=''>0 0 0 0 -0 0</pose>
      <inertial>
        <pose frame=''>0 0 0 0 -0 0</pose>
        <mass>500</mass>
        <inertia>
          <ixx>100</ixx>
          <ixy>0</ixy>
          <ixz>0</ixz>
          <iyy>100</iyy>
          <iyz>0</iyz>
          <izz>100</izz>
        </inertia>
      </inertial>
      <collision name='base_link_collision'>
        <pose frame=''>0 0 0 0 -0 0</pose>
        <geometry>
          <mesh>
            <scale>1 1 1</scale>
            <uri>model://motoman_aprs/meshes/sia20d/collision/MOTOMAN_BASE.stl</uri>
          </mesh>
        </geometry>
      </collision>
      <visual name='base_link_visual'>
        <pose frame=''>0 0 0 0 -0 0</pose>
        <geometry>
          <mesh>
            <scale>1 1 1</scale>
            <uri>model://motoman_aprs/meshes/sia20d/visual/MOTOMAN_BASE.stl</uri>
          </mesh>
        </geometry>
      </visual>
    </link>
    <link name='link_s'>
      <pose frame=''>0 0 0.41 0 -0 0</pose>
      <inertial>
        <pose frame=''>0 0 0 0 -0 0</pose>
        <mass>5</mass>
        <inertia>
          <ixx>1</ixx>
          <ixy>0</ixy>
          <ixz>0</ixz>
          <iyy>1</iyy>
          <iyz>0</iyz>
          <izz>1</izz>
        </inertia>
      </inertial>
      <collision name='link_s_collision'>
        <pose frame=''>0 0 0 0 -0 -3.14159</pose>
        <geometry>
          <mesh>
            <scale>1 1 1</scale>
            <uri>model://motoman_aprs/meshes/sia20d/collision/MOTOMAN_AXIS_S.stl</uri>
          </mesh>
        </geometry>
      </collision>
      <visual name='link_s_visual'>
        <pose frame=''>0 0 0 0 -0 -3.14159</pose>
        <geometry>
          <mesh>
            <scale>1 1 1</scale>
            <uri>model://motoman_aprs/meshes/sia20d/visual/MOTOMAN_AXIS_S.stl</uri>
          </mesh>
        </geometry>
      </visual>
    </link>
    <joint name='joint_s' type='revolute'>
      <child>link_s</child>
      <parent>base_link</parent>
      <axis>
        <xyz>0 0 1</xyz>
        <limit>
          <lower>-3.1416</lower>
          <upper>3.1416</upper>
          <effort>100</effort>
          <velocity>2.26</velocity>
        </limit>
        <dynamics>
          <spring_reference>0</spring_reference>
          <spring_stiffness>0</spring_stiffness>
        </dynamics>
        <use_parent_model_frame>1</use_parent_model_frame>
      </axis>
    </joint>
    <link name='link_l'>
      <pose frame=''>0 0 0.41 0 -0 0</pose>
      <inertial>
        <pose frame=''>0 0 0 0 -0 0</pose>
        <mass>5</mass>
        <inertia>
          <ixx>1</ixx>
          <ixy>0</ixy>
          <ixz>0</ixz>
          <iyy>1</iyy>
          <iyz>0</iyz>
          <izz>1</izz>
        </inertia>
      </inertial>
      <collision name='link_l_collision'>
        <pose frame=''>0 0 0 -1.57159 -7e-06 7e-06</pose>
        <geometry>
          <mesh>
            <scale>1 1 1</scale>
            <uri>model://motoman_aprs/meshes/sia20d/collision/MOTOMAN_AXIS_L.stl</uri>
          </mesh>
        </geometry>
      </collision>
      <visual name='link_l_visual'>
        <pose frame=''>0 0 0 -1.57159 -7e-06 7e-06</pose>
        <geometry>
          <mesh>
            <scale>1 1 1</scale>
            <uri>model://motoman_aprs/meshes/sia20d/visual/MOTOMAN_AXIS_L.stl</uri>
          </mesh>
        </geometry>
      </visual>
    </link>
    <joint name='joint_l' type='revolute'>
      <child>link_l</child>
      <parent>link_s</parent>
      <axis>
        <xyz>0 1 0</xyz>
        <limit>
          <lower>-1.91</lower>
          <upper>1.91</upper>
          <effort>100</effort>
          <velocity>2.26</velocity>
        </limit>
        <dynamics>
          <spring_reference>0</spring_reference>
          <spring_stiffness>0</spring_stiffness>
        </dynamics>
        <use_parent_model_frame>1</use_parent_model_frame>
      </axis>
    </joint>
    <link name='link_e'>
      <pose frame=''>0 0 0.9 0 -0 0</pose>
      <inertial>
        <pose frame=''>0 0 0 0 -0 0</pose>
        <mass>5</mass>
        <inertia>
          <ixx>1</ixx>
          <ixy>0</ixy>
          <ixz>0</ixz>
          <iyy>1</iyy>
          <iyz>0</iyz>
          <izz>1</izz>
        </inertia>
      </inertial>
      <collision name='link_e_collision'>
        <pose frame=''>0 0 0 0 -0 0</pose>
        <geometry>
          <mesh>
            <scale>1 1 1</scale>
            <uri>model://motoman_aprs/meshes/sia20d/collision/MOTOMAN_AXIS_E.stl</uri>
          </mesh>
        </geometry>
      </collision>
      <visual name='link_e_visual'>
        <pose frame=''>0 0 0 0 -0 0</pose>
        <geometry>
          <mesh>
            <scale>1 1 1</scale>
            <uri>model://motoman_aprs/meshes/sia20d/visual/MOTOMAN_AXIS_E.stl</uri>
          </mesh>
        </geometry>
      </visual>
    </link>
    <joint name='joint_e' type='revolute'>
      <child>link_e</child>
      <parent>link_l</parent>
      <axis>
        <xyz>0 0 1</xyz>
        <limit>
          <lower>-2.96</lower>
          <upper>2.96</upper>
          <effort>100</effort>
          <velocity>2.96</velocity>
        </limit>
        <dynamics>
          <spring_reference>0</spring_reference>
          <spring_stiffness>0</spring_stiffness>
        </dynamics>
        <use_parent_model_frame>1</use_parent_model_frame>
      </axis>
    </joint>
    <link name='link_u'>
      <pose frame=''>0 0 0.9 0 -0 0</pose>
      <inertial>
        <pose frame=''>0 0 0 0 -0 0</pose>
        <mass>5</mass>
        <inertia>
          <ixx>1</ixx>
          <ixy>0</ixy>
          <ixz>0</ixz>
          <iyy>1</iyy>
          <iyz>0</iyz>
          <izz>1</izz>
        </inertia>
      </inertial>
      <collision name='link_u_collision'>
        <pose frame=''>0 0 0 -1.57159 -9.3e-05 7e-06</pose>
        <geometry>
          <mesh>
            <scale>1 1 1</scale>
            <uri>model://motoman_aprs/meshes/sia20d/collision/MOTOMAN_AXIS_U.stl</uri>
          </mesh>
        </geometry>
      </collision>
      <visual name='link_u_visual'>
        <pose frame=''>0 0 0 -1.57159 -9.3e-05 7e-06</pose>
        <geometry>
          <mesh>
            <scale>1 1 1</scale>
            <uri>model://motoman_aprs/meshes/sia20d/visual/MOTOMAN_AXIS_U.stl</uri>
          </mesh>
        </geometry>
      </visual>
    </link>
    <joint name='joint_u' type='revolute'>
      <child>link_u</child>
      <parent>link_e</parent>
      <axis>
        <xyz>0 -1 0</xyz>
        <limit>
          <lower>-2.26</lower>
          <upper>2.26</upper>
          <effort>100</effort>
          <velocity>2.96</velocity>
        </limit>
        <dynamics>
          <spring_reference>0</spring_reference>
          <spring_stiffness>0</spring_stiffness>
        </dynamics>
        <use_parent_model_frame>1</use_parent_model_frame>
      </axis>
    </joint>
    <link name='link_r'>
      <pose frame=''>0 0 1.32 0 -0 0</pose>
      <inertial>
        <pose frame=''>0 0 0 0 -0 0</pose>
        <mass>5</mass>
        <inertia>
          <ixx>1</ixx>
          <ixy>0</ixy>
          <ixz>0</ixz>
          <iyy>1</iyy>
          <iyz>0</iyz>
          <izz>1</izz>
        </inertia>
      </inertial>
      <collision name='link_r_collision'>
        <pose frame=''>0 0 0 0 -0 0</pose>
        <geometry>
          <mesh>
            <scale>1 1 1</scale>
            <uri>model://motoman_aprs/meshes/sia20d/collision/MOTOMAN_AXIS_R.stl</uri>
          </mesh>
        </geometry>
      </collision>
      <visual name='link_r_visual'>
        <pose frame=''>0 0 0 0 -0 0</pose>
        <geometry>
          <mesh>
            <scale>1 1 1</scale>
            <uri>model://motoman_aprs/meshes/sia20d/visual/MOTOMAN_AXIS_R.stl</uri>
          </mesh>
        </geometry>
      </visual>
    </link>
    <joint name='joint_r' type='revolute'>
      <child>link_r</child>
      <parent>link_u</parent>
      <axis>
        <xyz>0 0 -1</xyz>
        <limit>
          <lower>-3.1416</lower>
          <upper>3.1416</upper>
          <effort>100</effort>
          <velocity>3.48</velocity>
        </limit>
        <dynamics>
          <spring_reference>0</spring_reference>
          <spring_stiffness>0</spring_stiffness>
        </dynamics>
        <use_parent_model_frame>1</use_parent_model_frame>
      </axis>
    </joint>
    <link name='link_b'>
      <pose frame=''>0 0 1.32 0 -0 0</pose>
      <inertial>
        <pose frame=''>0 0 0 0 -0 0</pose>
        <mass>5</mass>
        <inertia>
          <ixx>1</ixx>
          <ixy>0</ixy>
          <ixz>0</ixz>
          <iyy>1</iyy>
          <iyz>0</iyz>
          <izz>1</izz>
        </inertia>
      </inertial>
      <collision name='link_b_collision'>
        <pose frame=''>0 0 0 -1.57 0 0</pose>
        <geometry>
          <mesh>
            <scale>1 1 1</scale>
            <uri>model://motoman_aprs/meshes/sia20d/collision/MOTOMAN_AXIS_B.stl</uri>
          </mesh>
        </geometry>
      </collision>
      <visual name='link_b_visual'>
        <pose frame=''>0 0 0 -1.57 0 0</pose>
        <geometry>
          <mesh>
            <scale>1 1 1</scale>
            <uri>model://motoman_aprs/meshes/sia20d/visual/MOTOMAN_AXIS_B.stl</uri>
          </mesh>
        </geometry>
      </visual>
    </link>
    <joint name='joint_b' type='revolute'>
      <child>link_b</child>
      <parent>link_r</parent>
      <axis>
        <xyz>0 -1 0</xyz>
        <limit>
          <lower>-1.91</lower>
          <upper>1.91</upper>
          <effort>100</effort>
          <velocity>3.48</velocity>
        </limit>
        <dynamics>
          <spring_reference>0</spring_reference>
          <spring_stiffness>0</spring_stiffness>
        </dynamics>
        <use_parent_model_frame>1</use_parent_model_frame>
      </axis>
    </joint>
    <link name='motoman_link_t'>
      <pose frame=''>0 0 1.489 0 -0 0</pose>
      <inertial>
        <pose frame=''>4e-06 0.069404 -2e-06 0 -0 0</pose>
        <mass>5</mass>
        <inertia>
          <ixx>1</ixx>
          <ixy>0</ixy>
          <ixz>0</ixz>
          <iyy>1</iyy>
          <iyz>0</iyz>
          <izz>1</izz>
        </inertia>
      </inertial>
      <collision name='motoman_link_t_collision'>
        <pose frame=''>0 0 0 0 -0 0</pose>
        <geometry>
          <mesh>
            <scale>1 1 1</scale>
            <uri>model://motoman_aprs/meshes/motoman_link_t.STL</uri>
          </mesh>
        </geometry>
      </collision>
      <visual name='motoman_link_t_visual'>
        <pose frame=''>0 0 0 0 -0 0</pose>
        <geometry>
          <mesh>
            <scale>1 1 1</scale>
            <uri>model://motoman_aprs/meshes/motoman_link_t.STL</uri>
          </mesh>
        </geometry>
      </visual>
    </link>
    <joint name='motoman_joint_t' type='revolute'>
      <child>motoman_link_t</child>
      <parent>link_b</parent>
      <axis>
        <xyz>0 0 -1</xyz>
        <limit>
          <lower>-3.1416</lower>
          <upper>3.1416</upper>
          <effort>100</effort>
          <velocity>6.97</velocity>
        </limit>
        <dynamics>
          <spring_reference>0</spring_reference>
          <spring_stiffness>0</spring_stiffness>
        </dynamics>
        <use_parent_model_frame>1</use_parent_model_frame>
      </axis>
    </joint>
    <link name='motoman_finger_1'>
      <pose frame=''>0 0 1.6511 1.5708 -0 0</pose>
      <inertial>
        <pose frame=''>0.022998 0.021681 -9e-06 0 -0 0</pose>
        <mass>5</mass>
        <inertia>
          <ixx>1</ixx>
          <ixy>3.7227e-06</ixy>
          <ixz>1.1564e-09</ixz>
          <iyy>1</iyy>
          <iyz>-5.5289e-09</iyz>
          <izz>1</izz>
        </inertia>
      </inertial>
      <collision name='motoman_finger_1_collision'>
        <pose frame=''>0 0 0 0 -0 0</pose>
        <geometry>
          <mesh>
            <scale>1 1 1</scale>
            <uri>model://motoman_aprs/meshes/motoman_finger_1.STL</uri>
          </mesh>
        </geometry>
      </collision>
      <visual name='motoman_finger_1_visual'>
        <pose frame=''>0 0 0 0 -0 0</pose>
        <geometry>
          <mesh>
            <scale>1 1 1</scale>
            <uri>model://motoman_aprs/meshes/motoman_finger_1.STL</uri>
          </mesh>
        </geometry>
      </visual>
    </link>
    <joint name='motoman_prism_1' type='prismatic'>
      <child>motoman_finger_1</child>
      <parent>motoman_link_t</parent>
      <axis>
        <xyz>1 0 0</xyz>
        <limit>
          <lower>-0.05</lower>
          <upper>0.05</upper>
          <effort>100</effort>
          <velocity>100</velocity>
        </limit>
        <dynamics>
          <spring_reference>0</spring_reference>
          <spring_stiffness>0</spring_stiffness>
        </dynamics>
        <use_parent_model_frame>1</use_parent_model_frame>
      </axis>
    </joint>
    <link name='motoman_finger_2'>
      <pose frame=''>0 0 1.6511 1.5708 -0 -3.14159</pose>
      <inertial>
        <pose frame=''>0.022998 0.021681 -1e-05 0 -0 0</pose>
        <mass>5</mass>
        <inertia>
          <ixx>1</ixx>
          <ixy>3.7227e-06</ixy>
          <ixz>1.199e-09</ixz>
          <iyy>1</iyy>
          <iyz>-5.7323e-09</iyz>
          <izz>1</izz>
        </inertia>
      </inertial>
      <collision name='motoman_finger_2_collision'>
        <pose frame=''>0 0 0 0 -0 0</pose>
        <geometry>
          <mesh>
            <scale>1 1 1</scale>
            <uri>model://motoman_aprs/meshes/motoman_finger_2.STL</uri>
          </mesh>
        </geometry>
      </collision>
      <visual name='motoman_finger_2_visual'>
        <pose frame=''>0 0 0 0 -0 0</pose>
        <geometry>
          <mesh>
            <scale>1 1 1</scale>
            <uri>model://motoman_aprs/meshes/motoman_finger_2.STL</uri>
          </mesh>
        </geometry>
      </visual>
    </link>
    <joint name='motoman_prism_2' type='prismatic'>
      <child>motoman_finger_2</child>
      <parent>motoman_link_t</parent>
      <axis>
        <xyz>1 7e-06 -0</xyz>
        <limit>
          <lower>-0.05</lower>
          <upper>0.05</upper>
          <effort>100</effort>
          <velocity>100</velocity>
        </limit>
        <dynamics>
          <spring_reference>0</spring_reference>
          <spring_stiffness>0</spring_stiffness>
        </dynamics>
        <use_parent_model_frame>1</use_parent_model_frame>
      </axis>
    </joint>
  </model>
</sdf>
