<?xml version="1.0"?>
<sdf version="1.6">
    <model name="motoman_sia20d">
        <link name="motoman_base_link">
            <pose frame="">0 0 0 0 -0 0</pose>
            <inertial>
                <pose frame="">0 0 0 0 -0 0</pose>
                <mass>500</mass>
                <inertia>
                    <ixx>100</ixx>
                    <ixy>0</ixy>
                    <ixz>0</ixz>
                    <iyy>100</iyy>
                    <iyz>0</iyz>
                    <izz>100</izz>
                </inertia>
            </inertial>
            <collision name="motoman_base_link_collision">
                <pose frame="">0 0 0 0 -0 0</pose>
                <geometry>
                    <mesh>
                        <scale>1 1 1</scale>
                        <uri>model://motoman_aprs/meshes/sia20d/collision/MOTOMAN_BASE.stl</uri>
                    </mesh>
                </geometry>
                <surface>
                    <contact>
                        <ode />
                    </contact>
                    <friction>
                        <ode />
                    </friction>
                </surface>
            </collision>
            <visual name="motoman_base_link_visual">
                <pose frame="">0 0 0 0 -0 0</pose>
                <geometry>
                    <mesh>
                        <scale>1 1 1</scale>
                        <uri>model://motoman_aprs/meshes/sia20d/visual/MOTOMAN_BASE.stl</uri>
                    </mesh>
                </geometry>
                <material>
                    <script>
                        <name>Gazebo/White</name>
                        <uri>file://media/materials/scripts/gazebo.material</uri>
                    </script>
                </material>
            </visual>
            <gravity>1</gravity>
            <velocity_decay />
        </link>
        <link name="motoman_link_s">
            <pose frame="">0 0 0.41 0 -0 0</pose>
            <inertial>
                <pose frame="">0 0 0 0 -0 0</pose>
                <mass>5</mass>
                <inertia>
                    <ixx>1</ixx>
                    <ixy>0</ixy>
                    <ixz>0</ixz>
                    <iyy>1</iyy>
                    <iyz>0</iyz>
                    <izz>1</izz>
                </inertia>
            </inertial>
            <collision name="motoman_link_s_collision">
                <pose frame="">0 0 0 0 -0 -3.14159</pose>
                <geometry>
                    <mesh>
                        <scale>1 1 1</scale>
                        <uri>model://motoman_aprs/meshes/sia20d/collision/MOTOMAN_AXIS_S.stl</uri>
                    </mesh>
                </geometry>
                <surface>
                    <contact>
                        <ode />
                    </contact>
                    <friction>
                        <ode />
                    </friction>
                </surface>
            </collision>
            <visual name="motoman_link_s_visual">
                <pose frame="">0 0 0 0 -0 -3.14159</pose>
                <geometry>
                    <mesh>
                        <scale>1 1 1</scale>
                        <uri>model://motoman_aprs/meshes/sia20d/visual/MOTOMAN_AXIS_S.stl</uri>
                    </mesh>
                </geometry>
                <material>
                    <script>
                        <name>Gazebo/Blue</name>
                        <uri>file://media/materials/scripts/gazebo.material</uri>
                    </script>
                </material>
            </visual>
            <gravity>1</gravity>
            <velocity_decay />
        </link>
        <joint name="motoman_joint_s" type="revolute">
            <child>motoman_link_s</child>
            <parent>motoman_base_link</parent>
            <axis>
                <xyz>0 0 1</xyz>
                <limit>
                    <lower>-3.1416</lower>
                    <upper>3.1416</upper>
                    <effort>100</effort>
                    <velocity>2.26</velocity>
                </limit>
                <dynamics>
                    <spring_reference>0</spring_reference>
                    <spring_stiffness>0</spring_stiffness>
                </dynamics>
                <use_parent_model_frame>1</use_parent_model_frame>
            </axis>
        </joint>
        <link name="motoman_link_l">
            <pose frame="">0 0 0.41 0 -0 0</pose>
            <inertial>
                <pose frame="">0 0 0 0 -0 0</pose>
                <mass>5</mass>
                <inertia>
                    <ixx>1</ixx>
                    <ixy>0</ixy>
                    <ixz>0</ixz>
                    <iyy>1</iyy>
                    <iyz>0</iyz>
                    <izz>1</izz>
                </inertia>
            </inertial>
            <collision name="motoman_link_l_collision">
                <pose frame="">0 0 0 -1.57159 -7e-06 7e-06</pose>
                <geometry>
                    <mesh>
                        <scale>1 1 1</scale>
                        <uri>model://motoman_aprs/meshes/sia20d/collision/MOTOMAN_AXIS_L.stl</uri>
                    </mesh>
                </geometry>
                <surface>
                    <contact>
                        <ode />
                    </contact>
                    <friction>
                        <ode />
                    </friction>
                </surface>
            </collision>
            <visual name="motoman_link_l_visual">
                <pose frame="">0 0 0 -1.57159 -7e-06 7e-06</pose>
                <geometry>
                    <mesh>
                        <scale>1 1 1</scale>
                        <uri>model://motoman_aprs/meshes/sia20d/visual/MOTOMAN_AXIS_L.stl</uri>
                    </mesh>
                </geometry>
                <material>
                    <script>
                        <name>Gazebo/White</name>
                        <uri>file://media/materials/scripts/gazebo.material</uri>
                    </script>
                </material>
            </visual>
            <gravity>1</gravity>
            <velocity_decay />
        </link>
        <joint name="motoman_joint_l" type="revolute">
            <child>motoman_link_l</child>
            <parent>motoman_link_s</parent>
            <axis>
                <xyz>0 1 0</xyz>
                <limit>
                    <lower>-1.91</lower>
                    <upper>1.91</upper>
                    <effort>100</effort>
                    <velocity>2.26</velocity>
                </limit>
                <dynamics>
                    <spring_reference>0</spring_reference>
                    <spring_stiffness>0</spring_stiffness>
                </dynamics>
                <use_parent_model_frame>1</use_parent_model_frame>
            </axis>
        </joint>
        <link name="motoman_link_e">
            <pose frame="">0 0 0.9 0 -0 0</pose>
            <inertial>
                <pose frame="">0 0 0 0 -0 0</pose>
                <mass>5</mass>
                <inertia>
                    <ixx>1</ixx>
                    <ixy>0</ixy>
                    <ixz>0</ixz>
                    <iyy>1</iyy>
                    <iyz>0</iyz>
                    <izz>1</izz>
                </inertia>
            </inertial>
            <collision name="motoman_link_e_collision">
                <pose frame="">0 0 0 0 -0 0</pose>
                <geometry>
                    <mesh>
                        <scale>1 1 1</scale>
                        <uri>model://motoman_aprs/meshes/sia20d/collision/MOTOMAN_AXIS_E.stl</uri>
                    </mesh>
                </geometry>
                <surface>
                    <contact>
                        <ode />
                    </contact>
                    <friction>
                        <ode />
                    </friction>
                </surface>
            </collision>
            <visual name="motoman_link_e_visual">
                <pose frame="">0 0 0 0 -0 0</pose>
                <geometry>
                    <mesh>
                        <scale>1 1 1</scale>
                        <uri>model://motoman_aprs/meshes/sia20d/visual/MOTOMAN_AXIS_E.stl</uri>
                    </mesh>
                </geometry>
                <material>
                    <script>
                        <name>Gazebo/Blue</name>
                        <uri>file://media/materials/scripts/gazebo.material</uri>
                    </script>
                </material>
            </visual>
            <gravity>1</gravity>
            <velocity_decay />
        </link>
        <joint name="motoman_joint_e" type="revolute">
            <child>motoman_link_e</child>
            <parent>motoman_link_l</parent>
            <axis>
                <xyz>0 0 1</xyz>
                <limit>
                    <lower>-2.96</lower>
                    <upper>2.96</upper>
                    <effort>100</effort>
                    <velocity>2.96</velocity>
                </limit>
                <dynamics>
                    <spring_reference>0</spring_reference>
                    <spring_stiffness>0</spring_stiffness>
                </dynamics>
                <use_parent_model_frame>1</use_parent_model_frame>
            </axis>
        </joint>
        <link name="motoman_link_u">
            <pose frame="">0 0 0.9 0 -0 0</pose>
            <inertial>
                <pose frame="">0 0 0 0 -0 0</pose>
                <mass>5</mass>
                <inertia>
                    <ixx>1</ixx>
                    <ixy>0</ixy>
                    <ixz>0</ixz>
                    <iyy>1</iyy>
                    <iyz>0</iyz>
                    <izz>1</izz>
                </inertia>
            </inertial>
            <collision name="motoman_link_u_collision">
                <pose frame="">0 0 0 -1.57159 -9.3e-05 7e-06</pose>
                <geometry>
                    <mesh>
                        <scale>1 1 1</scale>
                        <uri>model://motoman_aprs/meshes/sia20d/collision/MOTOMAN_AXIS_U.stl</uri>
                    </mesh>
                </geometry>
                <surface>
                    <contact>
                        <ode />
                    </contact>
                    <friction>
                        <ode />
                    </friction>
                </surface>
            </collision>
            <visual name="motoman_link_u_visual">
                <pose frame="">0 0 0 -1.57159 -9.3e-05 7e-06</pose>
                <geometry>
                    <mesh>
                        <scale>1 1 1</scale>
                        <uri>model://motoman_aprs/meshes/sia20d/visual/MOTOMAN_AXIS_U.stl</uri>
                    </mesh>
                </geometry>
                <material>
                    <script>
                        <name>Gazebo/White</name>
                        <uri>file://media/materials/scripts/gazebo.material</uri>
                    </script>
                </material>
            </visual>
            <gravity>1</gravity>
            <velocity_decay />
        </link>
        <joint name="motoman_joint_u" type="revolute">
            <child>motoman_link_u</child>
            <parent>motoman_link_e</parent>
            <axis>
                <xyz>0 -1 0</xyz>
                <limit>
                    <lower>-2.26</lower>
                    <upper>2.26</upper>
                    <effort>100</effort>
                    <velocity>2.96</velocity>
                </limit>
                <dynamics>
                    <spring_reference>0</spring_reference>
                    <spring_stiffness>0</spring_stiffness>
                </dynamics>
                <use_parent_model_frame>1</use_parent_model_frame>
            </axis>
        </joint>
        <link name="motoman_link_r">
            <pose frame="">0 0 1.32 0 -0 0</pose>
            <inertial>
                <pose frame="">0 0 0 0 -0 0</pose>
                <mass>5</mass>
                <inertia>
                    <ixx>1</ixx>
                    <ixy>0</ixy>
                    <ixz>0</ixz>
                    <iyy>1</iyy>
                    <iyz>0</iyz>
                    <izz>1</izz>
                </inertia>
            </inertial>
            <collision name="motoman_link_r_collision">
                <pose frame="">0 0 0 0 -0 0</pose>
                <geometry>
                    <mesh>
                        <scale>1 1 1</scale>
                        <uri>model://motoman_aprs/meshes/sia20d/collision/MOTOMAN_AXIS_R.stl</uri>
                    </mesh>
                </geometry>
                <surface>
                    <contact>
                        <ode />
                    </contact>
                    <friction>
                        <ode />
                    </friction>
                </surface>
            </collision>
            <visual name="motoman_link_r_visual">
                <pose frame="">0 0 0 0 -0 0</pose>
                <geometry>
                    <mesh>
                        <scale>1 1 1</scale>
                        <uri>model://motoman_aprs/meshes/sia20d/visual/MOTOMAN_AXIS_R.stl</uri>
                    </mesh>
                </geometry>
                <material>
                    <script>
                        <name>Gazebo/Blue</name>
                        <uri>file://media/materials/scripts/gazebo.material</uri>
                    </script>
                </material>
            </visual>
            <gravity>1</gravity>
            <velocity_decay />
        </link>
        <joint name="motoman_joint_r" type="revolute">
            <child>motoman_link_r</child>
            <parent>motoman_link_u</parent>
            <axis>
                <xyz>0 0 -1</xyz>
                <limit>
                    <lower>-3.1416</lower>
                    <upper>3.1416</upper>
                    <effort>100</effort>
                    <velocity>3.48</velocity>
                </limit>
                <dynamics>
                    <spring_reference>0</spring_reference>
                    <spring_stiffness>0</spring_stiffness>
                </dynamics>
                <use_parent_model_frame>1</use_parent_model_frame>
            </axis>
        </joint>
        <link name="motoman_link_b">
            <pose frame="">0 0 1.32 0 -0 0</pose>
            <inertial>
                <pose frame="">0 0 0 0 -0 0</pose>
                <mass>5</mass>
                <inertia>
                    <ixx>1</ixx>
                    <ixy>0</ixy>
                    <ixz>0</ixz>
                    <iyy>1</iyy>
                    <iyz>0</iyz>
                    <izz>1</izz>
                </inertia>
            </inertial>
            <collision name="motoman_link_b_collision">
                <pose frame="">0 0 0 -1.57 0 0</pose>
                <geometry>
                    <mesh>
                        <scale>1 1 1</scale>
                        <uri>model://motoman_aprs/meshes/sia20d/collision/MOTOMAN_AXIS_B.stl</uri>
                    </mesh>
                </geometry>
                <surface>
                    <contact>
                        <ode />
                    </contact>
                    <friction>
                        <ode />
                    </friction>
                </surface>
            </collision>
            <visual name="motoman_link_b_visual">
                <pose frame="">0 0 0 -1.57 0 0</pose>
                <geometry>
                    <mesh>
                        <scale>1 1 1</scale>
                        <uri>model://motoman_aprs/meshes/sia20d/visual/MOTOMAN_AXIS_B.stl</uri>
                    </mesh>
                </geometry>
                <material>
                    <script>
                        <name>Gazebo/White</name>
                        <uri>file://media/materials/scripts/gazebo.material</uri>
                    </script>
                </material>
            </visual>
            <gravity>1</gravity>
            <velocity_decay />
        </link>
        <joint name="motoman_joint_b" type="revolute">
            <child>motoman_link_b</child>
            <parent>motoman_link_r</parent>
            <axis>
                <xyz>0 -1 0</xyz>
                <limit>
                    <lower>-1.91</lower>
                    <upper>1.91</upper>
                    <effort>100</effort>
                    <velocity>3.48</velocity>
                </limit>
                <dynamics>
                    <spring_reference>0</spring_reference>
                    <spring_stiffness>0</spring_stiffness>
                </dynamics>
                <use_parent_model_frame>1</use_parent_model_frame>
            </axis>
        </joint>
        <link name="motoman_link_t">
            <pose frame="">0 0 1.489 0 -0 0</pose>
            <inertial>
                <pose frame="">4e-06 0.069404 -2e-06 0 -0 0</pose>
                <mass>5</mass>
                <inertia>
                    <ixx>1</ixx>
                    <ixy>0</ixy>
                    <ixz>0</ixz>
                    <iyy>1</iyy>
                    <iyz>0</iyz>
                    <izz>1</izz>
                </inertia>
            </inertial>
            <collision name="motoman_link_t_collision">
                <pose frame="">0 0 0 0 -0 0</pose>
                <geometry>
                    <mesh>
                        <scale>1 1 1</scale>
                        <uri>model://motoman_aprs/meshes/motoman_link_t.STL</uri>
                    </mesh>
                </geometry>
                <surface>
                    <contact>
                        <ode />
                    </contact>
                    <friction>
                        <ode />
                    </friction>
                </surface>
            </collision>
            <visual name="motoman_link_t_visual">
                <pose frame="">0 0 0 0 -0 0</pose>
                <geometry>
                    <mesh>
                        <scale>1 1 1</scale>
                        <uri>model://motoman_aprs/meshes/motoman_link_t.STL</uri>
                    </mesh>
                </geometry>
                <material>
                    <script>
                        <name>Gazebo/Blue</name>
                        <uri>file://media/materials/scripts/gazebo.material</uri>
                    </script>
                </material>
            </visual>
            <gravity>1</gravity>
            <velocity_decay />
        </link>
        <joint name="motoman_joint_t" type="revolute">
            <child>motoman_link_t</child>
            <parent>motoman_link_b</parent>
            <axis>
                <xyz>0 0 -1</xyz>
                <limit>
                    <lower>-3.1416</lower>
                    <upper>3.1416</upper>
                    <effort>100</effort>
                    <velocity>6.97</velocity>
                </limit>
                <dynamics>
                    <spring_reference>0</spring_reference>
                    <spring_stiffness>0</spring_stiffness>
                </dynamics>
                <use_parent_model_frame>1</use_parent_model_frame>
            </axis>
        </joint>
        <link name="motoman_right_finger">
            <pose frame="">0 0 1.6511 1.5708 -0 0</pose>

            <collision name="motoman_right_finger_collision">
            <max_contacts>10</max_contacts>
                <pose frame="">0 0 0 0 -0 0</pose>
                <geometry>
                    <mesh>
                        <scale>1 1 1</scale>
                        <uri>model://motoman_aprs/meshes/motoman_finger_1.STL</uri>
                    </mesh>
                </geometry>
            </collision>
            <sensor name="right_finger_contact" type="contact">
                <always_on>true</always_on>
                <update_rate>10</update_rate>
                <visualize>true</visualize>
                <contact>
                    <collision>motoman_right_finger_collision</collision>
                </contact>
            </sensor>
            <visual name="motoman_right_finger_visual">
                <pose frame="">0 0 0 0 -0 0</pose>
                <geometry>
                    <mesh>
                        <scale>1 1 1</scale>
                        <uri>model://motoman_aprs/meshes/motoman_finger_1.STL</uri>
                    </mesh>
                </geometry>
            </visual>
        </link>
        <joint name="motoman_right_finger_joint" type="prismatic">
            <child>motoman_right_finger</child>
            <parent>motoman_link_t</parent>
            <axis>
                <xyz>1 0 0</xyz>
                <limit>
                    <lower>-0.05</lower>
                    <upper>0.05</upper>
                    <effort>100</effort>
                    <velocity>100</velocity>
                </limit>
                <dynamics>
                    <spring_reference>0</spring_reference>
                    <spring_stiffness>0</spring_stiffness>
                </dynamics>
                <use_parent_model_frame>1</use_parent_model_frame>
            </axis>
            <physics>
                <provide_feedback>1</provide_feedback>
                <ode>
                    <provide_feedback>1</provide_feedback>
                    <implicit_spring_damper>1</implicit_spring_damper>
                    <limit>
                        <cfm>0.000</cfm>
                        <erp>0.2</erp>
                    </limit>
                </ode>
            </physics>
        </joint>
        <link name="motoman_left_finger">
            <pose frame="">0 0 1.6511 1.5708 -0 -3.14159</pose>

            <collision name="motoman_left_finger_collision">
                <pose frame="">0 0 0 0 -0 0</pose>
                <max_contacts>10</max_contacts>
                <geometry>
                    <mesh>
                        <scale>1 1 1</scale>
                        <uri>model://motoman_aprs/meshes/motoman_finger_2.STL</uri>
                    </mesh>
                </geometry>
            </collision>
            <sensor name="left_finger_contact" type="contact">
                <always_on>true</always_on>
                <update_rate>10</update_rate>
                <visualize>true</visualize>
                <contact>
                    <collision>motoman_left_finger_collision</collision>
                </contact>
            </sensor>
            <visual name="motoman_left_finger_visual">
                <pose frame="">0 0 0 0 -0 0</pose>
                <geometry>
                    <mesh>
                        <scale>1 1 1</scale>
                        <uri>model://motoman_aprs/meshes/motoman_finger_2.STL</uri>
                    </mesh>
                </geometry>
            </visual>
        </link>
        <joint name="motoman_left_finger_joint" type="prismatic">
            <child>motoman_left_finger</child>
            <parent>motoman_link_t</parent>
            <axis>
                <xyz>1 7e-06 -0</xyz>
                <limit>
                    <lower>-0.05</lower>
                    <upper>0.05</upper>
                    <effort>100</effort>
                    <velocity>100</velocity>
                </limit>
                <dynamics>
                    <spring_reference>0</spring_reference>
                    <spring_stiffness>0</spring_stiffness>
                </dynamics>
                <use_parent_model_frame>1</use_parent_model_frame>
            </axis>
            <physics>
                <provide_feedback>1</provide_feedback>
                <ode>
                    <provide_feedback>1</provide_feedback>
                    <implicit_spring_damper>1</implicit_spring_damper>
                    <limit>
                        <cfm>0.000</cfm>
                        <erp>0.2</erp>
                    </limit>
                </ode>
            </physics>
        </joint>
    </model>
</sdf>
