<?xml version="1.0" ?>
<!-- =================================================================================== -->
<!-- |    This document was autogenerated by xacro from motoman.xacro                  | -->
<!-- |    EDITING THIS FILE BY HAND IS NOT RECOMMENDED                                 | -->
<!-- =================================================================================== -->
<robot name="motoman_sia20d" xmlns:xacro="http://ros.org/wiki/xacro">
  <link name="motoman_base_link">
    <visual>
      <geometry>
        <mesh filename="package://motoman_aprs/meshes/sia20d/visual/MOTOMAN_BASE.stl"/>
      </geometry>
      <material name="blue">
        <color rgba="0 0 1 1"/>
      </material>
    </visual>
    <collision>
      <geometry>
        <mesh filename="package://motoman_aprs/meshes/sia20d/collision/MOTOMAN_BASE.stl"/>
      </geometry>
      <material name="yellow">
        <color rgba="0 1 1 1"/>
      </material>
    </collision>
    <inertial>
      <mass value="500"/>
      <inertia ixx="100" ixy="0.0" ixz="0.0" iyy="100" iyz="0.0" izz="100"/>
    </inertial>
  </link>
  <link name="motoman_link_s">
    <visual>
      <origin rpy="0 0 3.1416" xyz="0 0 0"/>
      <geometry>
        <mesh filename="package://motoman_aprs/meshes/sia20d/visual/MOTOMAN_AXIS_S.stl"/>
      </geometry>
      <material name="silver">
        <color rgba="0.8 0.8 0.8 1"/>
      </material>
    </visual>
    <collision>
      <origin rpy="0 0 3.1416" xyz="0 0 0"/>
      <geometry>
        <mesh filename="package://motoman_aprs/meshes/sia20d/collision/MOTOMAN_AXIS_S.stl"/>
      </geometry>
      <material name="yellow"/>
    </collision>
    <inertial>
      <mass value="5"/>
      <inertia ixx="1" ixy="0.0" ixz="0.0" iyy="1" iyz="0.0" izz="1"/>
    </inertial>
  </link>
  <link name="motoman_link_l">
    <visual>
      <origin rpy="1.57 3.1416 3.1416" xyz="0 0 0"/>
      <geometry>
        <mesh filename="package://motoman_aprs/meshes/sia20d/visual/MOTOMAN_AXIS_L.stl"/>
      </geometry>
      <material name="blue"/>
    </visual>
    <collision>
      <origin rpy="1.57 3.1416 3.1416" xyz="0 0 0"/>
      <geometry>
        <mesh filename="package://motoman_aprs/meshes/sia20d/collision/MOTOMAN_AXIS_L.stl"/>
      </geometry>
      <material name="yellow"/>
    </collision>
    <inertial>
      <mass value="5"/>
      <inertia ixx="1" ixy="0.0" ixz="0.0" iyy="1" iyz="0.0" izz="1"/>
    </inertial>
  </link>
  <link name="motoman_link_e">
    <visual>
      <origin rpy="0 0 0" xyz="0 0 0"/>
      <geometry>
        <mesh filename="package://motoman_aprs/meshes/sia20d/visual/MOTOMAN_AXIS_E.stl"/>
      </geometry>
      <material name="silver"/>
    </visual>
    <collision>
      <origin rpy="0 0 0" xyz="0 0 0"/>
      <geometry>
        <mesh filename="package://motoman_aprs/meshes/sia20d/collision/MOTOMAN_AXIS_E.stl"/>
      </geometry>
      <material name="yellow"/>
    </collision>
    <inertial>
      <mass value="5"/>
      <inertia ixx="1" ixy="0.0" ixz="0.0" iyy="1" iyz="0.0" izz="1"/>
    </inertial>
  </link>
  <link name="motoman_link_u">
    <visual>
      <origin rpy="1.57 -3.1415 3.1416" xyz="0 0 0"/>
      <geometry>
        <mesh filename="package://motoman_aprs/meshes/sia20d/visual/MOTOMAN_AXIS_U.stl"/>
      </geometry>
      <material name="blue"/>
    </visual>
    <collision>
      <origin rpy="1.57 -3.1415 3.1416" xyz="0 0 0"/>
      <geometry>
        <mesh filename="package://motoman_aprs/meshes/sia20d/collision/MOTOMAN_AXIS_U.stl"/>
      </geometry>
      <material name="yellow"/>
    </collision>
    <inertial>
      <mass value="5"/>
      <inertia ixx="1" ixy="0.0" ixz="0.0" iyy="1" iyz="0.0" izz="1"/>
    </inertial>
  </link>
  <link name="motoman_link_r">
    <visual>
      <origin rpy="0 0 0" xyz="0 0 0"/>
      <geometry>
        <mesh filename="package://motoman_aprs/meshes/sia20d/visual/MOTOMAN_AXIS_R.stl"/>
      </geometry>
      <material name="silver"/>
    </visual>
    <collision>
      <origin rpy="0 0 0" xyz="0 0 0"/>
      <geometry>
        <mesh filename="package://motoman_aprs/meshes/sia20d/collision/MOTOMAN_AXIS_R.stl"/>
      </geometry>
      <material name="yellow"/>
    </collision>
    <inertial>
      <mass value="5"/>
      <inertia ixx="1" ixy="0.0" ixz="0.0" iyy="1" iyz="0.0" izz="1"/>
    </inertial>
  </link>
  <link name="motoman_link_b">
    <visual>
      <origin rpy="-1.57 0 0" xyz="0 0 0"/>
      <geometry>
        <mesh filename="package://motoman_aprs/meshes/sia20d/visual/MOTOMAN_AXIS_B.stl"/>
      </geometry>
      <material name="blue"/>
    </visual>
    <collision>
      <origin rpy="-1.57 0 0" xyz="0 0 0"/>
      <geometry>
        <mesh filename="package://motoman_aprs/meshes/sia20d/collision/MOTOMAN_AXIS_B.stl"/>
      </geometry>
      <material name="yellow"/>
    </collision>
    <inertial>
      <mass value="5"/>
      <inertia ixx="1" ixy="0.0" ixz="0.0" iyy="1" iyz="0.0" izz="1"/>
    </inertial>
  </link>
  <link name="motoman_link_t">
    <inertial>
      <origin rpy="0 0 0" xyz="3.6305E-06 0.069404 -1.8652E-06"/>
      <mass value="5"/>
      <inertia ixx="1" ixy="0" ixz="0" iyy="1" iyz="0" izz="1"/>
    </inertial>
    <visual>
      <origin rpy="0 0 0" xyz="0 0 0"/>
      <geometry>
        <mesh filename="package://motoman_aprs/meshes/motoman_link_t.STL"/>
      </geometry>
      <material name="">
        <color rgba="0.79216 0.81961 0.93333 1"/>
      </material>
    </visual>
    <collision>
      <origin rpy="0 0 0" xyz="0 0 0"/>
      <geometry>
        <mesh filename="package://motoman_aprs/meshes/motoman_link_t.STL"/>
      </geometry>
    </collision>
  </link>
  <!-- JOINTS -->
  <joint name="motoman_joint_s" type="revolute">
    <parent link="motoman_base_link"/>
    <child link="motoman_link_s"/>
    <origin rpy="0 0 0" xyz="0 0 0.41" xyztol=".1 .1 .1"/>
    <axis xyz="0 0 1"/>
    <limit effort="100" lower="-3.1416" upper="3.1416" velocity="2.26"/>
  </joint>
  <joint name="motoman_joint_l" type="revolute">
    <parent link="motoman_link_s"/>
    <child link="motoman_link_l"/>
    <origin rpy="0 0 0" xyz="0 0 0" xyztol=".1 .1 .1"/>
    <axis xyz="0 1 0"/>
    <limit effort="100" lower="-1.91" upper="1.91" velocity="2.26"/>
  </joint>
  <joint name="motoman_joint_e" type="revolute">
    <parent link="motoman_link_l"/>
    <child link="motoman_link_e"/>
    <origin rpy="0 0 0" xyz="0 0 0.49" xyztol=".1 .1 .1"/>
    <axis xyz="0 0 1"/>
    <limit effort="100" lower="-2.96" upper="2.96" velocity="2.96"/>
  </joint>
  <joint name="motoman_joint_u" type="revolute">
    <parent link="motoman_link_e"/>
    <child link="motoman_link_u"/>
    <origin rpy="0 0 0" xyz="0 0 0" xyztol=".1 .1 .1"/>
    <axis xyz="0 -1 0"/>
    <limit effort="100" lower="-2.26" upper="2.26" velocity="2.96"/>
  </joint>
  <joint name="motoman_joint_r" type="revolute">
    <parent link="motoman_link_u"/>
    <child link="motoman_link_r"/>
    <origin rpy="0 0 0" xyz="0 0 0.420" xyztol=".1 .1 .1"/>
    <axis xyz="0 0 -1"/>
    <limit effort="100" lower="-3.1416" upper="3.1416" velocity="3.48"/>
  </joint>
  <joint name="motoman_joint_b" type="revolute">
    <parent link="motoman_link_r"/>
    <child link="motoman_link_b"/>
    <origin rpy="0 0 0" xyz="0 0 0"/>
    <axis xyz="0 -1 0"/>
    <limit effort="100" lower="-1.91" upper="1.91" velocity="3.48"/>
  </joint>
  <joint name="motoman_joint_t" type="revolute">
    <parent link="motoman_link_b"/>
    <child link="motoman_link_t"/>
    <origin rpy="0 0 0" xyz="0 0 0.169" xyztol=".1 .1 .1"/>
    <axis xyz="0 0 -1"/>
    <limit effort="100" lower="-3.1416" upper="3.1416" velocity="6.97"/>
  </joint>
  <!-- GAZEBO EXTENSIONS -->
  <gazebo reference="motoman_base_link">
    <material>Gazebo/White</material>
  </gazebo>
  <gazebo reference="motoman_link_s">
    <material>Gazebo/Blue</material>
  </gazebo>
  <gazebo reference="motoman_link_l">
    <material>Gazebo/White</material>
  </gazebo>
  <gazebo reference="motoman_link_e">
    <material>Gazebo/Blue</material>
  </gazebo>
  <gazebo reference="motoman_link_u">
    <material>Gazebo/White</material>
  </gazebo>
  <gazebo reference="motoman_link_r">
    <material>Gazebo/Blue</material>
  </gazebo>
  <gazebo reference="motoman_link_b">
    <material>Gazebo/White</material>
  </gazebo>
  <gazebo reference="motoman_link_t">
    <material>Gazebo/Blue</material>
  </gazebo>
  <!-- GRIPPER -->
  <!--         <link name="${prefix}finger_1">
            <inertial>
                <origin xyz="0.022998 0.021681 -9.1584E-06" rpy="0 0 0" />
                <mass value="5" />
                <inertia ixx="1" ixy="3.7227E-06" ixz="1.1564E-09" iyy="1" iyz="-5.5289E-09" izz="1" />
            </inertial>
            <visual>
                <origin xyz="0 0 0" rpy="0 0 0" />
                <geometry>
                    <mesh filename="package://motoman_aprs/meshes/motoman_finger_1.STL" />
                </geometry>
                <material name="">
                    <color rgba="0.79216 0.81961 0.93333 1" />
                </material>
            </visual>
            <collision>
                <origin xyz="0 0 0" rpy="0 0 0" />
                <geometry>
                    <mesh filename="package://motoman_aprs/meshes/motoman_finger_1.STL" />
                </geometry>
            </collision>
        </link>
        <joint name="${prefix}prism_1" type="prismatic">
            <origin xyz="0 0 0.1621" rpy="1.5708 0 0" />
            <parent link="${prefix}link_t" />
            <child link="${prefix}finger_1" />
            <axis xyz="1 0 0" />
            <limit lower="-0.05" upper="0.05" effort="100" velocity="100" />
        </joint>
        <link name="${prefix}finger_2">
            <inertial>
                <origin xyz="0.022998 0.021681 -9.8018E-06" rpy="0 0 0" />
                <mass value="5" />
                <inertia ixx="1" ixy="3.7227E-06" ixz="1.199E-09" iyy="1" iyz="-5.7323E-09" izz="1" />
            </inertial>
            <visual>
                <origin xyz="0 0 0" rpy="0 0 0" />
                <geometry>
                    <mesh filename="package://motoman_aprs/meshes/motoman_finger_2.STL" />
                </geometry>
                <material name="">
                    <color rgba="0.79216 0.81961 0.93333 1" />
                </material>
            </visual>
            <collision>
                <origin xyz="0 0 0" rpy="0 0 0" />
                <geometry>
                    <mesh filename="package://motoman_aprs/meshes/motoman_finger_2.STL" />
                </geometry>
            </collision>
        </link>
        <joint name="${prefix}prism_2" type="prismatic">
            <origin xyz="0 0 0.1621" rpy="1.5708 0 3.1416" />
            <parent link="${prefix}link_t" />
            <child link="${prefix}finger_2" />
            <axis xyz="-1 0 0" />
            <limit lower="-0.05" upper="0.05" effort="100" velocity="100" />
        </joint>
        -->
  <link name="motoman_finger_1">
    <inertial>
      <origin rpy="0 0 0" xyz="0.022998 0.021681 -9.1584E-06"/>
      <mass value="5"/>
      <inertia ixx="1" ixy="3.7227E-06" ixz="1.1564E-09" iyy="1" iyz="-5.5289E-09" izz="1"/>
    </inertial>
    <visual>
      <origin rpy="0 0 0" xyz="0 0 0"/>
      <geometry>
        <mesh filename="package://motoman_aprs/meshes/motoman_finger_1.STL"/>
      </geometry>
      <material name="">
        <color rgba="0.79216 0.81961 0.93333 1"/>
      </material>
    </visual>
    <collision>
      <origin rpy="0 0 0" xyz="0 0 0"/>
      <geometry>
        <mesh filename="package://motoman_aprs/meshes/motoman_finger_1.STL"/>
      </geometry>
    </collision>
  </link>
  <joint name="motoman_prism_1" type="prismatic">
    <origin rpy="1.5708 0 0" xyz="0 0 0.1621"/>
    <parent link="motoman_link_t"/>
    <child link="motoman_finger_1"/>
    <axis xyz="1 0 0"/>
    <limit effort="100" lower="-0.05" upper="0.05" velocity="100"/>
  </joint>
  <link name="motoman_finger_2">
    <inertial>
      <origin rpy="0 0 0" xyz="0.022998 0.021681 -9.8018E-06"/>
      <mass value="5"/>
      <inertia ixx="1" ixy="3.7227E-06" ixz="1.199E-09" iyy="1" iyz="-5.7323E-09" izz="1"/>
    </inertial>
    <visual>
      <origin rpy="0 0 0" xyz="0 0 0"/>
      <geometry>
        <mesh filename="package://motoman_aprs/meshes/motoman_finger_2.STL"/>
      </geometry>
      <material name="">
        <color rgba="0.79216 0.81961 0.93333 1"/>
      </material>
    </visual>
    <collision>
      <origin rpy="0 0 0" xyz="0 0 0"/>
      <geometry>
        <mesh filename="package://motoman_aprs/meshes/motoman_finger_2.STL"/>
      </geometry>
    </collision>
  </link>
  <joint name="motoman_prism_2" type="prismatic">
    <origin rpy="1.5708 0 3.1416" xyz="0 0 0.1621"/>
    <parent link="motoman_link_t"/>
    <child link="motoman_finger_2"/>
    <axis xyz="-1 0 0"/>
    <limit effort="100" lower="-0.05" upper="0.05" velocity="100"/>
  </joint>
</robot>

