<?xml version="1.0" encoding="UTF-8"?>

<!--
  peter_moto_gripper(prefix)

  Creates the Schunk gripper modified by Peter Mnev with the passed in prefix. If there
  is only one hand in the urdf then an empty prefix can be used "". If
  there are multiple hands then a prefix followed by an "_" is needed.
-->

<robot xmlns:xacro="http://ros.org/wiki/xacro">
    <xacro:macro name="peter_moto_gripper" params="prefix">
        <link name="${prefix}finger_1">
            <inertial>
                <origin xyz="0.022998 0.021681 -9.1584E-06" rpy="0 0 0" />
                <mass value="5" />
                <inertia ixx="1" ixy="3.7227E-06" ixz="1.1564E-09" iyy="1" iyz="-5.5289E-09" izz="1" />
            </inertial>
            <visual>
                <origin xyz="0 0 0" rpy="0 0 0" />
                <geometry>
                    <mesh filename="package://motoman_aprs/meshes/motoman_finger_1.STL" />
                </geometry>
                <material name="">
                    <color rgba="0.79216 0.81961 0.93333 1" />
                </material>
            </visual>
            <collision>
                <origin xyz="0 0 0" rpy="0 0 0" />
                <geometry>
                    <mesh filename="package://motoman_aprs/meshes/motoman_finger_1.STL" />
                </geometry>
            </collision>
        </link>
        <joint name="${prefix}prism_1" type="prismatic">
            <origin xyz="0 0 0.1621" rpy="1.5708 0 0" />
            <parent link="${prefix}link_t" />
            <child link="${prefix}finger_1" />
            <axis xyz="1 0 0" />
            <limit lower="-0.05" upper="0.05" effort="100" velocity="100" />
        </joint>
        <link name="${prefix}finger_2">
            <inertial>
                <origin xyz="0.022998 0.021681 -9.8018E-06" rpy="0 0 0" />
                <mass value="5" />
                <inertia ixx="1" ixy="3.7227E-06" ixz="1.199E-09" iyy="1" iyz="-5.7323E-09" izz="1" />
            </inertial>
            <visual>
                <origin xyz="0 0 0" rpy="0 0 0" />
                <geometry>
                    <mesh filename="package://motoman_aprs/meshes/motoman_finger_2.STL" />
                </geometry>
                <material name="">
                    <color rgba="0.79216 0.81961 0.93333 1" />
                </material>
            </visual>
            <collision>
                <origin xyz="0 0 0" rpy="0 0 0" />
                <geometry>
                    <mesh filename="package://motoman_aprs/meshes/motoman_finger_2.STL" />
                </geometry>
            </collision>
        </link>
        <joint name="${prefix}prism_2" type="prismatic">
            <origin xyz="0 0 0.1621" rpy="1.5708 0 3.1416" />
            <parent link="${prefix}link_t" />
            <child link="${prefix}finger_2" />
            <axis xyz="-1 0 0" />
            <limit lower="-0.05" upper="0.05" effort="100" velocity="100" />
        </joint>
    </xacro:macro>
</robot>
