<?xml version="1.0" encoding="UTF-8"?>
<!-- =================================================================================== -->
<!-- |    This document was autogenerated by xacro from sia20d.xacro                   | -->
<!-- |    EDITING THIS FILE BY HAND IS NOT RECOMMENDED                                 | -->
<!-- =================================================================================== -->
<robot xmlns:xacro="http://ros.org/wiki/xacro" name="motoman_sia20d">
   <link name="base_link">
      <visual>
         <geometry>
            <mesh filename="package://motoman_sia20d_support/meshes/sia20d/visual/MOTOMAN_BASE.stl" />
         </geometry>
         <material name="blue">
            <color rgba="0 0 1 1" />
         </material>
      </visual>
      <collision>
         <geometry>
            <mesh filename="package://motoman_sia20d_support/meshes/sia20d/collision/MOTOMAN_BASE.stl" />
         </geometry>
         <material name="yellow">
            <color rgba="0 1 1 1" />
         </material>
      </collision>
      <inertial>
         <mass value="5" />
         <inertia ixx="1" ixy="0.0" ixz="0.0" iyy="1" iyz="0.0" izz="1" />
      </inertial>
   </link>
   <link name="link_s">
      <visual>
         <origin rpy="0 0 3.1416" xyz="0 0 0" />
         <geometry>
            <mesh filename="package://motoman_sia20d_support/meshes/sia20d/visual/MOTOMAN_AXIS_S.stl" />
         </geometry>
         <material name="silver">
            <color rgba="0.8 0.8 0.8 1" />
         </material>
      </visual>
      <collision>
         <origin rpy="0 0 3.1416" xyz="0 0 0" />
         <geometry>
            <mesh filename="package://motoman_sia20d_support/meshes/sia20d/collision/MOTOMAN_AXIS_S.stl" />
         </geometry>
         <material name="yellow" />
      </collision>
 <inertial>
         <mass value="5" />
         <inertia ixx="1" ixy="0.0" ixz="0.0" iyy="1" iyz="0.0" izz="1" />
      </inertial>
   </link>
   <link name="link_l">
      <visual>
         <origin rpy="1.57 3.1416 3.1416" xyz="0 0 0" />
         <geometry>
            <mesh filename="package://motoman_sia20d_support/meshes/sia20d/visual/MOTOMAN_AXIS_L.stl" />
         </geometry>
         <material name="blue" />
      </visual>
      <collision>
         <origin rpy="1.57 3.1416 3.1416" xyz="0 0 0" />
         <geometry>
            <mesh filename="package://motoman_sia20d_support/meshes/sia20d/collision/MOTOMAN_AXIS_L.stl" />
         </geometry>
         <material name="yellow" />
      </collision>
      <inertial>
         <mass value="5" />
         <inertia ixx="1" ixy="0.0" ixz="0.0" iyy="1" iyz="0.0" izz="1" />
      </inertial>
   </link>
   <link name="link_e">
      <visual>
         <origin rpy="0 0 0" xyz="0 0 0" />
         <geometry>
            <mesh filename="package://motoman_sia20d_support/meshes/sia20d/visual/MOTOMAN_AXIS_E.stl" />
         </geometry>
         <material name="silver" />
      </visual>
      <collision>
         <origin rpy="0 0 0" xyz="0 0 0" />
         <geometry>
            <mesh filename="package://motoman_sia20d_support/meshes/sia20d/collision/MOTOMAN_AXIS_E.stl" />
         </geometry>
         <material name="yellow" />
      </collision>
 <inertial>
         <mass value="5" />
         <inertia ixx="1" ixy="0.0" ixz="0.0" iyy="1" iyz="0.0" izz="1" />
      </inertial>
   </link>
   <link name="link_u">
      <visual>
         <origin rpy="1.57 -3.1415 3.1416" xyz="0 0 0" />
         <geometry>
            <mesh filename="package://motoman_sia20d_support/meshes/sia20d/visual/MOTOMAN_AXIS_U.stl" />
         </geometry>
         <material name="blue" />
      </visual>
      <collision>
         <origin rpy="1.57 -3.1415 3.1416" xyz="0 0 0" />
         <geometry>
            <mesh filename="package://motoman_sia20d_support/meshes/sia20d/collision/MOTOMAN_AXIS_U.stl" />
         </geometry>
         <material name="yellow" />
      </collision>
 <inertial>
         <mass value="5" />
         <inertia ixx="1" ixy="0.0" ixz="0.0" iyy="1" iyz="0.0" izz="1" />
      </inertial>
   </link>
   <link name="link_r">
      <visual>
         <origin rpy="0 0 0" xyz="0 0 0" />
         <geometry>
            <mesh filename="package://motoman_sia20d_support/meshes/sia20d/visual/MOTOMAN_AXIS_R.stl" />
         </geometry>
         <material name="silver" />
      </visual>
      <collision>
         <origin rpy="0 0 0" xyz="0 0 0" />
         <geometry>
            <mesh filename="package://motoman_sia20d_support/meshes/sia20d/collision/MOTOMAN_AXIS_R.stl" />
         </geometry>
         <material name="yellow" />
      </collision>
      <inertial>
         <mass value="5" />
         <inertia ixx="1" ixy="0.0" ixz="0.0" iyy="1" iyz="0.0" izz="1" />
      </inertial>
   </link>
   <link name="link_b">
      <visual>
         <origin rpy="-1.57 0 0" xyz="0 0 0" />
         <geometry>
            <mesh filename="package://motoman_sia20d_support/meshes/sia20d/visual/MOTOMAN_AXIS_B.stl" />
         </geometry>
         <material name="blue" />
      </visual>
      <collision>
         <origin rpy="-1.57 0 0" xyz="0 0 0" />
         <geometry>
            <mesh filename="package://motoman_sia20d_support/meshes/sia20d/collision/MOTOMAN_AXIS_B.stl" />
         </geometry>
         <material name="yellow" />
      </collision>
      <inertial>
         <mass value="5" />
         <inertia ixx="1" ixy="0.0" ixz="0.0" iyy="1" iyz="0.0" izz="1" />
      </inertial>
   </link>
   <link name="link_t">
      <visual>
         <geometry>
            <mesh filename="package://motoman_sia20d_support/meshes/sia20d/visual/MOTOMAN_AXIS_T.stl" />
         </geometry>
         <material name="silver" />
      </visual>
      <collision>
         <geometry>
            <mesh filename="package://motoman_sia20d_support/meshes/sia20d/collision/MOTOMAN_AXIS_T.stl" />
         </geometry>
         <material name="yellow" />
      </collision>
      <inertial>
         <mass value="5" />
         <inertia ixx="1" ixy="0.0" ixz="0.0" iyy="1" iyz="0.0" izz="1" />
      </inertial>
   </link>



   <link name="tool0">
     <inertial>
      <origin
        xyz="0.029072 0.059306 -0.024512"
        rpy="0 0 0" />
      <mass
        value="1.1697" />
      <inertia
        ixx="9.7204E-07"
        ixy="-1.2761E-13"
        ixz="4.8457E-10"
        iyy="9.7204E-07"
        iyz="2.5598E-10"
        izz="3.0898E-13" />
    </inertial>
    <visual>
      <origin
        xyz="0 0 0"
        rpy="0 0 0" />
      <geometry>
        <mesh
          filename="package://gripper_assembly/meshes/GripperBase.STL" />
      </geometry>
      <material
        name="">
        <color
          rgba="0.79216 0.81961 0.93333 1" />
      </material>
    </visual>
    <collision>
      <origin
        xyz="0 0 0"
        rpy="0 0 0" />
      <geometry>
        <mesh
          filename="package://gripper_assembly/meshes/GripperBase.STL" />
      </geometry>
    </collision>
   </link>
   
  <link
    name="Finger2">
    <inertial>
      <origin
        xyz="-0.0025535 0.011322 -0.030358"
        rpy="0 0 0" />
      <mass
        value="0.004984" />
      <inertia
        ixx="1.5491E-07"
        ixy="-7.3639E-10"
        ixz="-3.524E-09"
        iyy="1.4851E-07"
        iyz="-3.1016E-08"
        izz="6.565E-09" />
    </inertial>
    <visual>
      <origin
        xyz="0 0 0"
        rpy="0 0 0" />
      <geometry>
        <mesh
          filename="package://gripper_assembly/meshes/Finger2.STL" />
      </geometry>
      <material
        name="">
        <color
          rgba="0.79216 0.81961 0.93333 1" />
      </material>
    </visual>
    <collision>
      <origin
        xyz="0 0 0"
        rpy="0 0 0" />
      <geometry>
        <mesh
          filename="package://gripper_assembly/meshes/Finger2.STL" />
      </geometry>
    </collision>
  </link>


  <link
    name="Finger1">
    <inertial>
      <origin
        xyz="-0.01775 0.077561 -0.0015192"
        rpy="0 0 0" />
      <mass
        value="0.004984" />
      <inertia
        ixx="1.4851E-07"
        ixy="3.1016E-08"
        ixz="-7.3639E-10"
        iyy="6.565E-09"
        iyz="3.524E-09"
        izz="1.5491E-07" />
    </inertial>
    <visual>
      <origin
        xyz="0 0 0"
        rpy="0 0 0" />
      <geometry>
        <mesh
          filename="package://gripper_assembly/meshes/Finger1.STL" />
      </geometry>
      <material
        name="">
        <color
          rgba="1 0 0 1" />
      </material>
    </visual>
    <collision>
      <origin
        xyz="0 0 0"
        rpy="0 0 0" />
      <geometry>
        <mesh
          filename="package://gripper_assembly/meshes/Finger1.STL" />
      </geometry>
    </collision>
  </link>









   <joint name="joint_s" type="revolute">
      <parent link="base_link" />
      <child link="link_s" />
      <origin rpy="0 0 0" xyz="0 0 0.41" />
      <axis xyz="0 0 1" />
      <limit effort="100" lower="-3.1416" upper="3.1416" velocity="2.26" />
   </joint>
   <joint name="joint_l" type="revolute">
      <parent link="link_s" />
      <child link="link_l" />
      <origin rpy="0 0 0" xyz="0 0 0" />
      <axis xyz="0 1 0" />
      <limit effort="100" lower="-1.91" upper="1.91" velocity="2.26" />
   </joint>
   <joint name="joint_e" type="revolute">
      <parent link="link_l" />
      <child link="link_e" />
      <origin rpy="0 0 0" xyz="0 0 0.49" />
      <axis xyz="0 0 1" />
      <limit effort="100" lower="-2.96" upper="2.96" velocity="2.96" />
   </joint>
   <joint name="joint_u" type="revolute">
      <parent link="link_e" />
      <child link="link_u" />
      <origin rpy="0 0 0" xyz="0 0 0" />
      <axis xyz="0 -1 0" />
      <limit effort="100" lower="-2.26" upper="2.26" velocity="2.96" />
   </joint>
   <joint name="joint_r" type="revolute">
      <parent link="link_u" />
      <child link="link_r" />
      <origin rpy="0 0 0" xyz="0 0 0.420" />
      <axis xyz="0 0 -1" />
      <limit effort="100" lower="-3.1416" upper="3.1416" velocity="3.48" />
   </joint>
   <joint name="joint_b" type="revolute">
      <parent link="link_r" />
      <child link="link_b" />
      <origin rpy="0 0 0" xyz="0 0 0" />
      <axis xyz="0 -1 0" />
      <limit effort="100" lower="-1.91" upper="1.91" velocity="3.48" />
   </joint>
   <joint name="joint_t" type="revolute">
      <parent link="link_b" />
      <child link="link_t" />
      <origin rpy="0 0 0" xyz="0 0 0.18" />
      <axis xyz="0 0 -1" />
      <limit effort="100" lower="-3.1416" upper="3.1416" velocity="6.97" />
   </joint>


   <joint name="link_t-tool0" type="fixed">
      <origin rpy="-1.5708 0 0" xyz="-0.028 -0.06 .074" />
      <parent link="link_t" />
      <child link="tool0" />
   </joint>



  <joint
    name="Joint1"
    type="prismatic">
    <origin
      xyz="0 -0.070202 0.059329"
      rpy="0 0 3.1416" />
    <parent
      link="tool0" />
    <child
      link="Finger1" />
    <axis
      xyz="-1 0 0" />
    <limit
      lower = "-.05"
      upper = "0"
      effort="0"
      velocity="0" />
  </joint>



  <joint
    name="Joint2"
    type="prismatic">
    <origin
      xyz="0.029072 -0.1174 0.060364"
      rpy="4.71238898038 4.71238898038 0" />
    <parent
      link="tool0" />
    <child
      link="Finger2" />
    <axis
      xyz="0 1 0" />
    <limit
      lower = "0"
      upper = ".05"
      effort="0"
      velocity="0" />
  </joint>




</robot>
