<?xml version="1.0" encoding="UTF-8"?>
<sdf version="1.6">
    <model name="motoman_sia20d">
        <link name="link0">
            <pose frame="">0 0 0 0 -0 0</pose>
            <inertial>
                <pose frame="">0 0 0 0 -0 0</pose>
                <mass>150</mass>
                <inertia>
                    <ixx>1</ixx>
                    <ixy>0</ixy>
                    <ixz>0</ixz>
                    <iyy>1</iyy>
                    <iyz>0</iyz>
                    <izz>1</izz>
                </inertia>
            </inertial>
            <collision name="link0_fixed_joint_lump__motoman_base_link_collision">
                <pose frame="">0 0 0 0 -0 0</pose>
                <geometry>
                    <mesh>
                        <scale>1 1 1</scale>
                        <uri>model://motoman_sia20d_support/meshes/sia20d/collision/MOTOMAN_BASE.stl</uri>
                    </mesh>
                </geometry>
                <surface>
                    <contact>
                        <ode />
                    </contact>
                    <friction>
                        <ode />
                    </friction>
                </surface>
            </collision>
            <visual name="link0_fixed_joint_lump__motoman_base_link_visual">
                <pose frame="">0 0 0 0 -0 0</pose>
                <geometry>
                    <mesh>
                        <scale>1 1 1</scale>
                        <uri>model://motoman_sia20d_support/meshes/sia20d/visual/MOTOMAN_BASE.stl</uri>
                    </mesh>
                </geometry>
                <material>
                    <script>
                        <name>Gazebo/White</name>
                        <uri>file://media/materials/scripts/gazebo.material</uri>
                    </script>
                </material>
            </visual>
            <gravity>false</gravity>
            <velocity_decay />
            <self_collide>0</self_collide>
        </link>
        <joint name="world_joint" type="revolute">
            <child>link0</child>
            <parent>world</parent>
            <axis>
                <limit>
                    <lower>0</lower>
                    <upper>0</upper>
                </limit>
                <dynamics>
                    <damping>0</damping>
                    <friction>0</friction>
                    <spring_reference>0</spring_reference>
                    <spring_stiffness>0</spring_stiffness>
                </dynamics>
                <use_parent_model_frame>1</use_parent_model_frame>
                <xyz>0 0 1</xyz>
            </axis>
        </joint>
        <link name="motoman_link_s">
            <pose frame="">0 0 0.41 0 -0 0</pose>
            <inertial>
                <pose frame="">0 0 0 0 -0 0</pose>
                <mass>34.5</mass>
                <inertia>
                    <ixx>0.50208</ixx>
                    <ixy>0</ixy>
                    <ixz>0</ixz>
                    <iyy>0.50208</iyy>
                    <iyz>0</iyz>
                    <izz>0.129569</izz>
                </inertia>
            </inertial>
            <collision name="motoman_link_s_collision">
                <pose frame="">0 0 0 0 -0 -3.14159</pose>
                <geometry>
                    <mesh>
                        <scale>1 1 1</scale>
                        <uri>model://motoman_sia20d_support/meshes/sia20d/collision/MOTOMAN_AXIS_S.stl</uri>
                    </mesh>
                </geometry>
                <surface>
                    <contact>
                        <ode />
                    </contact>
                    <friction>
                        <ode />
                    </friction>
                </surface>
            </collision>
            <visual name="motoman_link_s_visual">
                <pose frame="">0 0 0 0 -0 -3.14159</pose>
                <geometry>
                    <mesh>
                        <scale>1 1 1</scale>
                        <uri>model://motoman_sia20d_support/meshes/sia20d/visual/MOTOMAN_AXIS_S.stl</uri>
                    </mesh>
                </geometry>
                <material>
                    <script>
                        <name>Gazebo/Blue</name>
                        <uri>file://media/materials/scripts/gazebo.material</uri>
                    </script>
                </material>
            </visual>
            <gravity>false</gravity>
            <velocity_decay />
            <self_collide>0</self_collide>
        </link>
        <joint name="motoman_joint_s" type="revolute">
            <child>motoman_link_s</child>
            <parent>link0</parent>
            <axis>
                <xyz>0 0 1</xyz>
                <limit>
                    <lower>-3.1416</lower>
                    <upper>3.1416</upper>
                    <effort>100</effort>
                    <velocity>2.26</velocity>
                </limit>
                <dynamics>
                    <spring_reference>0</spring_reference>
                    <spring_stiffness>0</spring_stiffness>
                </dynamics>
                <use_parent_model_frame>1</use_parent_model_frame>
            </axis>
        </joint>
        <link name="motoman_link_l">
            <pose frame="">0 0 0.41 0 -0 0</pose>
            <inertial>
                <pose frame="">0 0 0 0 -0 0</pose>
                <mass>30.6</mass>
                <inertia>
                    <ixx>0.310136</ixx>
                    <ixy>0</ixy>
                    <ixz>0</ixz>
                    <iyy>0.310136</iyy>
                    <iyz>0</iyz>
                    <izz>0.128895</izz>
                </inertia>
            </inertial>
            <collision name="motoman_link_l_collision">
                <pose frame="">0 0 0 -1.57159 -7e-06 7e-06</pose>
                <geometry>
                    <mesh>
                        <scale>1 1 1</scale>
                        <uri>model://motoman_sia20d_support/meshes/sia20d/collision/MOTOMAN_AXIS_L.stl</uri>
                    </mesh>
                </geometry>
                <surface>
                    <contact>
                        <ode />
                    </contact>
                    <friction>
                        <ode />
                    </friction>
                </surface>
            </collision>
            <visual name="motoman_link_l_visual">
                <pose frame="">0 0 0 -1.57159 -7e-06 7e-06</pose>
                <geometry>
                    <mesh>
                        <scale>1 1 1</scale>
                        <uri>model://motoman_sia20d_support/meshes/sia20d/visual/MOTOMAN_AXIS_L.stl</uri>
                    </mesh>
                </geometry>
                <material>
                    <script>
                        <name>Gazebo/White</name>
                        <uri>file://media/materials/scripts/gazebo.material</uri>
                    </script>
                </material>
            </visual>
            <gravity>false</gravity>
            <velocity_decay />
            <self_collide>0</self_collide>
        </link>
        <joint name="motoman_joint_l" type="revolute">
            <child>motoman_link_l</child>
            <parent>motoman_link_s</parent>
            <axis>
                <xyz>0 1 0</xyz>
                <limit>
                    <lower>-1.91</lower>
                    <upper>1.91</upper>
                    <effort>100</effort>
                    <velocity>2.26</velocity>
                </limit>
                <dynamics>
                    <spring_reference>0</spring_reference>
                    <spring_stiffness>0</spring_stiffness>
                </dynamics>
                <use_parent_model_frame>1</use_parent_model_frame>
            </axis>
        </joint>
        <link name="motoman_link_e">
            <pose frame="">0 0 0.9 0 -0 0</pose>
            <inertial>
                <pose frame="">0 0 0 0 -0 0</pose>
                <mass>18.54</mass>
                <inertia>
                    <ixx>0.147277</ixx>
                    <ixy>0</ixy>
                    <ixz>0</ixz>
                    <iyy>0.147277</iyy>
                    <iyz>0</iyz>
                    <izz>0.0521712</izz>
                </inertia>
            </inertial>
            <collision name="motoman_link_e_collision">
                <pose frame="">0 0 0 0 -0 0</pose>
                <geometry>
                    <mesh>
                        <scale>1 1 1</scale>
                        <uri>model://motoman_sia20d_support/meshes/sia20d/collision/MOTOMAN_AXIS_E.stl</uri>
                    </mesh>
                </geometry>
                <surface>
                    <contact>
                        <ode />
                    </contact>
                    <friction>
                        <ode />
                    </friction>
                </surface>
            </collision>
            <visual name="motoman_link_e_visual">
                <pose frame="">0 0 0 0 -0 0</pose>
                <geometry>
                    <mesh>
                        <scale>1 1 1</scale>
                        <uri>model://motoman_sia20d_support/meshes/sia20d/visual/MOTOMAN_AXIS_E.stl</uri>
                    </mesh>
                </geometry>
                <material>
                    <script>
                        <name>Gazebo/Blue</name>
                        <uri>file://media/materials/scripts/gazebo.material</uri>
                    </script>
                </material>
            </visual>
            <gravity>false</gravity>
            <velocity_decay />
            <self_collide>0</self_collide>
        </link>
        <joint name="motoman_joint_e" type="revolute">
            <child>motoman_link_e</child>
            <parent>motoman_link_l</parent>
            <axis>
                <xyz>0 0 1</xyz>
                <limit>
                    <lower>-2.96</lower>
                    <upper>2.96</upper>
                    <effort>100</effort>
                    <velocity>2.96</velocity>
                </limit>
                <dynamics>
                    <spring_reference>0</spring_reference>
                    <spring_stiffness>0</spring_stiffness>
                </dynamics>
                <use_parent_model_frame>1</use_parent_model_frame>
            </axis>
        </joint>
        <link name="motoman_link_u">
            <pose frame="">0 0 0.9 0 -0 0</pose>
            <inertial>
                <pose frame="">0 0 0 0 -0 0</pose>
                <mass>12.9</mass>
                <inertia>
                    <ixx>0.086548</ixx>
                    <ixy>0</ixy>
                    <ixz>0</ixz>
                    <iyy>0.086548</iyy>
                    <iyz>0</iyz>
                    <izz>0.0273309</izz>
                </inertia>
            </inertial>
            <collision name="motoman_link_u_collision">
                <pose frame="">0 0 0 -1.57159 -9.3e-05 7e-06</pose>
                <geometry>
                    <mesh>
                        <scale>1 1 1</scale>
                        <uri>model://motoman_sia20d_support/meshes/sia20d/collision/MOTOMAN_AXIS_U.stl</uri>
                    </mesh>
                </geometry>
                <surface>
                    <contact>
                        <ode />
                    </contact>
                    <friction>
                        <ode />
                    </friction>
                </surface>
            </collision>
            <visual name="motoman_link_u_visual">
                <pose frame="">0 0 0 -1.57159 -9.3e-05 7e-06</pose>
                <geometry>
                    <mesh>
                        <scale>1 1 1</scale>
                        <uri>model://motoman_sia20d_support/meshes/sia20d/visual/MOTOMAN_AXIS_U.stl</uri>
                    </mesh>
                </geometry>
                <material>
                    <script>
                        <name>Gazebo/White</name>
                        <uri>file://media/materials/scripts/gazebo.material</uri>
                    </script>
                </material>
            </visual>
            <gravity>false</gravity>
            <velocity_decay />
            <self_collide>0</self_collide>
        </link>
        <joint name="motoman_joint_u" type="revolute">
            <child>motoman_link_u</child>
            <parent>motoman_link_e</parent>
            <axis>
                <xyz>0 -1 0</xyz>
                <limit>
                    <lower>-2.26</lower>
                    <upper>2.26</upper>
                    <effort>100</effort>
                    <velocity>2.96</velocity>
                </limit>
                <dynamics>
                    <spring_reference>0</spring_reference>
                    <spring_stiffness>0</spring_stiffness>
                </dynamics>
                <use_parent_model_frame>1</use_parent_model_frame>
            </axis>
        </joint>
        <link name="motoman_link_r">
            <pose frame="">0 0 1.32 0 -0 0</pose>
            <inertial>
                <pose frame="">0 0 0 0 -0 0</pose>
                <mass>7.3</mass>
                <inertia>
                    <ixx>0.0349674</ixx>
                    <ixy>0</ixy>
                    <ixz>0</ixz>
                    <iyy>0.0349674</iyy>
                    <iyz>0</iyz>
                    <izz>0.010482</izz>
                </inertia>
            </inertial>
            <collision name="motoman_link_r_collision">
                <pose frame="">0 0 0 0 -0 0</pose>
                <geometry>
                    <mesh>
                        <scale>1 1 1</scale>
                        <uri>model://motoman_sia20d_support/meshes/sia20d/collision/MOTOMAN_AXIS_R.stl</uri>
                    </mesh>
                </geometry>
                <surface>
                    <contact>
                        <ode />
                    </contact>
                    <friction>
                        <ode />
                    </friction>
                </surface>
            </collision>
            <visual name="motoman_link_r_visual">
                <pose frame="">0 0 0 0 -0 0</pose>
                <geometry>
                    <mesh>
                        <scale>1 1 1</scale>
                        <uri>model://motoman_sia20d_support/meshes/sia20d/visual/MOTOMAN_AXIS_R.stl</uri>
                    </mesh>
                </geometry>
                <material>
                    <script>
                        <name>Gazebo/Blue</name>
                        <uri>file://media/materials/scripts/gazebo.material</uri>
                    </script>
                </material>
            </visual>
            <gravity>false</gravity>
            <velocity_decay />
            <self_collide>0</self_collide>
        </link>
        <joint name="motoman_joint_r" type="revolute">
            <child>motoman_link_r</child>
            <parent>motoman_link_u</parent>
            <axis>
                <xyz>0 0 -1</xyz>
                <limit>
                    <lower>-3.1416</lower>
                    <upper>3.1416</upper>
                    <effort>100</effort>
                    <velocity>3.48</velocity>
                </limit>
                <dynamics>
                    <spring_reference>0</spring_reference>
                    <spring_stiffness>0</spring_stiffness>
                </dynamics>
                <use_parent_model_frame>1</use_parent_model_frame>
            </axis>
        </joint>
        <link name="motoman_link_b">
            <pose frame="">0 0 1.32 0 -0 0</pose>
            <inertial>
                <pose frame="">0 0 0 0 -0 0</pose>
                <mass>6.6</mass>
                <inertia>
                    <ixx>0.0286698</ixx>
                    <ixy>0</ixy>
                    <ixz>0</ixz>
                    <iyy>0.0286698</iyy>
                    <iyz>0</iyz>
                    <izz>0.0088123</izz>
                </inertia>
            </inertial>
            <collision name="motoman_link_b_collision">
                <pose frame="">0 0 0 -1.57 0 0</pose>
                <geometry>
                    <mesh>
                        <scale>1 1 1</scale>
                        <uri>model://motoman_sia20d_support/meshes/sia20d/collision/MOTOMAN_AXIS_B.stl</uri>
                    </mesh>
                </geometry>
                <surface>
                    <contact>
                        <ode />
                    </contact>
                    <friction>
                        <ode />
                    </friction>
                </surface>
            </collision>
            <visual name="motoman_link_b_visual">
                <pose frame="">0 0 0 -1.57 0 0</pose>
                <geometry>
                    <mesh>
                        <scale>1 1 1</scale>
                        <uri>model://motoman_sia20d_support/meshes/sia20d/visual/MOTOMAN_AXIS_B.stl</uri>
                    </mesh>
                </geometry>
                <material>
                    <script>
                        <name>Gazebo/White</name>
                        <uri>file://media/materials/scripts/gazebo.material</uri>
                    </script>
                </material>
            </visual>
            <gravity>false</gravity>
            <velocity_decay />
            <self_collide>0</self_collide>
        </link>
        <joint name="motoman_joint_b" type="revolute">
            <child>motoman_link_b</child>
            <parent>motoman_link_r</parent>
            <axis>
                <xyz>0 -1 0</xyz>
                <limit>
                    <lower>-1.91</lower>
                    <upper>1.91</upper>
                    <effort>100</effort>
                    <velocity>3.48</velocity>
                </limit>
                <dynamics>
                    <spring_reference>0</spring_reference>
                    <spring_stiffness>0</spring_stiffness>
                </dynamics>
                <use_parent_model_frame>1</use_parent_model_frame>
            </axis>
        </joint>
#ifdef MOTO_ROBOTIQ
#include "Moto_Robotiq.sdf"
#endif
#ifdef MOTO_APRS_FINGERS
#include "Moto_Aprs_Fingers.sdf"
#endif
#ifdef MOTO_OLD_GRASPING_KLUDGE
        <gripper name="grasping">
            <grasp_check>
                <attach_steps>40</attach_steps>
                <detach_steps>20</detach_steps>
                <min_contact_count>1</min_contact_count>
            </grasp_check>
            <gripper_link>link_rightfinger</gripper_link>
            <gripper_link>link_leftfinger</gripper_link>
            <palm_link>motoman_link_t</palm_link>
        </gripper>
#endif
    </model>
</sdf>
