<?xml version="1.0" ?>
<!-- =================================================================================== -->
<!-- |    This document was autogenerated by xacro from lrmate200id_and_c2_only.xacro  | -->
<!-- |    EDITING THIS FILE BY HAND IS NOT RECOMMENDED                                 | -->
<!-- =================================================================================== -->
<robot name="fanuc_lrmate200id" xmlns:xacro="http://ros.org/wiki/xacro">
  <!-- The 'pi' constant in this file is DEPRECATED. Use the '(math.)pi'
       constant supported by Indigo/Jade/Kinetic xacro instead.

       This file is kept for bw-compatibility, but will be removed in
       Kinetic.
  -->
  <link name="fanuc_base_link">
    <visual>
      <origin rpy="0 0 0" xyz="0 0 0"/>
      <geometry>
        <mesh filename="package://fanuc_lrmate200id_support/meshes/lrmate200id/visual/base_link.stl" scale="1.0 1.0 1.0"/>
      </geometry>
      <material name="">
        <color rgba="0.278431372549 0.278431372549 0.278431372549 1.0"/>
      </material>
    </visual>
    <collision>
      <origin rpy="0 0 0" xyz="0 0 0"/>
      <geometry>
        <mesh filename="package://fanuc_lrmate200id_support/meshes/lrmate200id/visual/base_link.stl" scale="1.0 1.0 1.0"/>
      </geometry>
    </collision>
  </link>
  <link name="fanuc_link_1">
    <inertial>
      <mass value="4"/>
      <inertia ixx="0.0322667" ixy="0.0" ixz="0.0" iyy="0.0226667" iyz="0.0" izz="0.0226667"/>
    </inertial>
    <visual>
      <origin rpy="0 0 0" xyz="0 0 0"/>
      <geometry>
        <mesh filename="package://fanuc_lrmate200id_support/meshes/lrmate200id/visual/link_1.stl" scale="1.0 1.0 1.0"/>
      </geometry>
      <material name="">
        <color rgba="0.96 0.76 0.13 1.0"/>
      </material>
    </visual>
    <collision>
      <origin rpy="0 0 0" xyz="0 0 0"/>
      <geometry>
        <mesh filename="package://fanuc_lrmate200id_support/meshes/lrmate200id/visual/link_1.stl" scale="1.0 1.0 1.0"/>
      </geometry>
    </collision>
  </link>
  <link name="fanuc_link_2">
    <inertial>
      <mass value="5"/>
      <inertia ixx="0.0973333" ixy="0.0" ixz="0.0" iyy="0.0888333" iyz="0.0" izz="0.0248333"/>
    </inertial>
    <visual>
      <origin rpy="0 0 0" xyz="0 0 0"/>
      <geometry>
        <mesh filename="package://fanuc_lrmate200id_support/meshes/lrmate200id/visual/link_2.stl" scale="1.0 1.0 1.0"/>
      </geometry>
      <material name="">
        <color rgba="0.96 0.76 0.13 1.0"/>
      </material>
    </visual>
    <collision>
      <origin rpy="0 0 0" xyz="0 0 0"/>
      <geometry>
        <mesh filename="package://fanuc_lrmate200id_support/meshes/lrmate200id/visual/link_2.stl" scale="1.0 1.0 1.0"/>
      </geometry>
    </collision>
  </link>
  <link name="fanuc_link_3">
    <inertial>
      <mass value="4"/>
      <inertia ixx="0.0104333" ixy="0.0" ixz="0.0" iyy="0.0121667" iyz="0.0" izz="0.0113333"/>
    </inertial>
    <visual>
      <origin rpy="0 0 0" xyz="0 0 0"/>
      <geometry>
        <mesh filename="package://fanuc_lrmate200id_support/meshes/lrmate200id/visual/link_3.stl" scale="1.0 1.0 1.0"/>
      </geometry>
      <material name="">
        <color rgba="0.96 0.76 0.13 1.0"/>
      </material>
    </visual>
    <collision>
      <origin rpy="0 0 0" xyz="0 0 0"/>
      <geometry>
        <mesh filename="package://fanuc_lrmate200id_support/meshes/lrmate200id/visual/link_3.stl" scale="1.0 1.0 1.0"/>
      </geometry>
    </collision>
  </link>
  <link name="fanuc_link_4">
    <inertial>
      <mass value="5"/>
      <inertia ixx="0.00833333" ixy="0.0" ixz="0.0" iyy="0.0368333" iyz="0.0" izz="0.0368333"/>
    </inertial>
    <visual>
      <origin rpy="0 0 0" xyz="0 0 0"/>
      <geometry>
        <mesh filename="package://fanuc_lrmate200id_support/meshes/lrmate200id/visual/link_4.stl" scale="1.0 1.0 1.0"/>
      </geometry>
      <material name="">
        <color rgba="0.96 0.76 0.13 1.0"/>
      </material>
    </visual>
    <collision>
      <origin rpy="0 0 0" xyz="0 0 0"/>
      <geometry>
        <mesh filename="package://fanuc_lrmate200id_support/meshes/lrmate200id/visual/link_4.stl" scale="1.0 1.0 1.0"/>
      </geometry>
    </collision>
  </link>
  <link name="fanuc_link_5">
    <inertial>
      <mass value="1.5"/>
      <inertia ixx="0.0018125" ixy="0.0" ixz="0.0" iyy="0.0023125" iyz="0.0" izz="0.002525"/>
    </inertial>
    <visual>
      <origin rpy="0 0 0" xyz="0 0 0"/>
      <geometry>
        <mesh filename="package://fanuc_lrmate200id_support/meshes/lrmate200id/visual/link_5.stl" scale="1.0 1.0 1.0"/>
      </geometry>
      <material name="">
        <color rgba="0.96 0.76 0.13 1.0"/>
      </material>
    </visual>
    <collision>
      <origin rpy="0 0 0" xyz="0 0 0"/>
      <geometry>
        <mesh filename="package://fanuc_lrmate200id_support/meshes/lrmate200id/visual/link_5.stl" scale="1.0 1.0 1.0"/>
      </geometry>
    </collision>
  </link>
  <link name="fanuc_link_6">
    <inertial>
      <mass value="0.25"/>
      <inertia ixx="6.66666e-05" ixy="0.0" ixz="0.0" iyy="3.54167e-05" iyz="0.0" izz="3.54167e-05"/>
    </inertial>
    <visual>
      <origin rpy="0 0 0" xyz="0 0 0"/>
      <geometry>
        <mesh filename="package://fanuc_lrmate200id_support/meshes/lrmate200id/visual/link_6.stl" scale="1.0 1.0 1.0"/>
      </geometry>
      <material name="">
        <color rgba="0.15 0.15 0.15 1.0"/>
      </material>
    </visual>
    <collision>
      <origin rpy="0 0 0" xyz="0 0 0"/>
      <geometry>
        <mesh filename="package://fanuc_lrmate200id_support/meshes/lrmate200id/visual/link_6.stl" scale="1.0 1.0 1.0"/>
      </geometry>
    </collision>
  </link>
  <!--   <link name="${prefix}tool0" /> -->
  <joint name="fanuc_joint_1" type="revolute">
    <origin rpy="0 0 0.0" xyz="0 0 0.33"/>
    <!-- <origin xyz="0 0 0.330" rpy="0 0 0" />-->
    <parent link="fanuc_base_link"/>
    <child link="fanuc_link_1"/>
    <axis xyz="0 0 1"/>
    <limit effort="0" lower="-2.965" upper="2.965" velocity="7.85"/>
  </joint>
  <joint name="fanuc_joint_2" type="revolute">
    <origin rpy="0 0 0" xyz="0.050 0 0"/>
    <parent link="fanuc_link_1"/>
    <child link="fanuc_link_2"/>
    <axis xyz="0 1 0"/>
    <limit effort="0" lower="-1.745329" upper="2.530727" velocity="6.63"/>
  </joint>
  <joint name="fanuc_joint_3" type="revolute">
    <origin rpy="0 0 0" xyz="0 0 0.330"/>
    <parent link="fanuc_link_2"/>
    <child link="fanuc_link_3"/>
    <axis xyz="0 -1 0"/>
    <limit effort="0" lower="-2.450966" upper="4.886922" velocity="9.08"/>
  </joint>
  <joint name="fanuc_joint_4" type="revolute">
    <origin rpy="0 0 0" xyz="0 0 0.035"/>
    <parent link="fanuc_link_3"/>
    <child link="fanuc_link_4"/>
    <axis xyz="-1 0 0"/>
    <limit effort="0" lower="-3.315" upper="3.315" velocity="9.6"/>
  </joint>
  <joint name="fanuc_joint_5" type="revolute">
    <origin rpy="0 0 0" xyz="0.335 0 0"/>
    <parent link="fanuc_link_4"/>
    <child link="fanuc_link_5"/>
    <axis xyz="0 -1 0"/>
    <limit effort="0" lower="-2.18" upper="2.18" velocity="9.51"/>
  </joint>
  <joint name="fanuc_joint_6" type="revolute">
    <origin rpy="0 0 0" xyz="0.080 0 0"/>
    <parent link="fanuc_link_5"/>
    <child link="fanuc_link_6"/>
    <axis xyz="-1 0 0"/>
    <limit effort="0" lower="-6.285" upper="6.285" velocity="17.45"/>
  </joint>
  <gazebo reference="fanuc_base_link">
    <material>Gazebo/Grey</material>
  </gazebo>
  <gazebo reference="fanuc_link_1">
    <material>Gazebo/Yellow</material>
  </gazebo>
  <gazebo reference="fanuc_link_2">
    <material>Gazebo/Yellow</material>
  </gazebo>
  <gazebo reference="fanuc_link_3">
    <material>Gazebo/Yellow</material>
  </gazebo>
  <gazebo reference="fanuc_link_4">
    <material>Gazebo/Yellow</material>
  </gazebo>
  <gazebo reference="fanuc_link_5">
    <material>Gazebo/Yellow</material>
  </gazebo>
  <gazebo reference="fanuc_link_6">
    <material>Gazebo/Yellow</material>
  </gazebo>
   <!--[ERROR] [1474736838.974400369]: joint 'fanuc_joint_6-tool0' is not unique.-->
  <!-- First Robot -->
  <!-- ROS base_link to Fanuc World Coordinates transform -->
 
</robot>
