<?xml version="1.0" ?>
<robot name="fanuc_lrmate200id">
  <joint name="fanuc_lrmate200id__world_joint" type="fixed">
    <parent link="fanuc_lrmate200id__world"/>
    <child link="fanuc_lrmate200id__link0"/>
    <origin rpy="0 0 0" xyz="0 0 0"/>
    <axis xyz="0 0 1"/>
    <limit effort="0.0" lower="0.0" upper="0.0" velocity="0.0"/>
  </joint>
  <joint name="fanuc_lrmate200id__fanuc_joint_1" type="revolute">
    <parent link="fanuc_lrmate200id__link0"/>
    <child link="fanuc_lrmate200id__fanuc_link_1"/>
    <origin rpy="0 0 0" xyz="0   0   0.33"/>
    <axis xyz="0 0 1"/>
    <limit effort="0.0" lower="-2.965" upper="2.965" velocity="7.85"/>
  </joint>
  <joint name="fanuc_lrmate200id__fanuc_joint_2" type="revolute">
    <parent link="fanuc_lrmate200id__fanuc_link_1"/>
    <child link="fanuc_lrmate200id__fanuc_link_2"/>
    <origin rpy="0 0 0" xyz="0.05 0   0"/>
    <axis xyz="0 1 0"/>
    <limit effort="0.0" lower="-1.74533" upper="2.53073" velocity="6.63"/>
  </joint>
  <joint name="fanuc_lrmate200id__fanuc_joint_3" type="revolute">
    <parent link="fanuc_lrmate200id__fanuc_link_2"/>
    <child link="fanuc_lrmate200id__fanuc_link_3"/>
    <origin rpy="0 0 0" xyz="0   0   0.33"/>
    <axis xyz="0 -1  0"/>
    <limit effort="0.0" lower="-2.45097" upper="4.88692" velocity="9.08"/>
  </joint>
  <joint name="fanuc_lrmate200id__fanuc_joint_4" type="revolute">
    <parent link="fanuc_lrmate200id__fanuc_link_3"/>
    <child link="fanuc_lrmate200id__fanuc_link_4"/>
    <origin rpy="0 0 0" xyz="0    0    0.035"/>
    <axis xyz="-1  0  0"/>
    <limit effort="0.0" lower="-3.315" upper="3.315" velocity="9.6"/>
  </joint>
  <joint name="fanuc_lrmate200id__fanuc_joint_5" type="revolute">
    <parent link="fanuc_lrmate200id__fanuc_link_4"/>
    <child link="fanuc_lrmate200id__fanuc_link_5"/>
    <origin rpy="0 0 0" xyz="0.335 0    0"/>
    <axis xyz="0 -1  0"/>
    <limit effort="0.0" lower="-2.18" upper="2.18" velocity="9.51"/>
  </joint>
  <joint name="fanuc_lrmate200id__fanuc_joint_6" type="revolute">
    <parent link="fanuc_lrmate200id__fanuc_link_5"/>
    <child link="fanuc_lrmate200id__fanuc_link_6"/>
    <origin rpy="0 0 0" xyz="0.074 0    0"/>
    <axis xyz="-1  0  0"/>
    <limit effort="0.0" lower="-6.285" upper="6.285" velocity="17.45"/>
  </joint>
  <joint name="fanuc_lrmate200id__fanuc_prism1" type="prismatic">
    <parent link="fanuc_lrmate200id__fanuc_link_6"/>
    <child link="fanuc_lrmate200id__fanuc_finger_1"/>
    <origin rpy="-3.14159  0       1.5708" xyz="0.1401  0.02    0.01099"/>
    <axis xyz="-1  0  0"/>
    <limit effort="1000.0" lower="-0.008" upper="0.0" velocity="1000.0"/>
  </joint>
  <joint name="fanuc_lrmate200id__fanuc_prism2" type="prismatic">
    <parent link="fanuc_lrmate200id__fanuc_link_6"/>
    <child link="fanuc_lrmate200id__fanuc_finger_2"/>
    <origin rpy="-3.14159  0      -1.5708" xyz="0.1401   0      -0.01099"/>
    <axis xyz="-1  0  0"/>
    <limit effort="1000.0" lower="-0.008" upper="0.0" velocity="1000.0"/>
  </joint>
  <link name="fanuc_lrmate200id__world">
    <inertial>
      <mass value="0"/>
      <origin rpy="0 0 0" xyz="0 0 0"/>
      <inertia ixx="0" ixy="0" ixz="0" iyy="0" iyz="0" izz="0"/>
    </inertial>
  </link>
  <link name="fanuc_lrmate200id__link0">
    <inertial>
      <mass value="4"/>
      <origin rpy="0 0 0" xyz="0 0 0"/>
      <inertia ixx="0.0216667" ixy="0" ixz="0" iyy="0.0216667" iyz="0" izz="0.0240667"/>
    </inertial>
    <collision name="fanuc_lrmate200id__link0_fixed_joint_lump__fanuc_base_link_collision">
      <origin rpy="0 0 0" xyz="0 0 0"/>
      <geometry>
        <mesh filename="package://PATHTOMESHES/meshes/lrmate200id/visual/base_link.stl" scale="1 1 1"/>
      </geometry>
    </collision>
    <visual name="fanuc_lrmate200id__link0_fixed_joint_lump__fanuc_base_link_visual">
      <origin rpy="0 0 0" xyz="0 0 0"/>
      <geometry>
        <mesh filename="package://PATHTOMESHES/meshes/lrmate200id/visual/base_link.stl" scale="1 1 1"/>
      </geometry>
    </visual>
  </link>
  <link name="fanuc_lrmate200id__fanuc_link_1">
    <inertial>
      <mass value="4"/>
      <origin rpy="0 0 0" xyz="0 0 0"/>
      <inertia ixx="0.0322667" ixy="0" ixz="0" iyy="0.0226667" iyz="0" izz="0.0226667"/>
    </inertial>
    <collision name="fanuc_lrmate200id__fanuc_link_1_collision">
      <origin rpy="0 0 0" xyz="0 0 0"/>
      <geometry>
        <mesh filename="package://PATHTOMESHES/meshes/lrmate200id/visual/link_1.stl" scale="1 1 1"/>
      </geometry>
    </collision>
    <visual name="fanuc_lrmate200id__fanuc_link_1_visual">
      <origin rpy="0 0 0" xyz="0 0 0"/>
      <geometry>
        <mesh filename="package://PATHTOMESHES/meshes/lrmate200id/visual/link_1.stl" scale="1 1 1"/>
      </geometry>
    </visual>
  </link>
  <link name="fanuc_lrmate200id__fanuc_link_2">
    <inertial>
      <mass value="5"/>
      <origin rpy="0 0 0" xyz="0 0 0"/>
      <inertia ixx="0.0973333" ixy="0" ixz="0" iyy="0.0888333" iyz="0" izz="0.0248333"/>
    </inertial>
    <collision name="fanuc_lrmate200id__fanuc_link_2_collision">
      <origin rpy="0 0 0" xyz="0 0 0"/>
      <geometry>
        <mesh filename="package://PATHTOMESHES/meshes/lrmate200id/visual/link_2.stl" scale="1 1 1"/>
      </geometry>
    </collision>
    <visual name="fanuc_lrmate200id__fanuc_link_2_visual">
      <origin rpy="0 0 0" xyz="0 0 0"/>
      <geometry>
        <mesh filename="package://PATHTOMESHES/meshes/lrmate200id/visual/link_2.stl" scale="1 1 1"/>
      </geometry>
    </visual>
  </link>
  <link name="fanuc_lrmate200id__fanuc_link_3">
    <inertial>
      <mass value="4"/>
      <origin rpy="0 0 0" xyz="0 0 0"/>
      <inertia ixx="0.0104333" ixy="0" ixz="0" iyy="0.0121667" iyz="0" izz="0.0113333"/>
    </inertial>
    <collision name="fanuc_lrmate200id__fanuc_link_3_collision">
      <origin rpy="0 0 0" xyz="0 0 0"/>
      <geometry>
        <mesh filename="package://PATHTOMESHES/meshes/lrmate200id/visual/link_3.stl" scale="1 1 1"/>
      </geometry>
    </collision>
    <visual name="fanuc_lrmate200id__fanuc_link_3_visual">
      <origin rpy="0 0 0" xyz="0 0 0"/>
      <geometry>
        <mesh filename="package://PATHTOMESHES/meshes/lrmate200id/visual/link_3.stl" scale="1 1 1"/>
      </geometry>
    </visual>
  </link>
  <link name="fanuc_lrmate200id__fanuc_link_4">
    <inertial>
      <mass value="5"/>
      <origin rpy="0 0 0" xyz="0 0 0"/>
      <inertia ixx="0.00833333" ixy="0" ixz="0" iyy="0.0368333" iyz="0" izz="0.0368333"/>
    </inertial>
    <collision name="fanuc_lrmate200id__fanuc_link_4_collision">
      <origin rpy="0 0 0" xyz="0 0 0"/>
      <geometry>
        <mesh filename="package://PATHTOMESHES/meshes/lrmate200id/visual/link_4.stl" scale="1 1 1"/>
      </geometry>
    </collision>
    <visual name="fanuc_lrmate200id__fanuc_link_4_visual">
      <origin rpy="0 0 0" xyz="0 0 0"/>
      <geometry>
        <mesh filename="package://PATHTOMESHES/meshes/lrmate200id/visual/link_4.stl" scale="1 1 1"/>
      </geometry>
    </visual>
  </link>
  <link name="fanuc_lrmate200id__fanuc_link_5">
    <inertial>
      <mass value="1.5"/>
      <origin rpy="0 0 0" xyz="0 0 0"/>
      <inertia ixx="0.0018125" ixy="0" ixz="0" iyy="0.0023125" iyz="0" izz="0.002525"/>
    </inertial>
    <collision name="fanuc_lrmate200id__fanuc_link_5_collision">
      <origin rpy="0 0 0" xyz="0 0 0"/>
      <geometry>
        <mesh filename="package://PATHTOMESHES/meshes/lrmate200id/visual/link_5.stl" scale="1 1 1"/>
      </geometry>
    </collision>
    <visual name="fanuc_lrmate200id__fanuc_link_5_visual">
      <origin rpy="0 0 0" xyz="0 0 0"/>
      <geometry>
        <mesh filename="package://PATHTOMESHES/meshes/lrmate200id/visual/link_5.stl" scale="1 1 1"/>
      </geometry>
    </visual>
  </link>
  <link name="fanuc_lrmate200id__fanuc_link_6">
    <inertial>
      <mass value="4"/>
      <origin rpy="0 0 0" xyz="0 0 0"/>
      <inertia ixx="1e-3" ixy="0" ixz="0" iyy="1e-3" iyz="0" izz="1e-3"/>
    </inertial>
    <collision name="fanuc_lrmate200id__fanuc_link_6_collision">
      <origin rpy="0 0 0" xyz="0 0 0"/>
      <geometry>
        <mesh filename="package://PATHTOMESHES/meshes/fanuc_link_6.STL" scale="1 1 1"/>
      </geometry>
    </collision>
    <visual name="fanuc_lrmate200id__fanuc_link_6_visual">
      <origin rpy="0 0 0" xyz="0 0 0"/>
      <geometry>
        <mesh filename="package://PATHTOMESHES/meshes/fanuc_link_6.STL" scale="1 1 1"/>
      </geometry>
    </visual>
  </link>
  <link name="fanuc_lrmate200id__fanuc_finger_1">
    <inertial>
      <mass value="0.1"/>
      <origin rpy="0 0 0" xyz="0 0 0"/>
      <inertia ixx="1e-3" ixy="0" ixz="0" iyy="1e-3" iyz="0" izz="1e-3"/>
    </inertial>
    <collision name="fanuc_lrmate200id__fanuc_finger_1_collision">
      <origin rpy="0 0 0" xyz="0 0 0"/>
      <geometry>
        <mesh filename="package://PATHTOMESHES/meshes/fanuc_finger_1.STL" scale="1 1 1"/>
      </geometry>
    </collision>
    <visual name="fanuc_lrmate200id__fanuc_finger_1_visual">
      <origin rpy="0 0 0" xyz="0 0 0"/>
      <geometry>
        <mesh filename="package://PATHTOMESHES/meshes/fanuc_finger_1.STL" scale="1 1 1"/>
      </geometry>
    </visual>
  </link>
  <link name="fanuc_lrmate200id__fanuc_finger_2">
    <inertial>
      <mass value="0.1"/>
      <origin rpy="0 0 0" xyz="0 0 0"/>
      <inertia ixx="1e-3" ixy="0" ixz="0" iyy="1e-3" iyz="0" izz="1e-3"/>
    </inertial>
    <collision name="fanuc_lrmate200id__fanuc_finger_2_collision">
      <origin rpy="0 0 0" xyz="0 0 0"/>
      <geometry>
        <mesh filename="package://PATHTOMESHES/meshes/fanuc_finger_2.STL" scale="1 1 1"/>
      </geometry>
    </collision>
    <visual name="fanuc_lrmate200id__fanuc_finger_2_visual">
      <origin rpy="0 0 0" xyz="0 0 0"/>
      <geometry>
        <mesh filename="package://PATHTOMESHES/meshes/fanuc_finger_2.STL" scale="1 1 1"/>
      </geometry>
    </visual>
  </link>
</robot>
