<?xml version="1.0" ?>
<!-- =================================================================================== -->
<!-- |    This document was autogenerated by xacro from fanuc_only.xacro               | -->
<!-- |    EDITING THIS FILE BY HAND IS NOT RECOMMENDED                                 | -->
<!-- =================================================================================== -->
<robot name="fanuc_lrmate200id" xmlns:xacro="http://ros.org/wiki/xacro">
  <link name="world"/>
  <joint name="fanuc_base_link-base" type="fixed">
    <origin rpy="0 0 0" xyz="0 0 0"/>
    <parent link="world"/>
    <child link="fanuc_base_link"/>
  </joint>
  <!-- links: main serial chain -->
  <link name="fanuc_base_link">
    <visual>
      <origin rpy="0 0 0" xyz="0 0 0"/>
      <geometry>
        <mesh filename="package://fanuc_lrmate200id_support/meshes/lrmate200id/visual/base_link.stl"/>
      </geometry>
      <material name="">
        <color rgba="0.278431372549 0.278431372549 0.278431372549 1.0"/>
      </material>
    </visual>
    <collision>
      <origin rpy="0 0 0" xyz="0 0 0"/>
      <geometry>
        <mesh filename="package://fanuc_lrmate200id_support/meshes/lrmate200id/collision/base_link.stl"/>
      </geometry>
    </collision>
    <inertial>
      <mass value="0.1"/>
      <inertia ixx="0.03" ixy="0.0" ixz="0.0" iyy="0.03" iyz="0.0" izz="0.03"/>
    </inertial>
  </link>
  <link name="fanuc_link_1">
    <visual>
      <origin rpy="0 0 0" xyz="0 0 0"/>
      <geometry>
        <mesh filename="package://fanuc_lrmate200id_support/meshes/lrmate200id/visual/link_1.stl"/>
      </geometry>
      <material name="">
        <color rgba="0.96 0.76 0.13 1.0"/>
      </material>
    </visual>
    <collision>
      <origin rpy="0 0 0" xyz="0 0 0"/>
      <geometry>
        <mesh filename="package://fanuc_lrmate200id_support/meshes/lrmate200id/collision/link_1.stl"/>
      </geometry>
    </collision>
    <inertial>
      <origin rpy="0 0 0" xyz="0 0 0"/>
      <mass value="1"/>
      <inertia ixx="0.0226667" ixy="0.0" ixz="0.0" iyy="0.0226667" iyz="0.0" izz="0.0226667"/>
    </inertial>
  </link>
  <link name="fanuc_link_2">
    <visual>
      <origin rpy="0 0 0" xyz="0 0 0"/>
      <geometry>
        <mesh filename="package://fanuc_lrmate200id_support/meshes/lrmate200id/visual/link_2.stl"/>
      </geometry>
      <material name="">
        <color rgba="0.96 0.76 0.13 1.0"/>
      </material>
    </visual>
    <collision>
      <origin rpy="0 0 0" xyz="0 0 0"/>
      <geometry>
        <mesh filename="package://fanuc_lrmate200id_support/meshes/lrmate200id/collision/link_2.stl"/>
      </geometry>
    </collision>
    <inertial>
      <origin rpy="0 0 0" xyz="0 0 0"/>
      <mass value="1"/>
      <inertia ixx="0.0226667" ixy="0.0" ixz="0.0" iyy="0.0226667" iyz="0.0" izz="0.0226667"/>
    </inertial>
  </link>
  <link name="fanuc_link_3">
    <visual>
      <origin rpy="0 0 0" xyz="0 0 0"/>
      <geometry>
        <mesh filename="package://fanuc_lrmate200id_support/meshes/lrmate200id/visual/link_3.stl"/>
      </geometry>
      <material name="">
        <color rgba="0.96 0.76 0.13 1.0"/>
      </material>
    </visual>
    <collision>
      <origin rpy="0 0 0" xyz="0 0 0"/>
      <geometry>
        <mesh filename="package://fanuc_lrmate200id_support/meshes/lrmate200id/collision/link_3.stl"/>
      </geometry>
    </collision>
    <inertial>
      <origin rpy="0 0 0" xyz="0 0 0"/>
      <mass value="1"/>
      <inertia ixx="0.0226667" ixy="0.0" ixz="0.0" iyy="0.0226667" iyz="0.0" izz="0.0226667"/>
    </inertial>
  </link>
  <link name="fanuc_link_4">
    <visual>
      <origin rpy="0 0 0" xyz="0 0 0"/>
      <geometry>
        <mesh filename="package://fanuc_lrmate200id_support/meshes/lrmate200id/visual/link_4.stl"/>
      </geometry>
      <material name="">
        <color rgba="0.96 0.76 0.13 1.0"/>
      </material>
    </visual>
    <collision>
      <origin rpy="0 0 0" xyz="0 0 0"/>
      <geometry>
        <mesh filename="package://fanuc_lrmate200id_support/meshes/lrmate200id/collision/link_4.stl"/>
      </geometry>
    </collision>
    <inertial>
      <origin rpy="0 0 0" xyz="0 0 0"/>
      <mass value="1"/>
      <inertia ixx="0.0226667" ixy="0.0" ixz="0.0" iyy="0.0226667" iyz="0.0" izz="0.0226667"/>
    </inertial>
  </link>
  <link name="fanuc_link_5">
    <visual>
      <origin rpy="0 0 0" xyz="0 0 0"/>
      <geometry>
        <mesh filename="package://fanuc_lrmate200id_support/meshes/lrmate200id/visual/link_5.stl"/>
      </geometry>
      <material name="">
        <color rgba="0.96 0.76 0.13 1.0"/>
      </material>
    </visual>
    <collision>
      <origin rpy="0 0 0" xyz="0 0 0"/>
      <geometry>
        <mesh filename="package://fanuc_lrmate200id_support/meshes/lrmate200id/collision/link_5.stl"/>
      </geometry>
    </collision>
    <inertial>
      <origin rpy="0 0 0" xyz="0 0 0"/>
      <mass value="1"/>
      <inertia ixx="0.0226667" ixy="0.0" ixz="0.0" iyy="0.0226667" iyz="0.0" izz="0.0226667"/>
    </inertial>
  </link>
  <link name="fanuc_link_6">
    <visual>
      <origin rpy="0 0 0" xyz="0 0 0"/>
      <geometry>
        <mesh filename="package://fanuc_lrmate200id_support/meshes/lrmate200id/visual/link_6.stl"/>
      </geometry>
      <material name="">
        <color rgba="0.15 0.15 0.15 1.0"/>
      </material>
    </visual>
    <collision>
      <origin rpy="0 0 0" xyz="0 0 0"/>
      <geometry>
        <mesh filename="package://fanuc_lrmate200id_support/meshes/lrmate200id/collision/link_6.stl"/>
      </geometry>
    </collision>
    <inertial>
      <origin rpy="0 0 0" xyz="0 0 0"/>
      <mass value="1"/>
      <inertia ixx="0.0226667" ixy="0.0" ixz="0.0" iyy="0.0226667" iyz="0.0" izz="0.0226667"/>
    </inertial>
  </link>
  <!--   <link name="${prefix}tool0" /> -->
  <joint name="fanuc_joint_1" type="revolute">
    <origin rpy="0 0 0" xyz="0 0 0.330"/>
    <parent link="fanuc_base_link"/>
    <child link="fanuc_link_1"/>
    <axis xyz="0 0 1"/>
    <limit effort="0" lower="-2.965" upper="2.965" velocity="7.85"/>
  </joint>
  <joint name="fanuc_joint_2" type="revolute">
    <origin rpy="0 0 0" xyz="0.050 0 0"/>
    <parent link="fanuc_link_1"/>
    <child link="fanuc_link_2"/>
    <axis xyz="0 1 0"/>
    <limit effort="0" lower="-1.745329" upper="2.530727" velocity="6.63"/>
  </joint>
  <joint name="fanuc_joint_3" type="revolute">
    <origin rpy="0 0 0" xyz="0 0 0.330"/>
    <parent link="fanuc_link_2"/>
    <child link="fanuc_link_3"/>
    <axis xyz="0 -1 0"/>
    <limit effort="0" lower="-2.450966" upper="4.886922" velocity="9.08"/>
  </joint>
  <joint name="fanuc_joint_4" type="revolute">
    <origin rpy="0 0 0" xyz="0 0 0.035"/>
    <parent link="fanuc_link_3"/>
    <child link="fanuc_link_4"/>
    <axis xyz="-1 0 0"/>
    <limit effort="0" lower="-3.315" upper="3.315" velocity="9.6"/>
  </joint>
  <joint name="fanuc_joint_5" type="revolute">
    <origin rpy="0 0 0" xyz="0.335 0 0"/>
    <parent link="fanuc_link_4"/>
    <child link="fanuc_link_5"/>
    <axis xyz="0 -1 0"/>
    <limit effort="0" lower="-2.18" upper="2.18" velocity="9.51"/>
  </joint>
  <joint name="fanuc_joint_6" type="revolute">
    <origin rpy="0 0 0" xyz="0.080 0 0"/>
    <parent link="fanuc_link_5"/>
    <child link="fanuc_link_6"/>
    <axis xyz="-1 0 0"/>
    <limit effort="0" lower="-6.285" upper="6.285" velocity="17.45"/>
  </joint>
  <gazebo reference="fanuc_base_link">
    <material>Gazebo/Grey</material>
    <turnGravityOff>true</turnGravityOff>
  </gazebo>
  <gazebo reference="fanuc_link_1">
    <material>Gazebo/Yellow</material>
    <turnGravityOff>true</turnGravityOff>
  </gazebo>
  <gazebo reference="fanuc_link_2">
    <material>Gazebo/Yellow</material>
    <turnGravityOff>true</turnGravityOff>
  </gazebo>
  <gazebo reference="fanuc_link_3">
    <material>Gazebo/Yellow</material>
    <turnGravityOff>true</turnGravityOff>
  </gazebo>
  <gazebo reference="fanuc_link_4">
    <material>Gazebo/Yellow</material>
    <turnGravityOff>true</turnGravityOff>
  </gazebo>
  <gazebo reference="fanuc_link_5">
    <material>Gazebo/Yellow</material>
    <turnGravityOff>true</turnGravityOff>
  </gazebo>
  <gazebo reference="fanuc_link_6">
    <material>Gazebo/Yellow</material>
    <turnGravityOff>true</turnGravityOff>
  </gazebo>
  <link name="fanuc_finger_1">
    <visual>
      <origin rpy="0 0 0" xyz="0 0 0"/>
      <geometry>
        <mesh filename="package://fanuc_lrmate200id_support/meshes/lrmate200id/visual/fanuc_finger_1.STL"/>
      </geometry>
      <material name="">
        <color rgba="0.15 0.15 0.15 1.0"/>
      </material>
    </visual>
    <collision>
      <origin rpy="0 0 0" xyz="0 0 0"/>
      <geometry>
        <mesh filename="package://fanuc_lrmate200id_support/meshes/lrmate200id/collision/fanuc_finger_1.STL"/>
      </geometry>
    </collision>
    <inertial>
      <origin rpy="0 0 0" xyz="0 0 0"/>
      <mass value="1"/>
      <inertia ixx="1e-3" ixy="0.0" ixz="0.0" iyy="1e-3" iyz="0.0" izz="1e-3"/>
    </inertial>
  </link>
  <link name="fanuc_finger_2">
    <visual>
      <origin rpy="0 0 0" xyz="0 0 0"/>
      <geometry>
        <mesh filename="package://fanuc_lrmate200id_support/meshes/lrmate200id/visual/fanuc_finger_2.STL"/>
      </geometry>
      <material name="">
        <color rgba="0.15 0.15 0.15 1.0"/>
      </material>
    </visual>
    <collision>
      <origin rpy="0 0 0" xyz="0 0 0"/>
      <geometry>
        <mesh filename="package://fanuc_lrmate200id_support/meshes/lrmate200id/collision/fanuc_finger_2.STL"/>
      </geometry>
    </collision>
    <inertial>
      <origin rpy="0 0 0" xyz="0 0 0"/>
      <mass value="1"/>
      <inertia ixx="1e-3" ixy="0.0" ixz="0.0" iyy="1e-3" iyz="0.0" izz="1e-3"/>
    </inertial>
  </link>
  <joint name="fanuc_prism1" type="prismatic">
    <origin rpy="-3.14159  0       1.5708" xyz="0.0 0.02    0.01099"/>
    <parent link="fanuc_link_6"/>
    <child link="fanuc_finger_1"/>
    <axis xyz="-1 0 0 "/>
    <limit effort="1000" lower="-0.008" upper="0.01" velocity="1000"/>
  </joint>
  <joint name="fanuc_prism2" type="prismatic">
    <origin rpy="-3.14159  0      -1.5708" xyz="0.0 0 -0.01099"/>
    <parent link="fanuc_link_6"/>
    <child link="fanuc_finger_2"/>
    <axis xyz="-1 0 0"/>
    <limit effort="1000" lower="-0.008" upper="0.0" velocity="1000"/>
  </joint>
  <transmission name="trans_fanuc_prism1">
    <type>transmission_interface/SimpleTransmission</type>
    <joint name="fanuc_prism1">
      <hardwareInterface>hardware_interface/EffortJointInterface</hardwareInterface>
    </joint>
    <actuator name="fanuc_prism1_motor">
      <hardwareInterface>hardware_interface/EffortJointInterface</hardwareInterface>
      <mechanicalReduction>1</mechanicalReduction>
    </actuator>
  </transmission>
  <transmission name="trans_fanuc_prism2">
    <type>transmission_interface/SimpleTransmission</type>
    <joint name="fanuc_prism2">
      <hardwareInterface>hardware_interface/EffortJointInterface</hardwareInterface>
    </joint>
    <actuator name="fanuc_prism2_motor">
      <hardwareInterface>hardware_interface/EffortJointInterface</hardwareInterface>
      <mechanicalReduction>1</mechanicalReduction>
    </actuator>
  </transmission>
  <gazebo reference="fanuc_finger_1">
    <material>Gazebo/White</material>
    <turnGravityOff>true</turnGravityOff>
  </gazebo>
  <gazebo reference="fanuc_finger_2">
    <material>Gazebo/White</material>
    <turnGravityOff>true</turnGravityOff>
  </gazebo>
  <transmission name="trans_fanuc_joint_1">
    <type>transmission_interface/SimpleTransmission</type>
    <joint name="fanuc_joint_1">
      <hardwareInterface>hardware_interface/EffortJointInterface</hardwareInterface>
    </joint>
    <actuator name="fanuc_joint_1_motor">
      <mechanicalReduction>1</mechanicalReduction>
    </actuator>
  </transmission>
  <transmission name="trans_fanuc_joint_2">
    <type>transmission_interface/SimpleTransmission</type>
    <joint name="fanuc_joint_2">
      <hardwareInterface>hardware_interface/EffortJointInterface</hardwareInterface>
    </joint>
    <actuator name="fanuc_joint_2_motor">
      <mechanicalReduction>1</mechanicalReduction>
    </actuator>
  </transmission>
  <transmission name="trans_fanuc_joint_3">
    <type>transmission_interface/SimpleTransmission</type>
    <joint name="fanuc_joint_3">
      <hardwareInterface>hardware_interface/EffortJointInterface</hardwareInterface>
    </joint>
    <actuator name="fanuc_joint_3_motor">
      <mechanicalReduction>1</mechanicalReduction>
    </actuator>
  </transmission>
  <transmission name="trans_fanuc_joint_4">
    <type>transmission_interface/SimpleTransmission</type>
    <joint name="fanuc_joint_4">
      <hardwareInterface>hardware_interface/EffortJointInterface</hardwareInterface>
    </joint>
    <actuator name="fanuc_joint_4_motor">
      <mechanicalReduction>1</mechanicalReduction>
    </actuator>
  </transmission>
  <transmission name="trans_fanuc_joint_5">
    <type>transmission_interface/SimpleTransmission</type>
    <joint name="fanuc_joint_5">
      <hardwareInterface>hardware_interface/EffortJointInterface</hardwareInterface>
    </joint>
    <actuator name="fanuc_joint_5_motor">
      <mechanicalReduction>1</mechanicalReduction>
    </actuator>
  </transmission>
  <transmission name="trans_fanuc_joint_6">
    <type>transmission_interface/SimpleTransmission</type>
    <joint name="fanuc_joint_6">
      <hardwareInterface>hardware_interface/EffortJointInterface</hardwareInterface>
    </joint>
    <actuator name="fanuc_joint_6_motor">
      <mechanicalReduction>1</mechanicalReduction>
    </actuator>
  </transmission>
  <transmission name="trans_fanuc_prism1">
    <type>transmission_interface/SimpleTransmission</type>
    <joint name="fanuc_prism1">
      <hardwareInterface>hardware_interface/EffortJointInterface</hardwareInterface>
    </joint>
    <actuator name="fanuc_prism1_motor">
      <hardwareInterface>hardware_interface/EffortJointInterface</hardwareInterface>
      <mechanicalReduction>1</mechanicalReduction>
    </actuator>
  </transmission>
  <transmission name="trans_fanuc_prism2">
    <type>transmission_interface/SimpleTransmission</type>
    <joint name="fanuc_prism2">
      <hardwareInterface>hardware_interface/EffortJointInterface</hardwareInterface>
    </joint>
    <actuator name="fanuc_prism2_motor">
      <hardwareInterface>hardware_interface/EffortJointInterface</hardwareInterface>
      <mechanicalReduction>1</mechanicalReduction>
    </actuator>
  </transmission>
  <gazebo>
    <static>false</static>
    <plugin filename="libgazebo_ros_control.so" name="gazebo_ros_control">
      <robotNamespace>/fanuc_lrmate200id</robotNamespace>
      <legacynodens>true</legacynodens>
    </plugin>
  </gazebo>
  <gazebo>
    <plugin filename="libgzparallelgripperplugin.so" name="ParallelGripperPlugin">
      <robotNamespace>/fanuc_lrmate200id</robotNamespace>
      <grip_force_close>5</grip_force_close>
      <joint1>fanuc_lrmate200id::fanuc_prism1</joint1>
      <joint2>fanuc_lrmate200id::fanuc_prism2</joint2>
      <grip_kp>10000</grip_kp>
      <control_topic>/fanuc_lrmate200id/control</control_topic>
      <debug>1</debug>
      <fulldebug>0</fulldebug>
      <collisions>1</collisions>
      <synchronous> 0  </synchronous>
    </plugin>
  </gazebo>
</robot>

